Workbook

Sheet Cover
B1: CASH MANAGEMENT WORKBOOK
B2: Executive Control Center | 13-Week Direct Cash Planning Model
B3: Mohamed Magdy
B4: FP&A Analyst | Financial Planning, Data Analytics & Business Intelligence
B6: EXECUTIVE PURPOSE | J6: MODEL SCOPE
B7: Cash visibility, liquidity planning, and funding decisions in one decision-ready workbook. | J7: Inputs → Forecast → Supporting data | 13-week direct cash planning model
B10: DECISION METRICS
B11: OPENING CASH | F11: MINIMUM CASH BUFFER | J11: FORECASTED BILLINGS | N11: SCENARIO FACTOR
B12: ='Cash Forecast'!D12 -> 4500000 | F12: ='Cash Inputs'!D6 -> 1000000 | J12: ='Cash Forecast'!T15 -> 13090000 | N12: ='Cash Forecast'!T14 -> 0.85
B15: WORKBOOK SHEETS | CLICK TO OPEN | J15: KEY CONTACT
B16: =HYPERLINK("#'Cash Inputs'!A1","01 CASH INPUTS | Assumptions and weekly drivers") -> 01 CASH INPUTS | Assumptions and weekly drivers | J16: Primary contact
B17: =HYPERLINK("#'Cash Forecast'!A1","02 CASH FORECAST | Cash runway and funding view") -> 02 CASH FORECAST | Cash runway and funding view | J17: =HYPERLINK("mailto:mohamedeones123@gmail.com","mohamedeones123@gmail.com") -> mohamedeones123@gmail.com
B18: =HYPERLINK("#'Training Data'!A1","03 TRAINING DATA | Supporting inputs and references") -> 03 TRAINING DATA | Supporting inputs and references | J18: +20 101 301 9563
J19: =HYPERLINK("https://www.linkedin.com/in/mohamed-magdy-finance","linkedin.com/in/mohamed-magdy-finance") -> linkedin.com/in/mohamed-magdy-finance
J20: =HYPERLINK("https://github.com/Mohamed-Magdy-Finance","github.com/Mohamed-Magdy-Finance") -> github.com/Mohamed-Magdy-Finance
B21: DECISION WORKFLOW | J21: MANAGEMENT USE
B22: Inputs → Forecast → Supporting data | J22: Built for management review, liquidity monitoring, and funding decisions.
B25: Prepared for management review | Cash visibility • liquidity planning • funding decisions

Sheet Training Data
A1: Training Data - Manufacturing Company (USD)
B3: Control Assumptions | J3: Input Quality Checks
B4: Selected Scenario | D4: Stress | F4: Opening Revenue (not used) | G4: 0 | J4: Scenario Validity | K4: =IF(OR(D4="Base",D4="Conservative",D4="Stress"),"OK","REVIEW") -> OK | L4: Blue = Manual input
B5: Opening Cash Balance | D5: 4500000 | F5: Revolver APR | G5: 0.08 | J5: AR Collection % | K5: =IF(AND(SUM(D15:D17)>=0,SUM(D15:D17)<=1),"OK","REVIEW") -> OK | L5: Green = Linked value
B6: Minimum Cash Buffer | D6: 1000000 | F6: Weeks / Year | G6: 52 | J6: AP Payment % | K6: =IF(SUM(D22:D24)=1,"OK","REVIEW") -> OK | L6: Amber = Review / event
B7: Opening AR Balance | D7: 2400000 | F7: Cash Sweep % | G7: 1 | J7: Scenario Completeness | K7: =IF(COUNTA(C43:F45)=ROWS(C43:F45)*COLUMNS(C43:F45),"OK","REVIEW") -> OK | L7: All checks should read OK
B8: Opening AP Balance | D8: 1600000 | F8: Facility Limit | G8: 10000000 | J8: Sales Input Completeness | K8: =IF(COUNT(D12:P18)=ROWS(D12:P18)*COLUMNS(D12:P18),"OK","REVIEW") -> OK | L8: Sales / AR block complete
A10: Sales & AR Forecasts
B11: Input | C11: Units | D11: Week 1 | E11: Week 2 | F11: Week 3 | G11: Week 4 | H11: Week 5 | I11: Week 6 | J11: Week 7 | K11: Week 8 | L11: Week 9 | M11: Week 10 | N11: Week 11 | O11: Week 12 | P11: Week 13
B12: Sales Billings | C12: $ | D12: 950000 | E12: 1000000 | F12: 1050000 | G12: 1100000 | H12: 1000000 | I12: 1150000 | J12: 1200000 | K12: 1250000 | L12: 1200000 | M12: 1300000 | N12: 1350000 | O12: 1400000 | P12: 1450000
B13: Cash Sales % | C13: % | D13: 0.3 | E13: 0.3 | F13: 0.3 | G13: 0.3 | H13: 0.3 | I13: 0.3 | J13: 0.3 | K13: 0.3 | L13: 0.3 | M13: 0.3 | N13: 0.3 | O13: 0.3 | P13: 0.3
B14: Existing AR Collections | C14: $ | D14: 700000 | E14: 650000 | F14: 600000 | G14: 550000 | H14: 450000 | I14: 300000 | J14: 1500000 | K14: 1500000 | L14: 1500000 | M14: 1500000 | N14: 1500000 | O14: 1500000 | P14: 1500000
B15: Current Week Credit Collection % | C15: % | D15: 0.2 | E15: 0.2 | F15: 0.2 | G15: 0.2 | H15: 0.2 | I15: 0.2 | J15: 0.2 | K15: 0.2 | L15: 0.2 | M15: 0.2 | N15: 0.2 | O15: 0.2 | P15: 0.2
B16: 1 Week Lag Collection % | C16: % | D16: 0.35 | E16: 0.35 | F16: 0.35 | G16: 0.35 | H16: 0.35 | I16: 0.35 | J16: 0.35 | K16: 0.35 | L16: 0.35 | M16: 0.35 | N16: 0.35 | O16: 0.35 | P16: 0.35
B17: 2 Week Lag Collection % | C17: % | D17: 0.25 | E17: 0.25 | F17: 0.25 | G17: 0.25 | H17: 0.25 | I17: 0.25 | J17: 0.25 | K17: 0.25 | L17: 0.25 | M17: 0.25 | N17: 0.25 | O17: 0.25 | P17: 0.25
B18: Other Receipts | C18: $ | D18: 20000 | E18: 20000 | F18: 15000 | G18: 20000 | H18: 20000 | I18: 25000 | J18: 20000 | K18: 20000 | L18: 25000 | M18: 25000 | N18: 25000 | O18: 30000 | P18: 30000
A19: Purchasing & AP Forecasts
B20: AP Purchases | C20: $ | D20: 1100000 | E20: 1150000 | F20: 1200000 | G20: 1250000 | H20: 1180000 | I20: 1400000 | J20: 1300000 | K20: 1350000 | L20: 1320000 | M20: 1380000 | N20: 1420000 | O20: 1450000 | P20: 1500000
B21: Existing AP Payments | C21: $ | D21: 450000 | E21: 430000 | F21: 440000 | G21: 460000 | H21: 480000 | I21: 520000 | J21: 500000 | K21: 490000 | L21: 500000 | M21: 520000 | N21: 540000 | O21: 560000 | P21: 580000
B22: Current Week AP Payment % | C22: % | D22: 0.3 | E22: 0.3 | F22: 0.3 | G22: 0.3 | H22: 0.3 | I22: 0.3 | J22: 0.3 | K22: 0.3 | L22: 0.3 | M22: 0.3 | N22: 0.3 | O22: 0.3 | P22: 0.3
B23: 1 Week Lag AP Payment % | C23: % | D23: 0.45 | E23: 0.45 | F23: 0.45 | G23: 0.45 | H23: 0.45 | I23: 0.45 | J23: 0.45 | K23: 0.45 | L23: 0.45 | M23: 0.45 | N23: 0.45 | O23: 0.45 | P23: 0.45
B24: 2 Week Lag AP Payment % | C24: % | D24: 0.25 | E24: 0.25 | F24: 0.25 | G24: 0.25 | H24: 0.25 | I24: 0.25 | J24: 0.25 | K24: 0.25 | L24: 0.25 | M24: 0.25 | N24: 0.25 | O24: 0.25 | P24: 0.25
A25: HR, Treasury & Other Payments
B26: Payroll | C26: $ | D26: 180000 | E26: 180000 | F26: 185000 | G26: 185000 | H26: 190000 | I26: 190000 | J26: 195000 | K26: 195000 | L26: 200000 | M26: 200000 | N26: 205000 | O26: 205000 | P26: 210000
B27: Taxes & Statutory | C27: $ | D27: 75000 | E27: 80000 | F27: 85000 | G27: 90000 | H27: 100000 | I27: 250000 | J27: 110000 | K27: 115000 | L27: 120000 | M27: 125000 | N27: 130000 | O27: 135000 | P27: 140000
B28: CapEx | C28: $ | D28: 120000 | E28: 100000 | F28: 150000 | G28: 130000 | H28: 140000 | I28: 1500000 | J28: 150000 | K28: 140000 | L28: 130000 | M28: 160000 | N28: 150000 | O28: 140000 | P28: 130000
B29: Debt Service | C29: $ | D29: 50000 | E29: 50000 | F29: 50000 | G29: 50000 | H29: 50000 | I29: 600000 | J29: 50000 | K29: 50000 | L29: 50000 | M29: 50000 | N29: 50000 | O29: 50000 | P29: 50000
B30: Other Operating Payments | C30: $ | D30: 35000 | E30: 35000 | F30: 40000 | G30: 40000 | H30: 45000 | I30: 45000 | J30: 45000 | K30: 45000 | L30: 50000 | M30: 50000 | N30: 50000 | O30: 55000 | P30: 55000
A33: Finance & Treasury Forecasts
B34: Input | C34: Units | D34: Week 1 | E34: Week 2 | F34: Week 3 | G34: Week 4 | H34: Week 5 | I34: Week 6 | J34: Week 7 | K34: Week 8 | L34: Week 9 | M34: Week 10 | N34: Week 11 | O34: Week 12 | P34: Week 13
B35: Cash Transfers In | C35: $ | D35: 0 | E35: 0 | F35: 0 | G35: 0 | H35: 0 | I35: 0 | J35: 0 | K35: 0 | L35: 0 | M35: 0 | N35: 0 | O35: 0 | P35: 0
B36: Cash Transfers Out | C36: $ | D36: 0 | E36: 0 | F36: 0 | G36: 0 | H36: 0 | I36: 250000 | J36: 0 | K36: 0 | L36: 0 | M36: 0 | N36: 0 | O36: 0 | P36: 0
B37: Bank Fees & Charges | C37: $ | D37: 12000 | E37: 12000 | F37: 12000 | G37: 12000 | H37: 12000 | I37: 12000 | J37: 12000 | K37: 12000 | L37: 12000 | M37: 12000 | N37: 12000 | O37: 12000 | P37: 12000
B38: Other Financing Inflows | C38: $ | D38: 0 | E38: 0 | F38: 0 | G38: 0 | H38: 0 | I38: 0 | J38: 0 | K38: 0 | L38: 0 | M38: 0 | N38: 0 | O38: 0 | P38: 0
B39: Other Financing Outflows | C39: $ | D39: 0 | E39: 0 | F39: 0 | G39: 0 | H39: 0 | I39: 100000 | J39: 0 | K39: 0 | L39: 0 | M39: 0 | N39: 0 | O39: 0 | P39: 0
B40: Revolver Repayments Planned | C40: $ | D40: 0 | E40: 0 | F40: 0 | G40: 0 | H40: 0 | I40: 0 | J40: 0 | K40: 0 | L40: 0 | M40: 0 | N40: 0 | O40: 0 | P40: 0
A41: Scenario Assumptions
B42: Scenario | C42: Sales Factor | D42: AR Collection Factor | E42: AP Payment Factor | F42: CapEx Factor
B43: Base | C43: 1 | D43: 1 | E43: 1 | F43: 1
B44: Conservative | C44: 0.95 | D44: 0.9 | E44: 0.95 | F44: 0.8
...

Sheet Cash Inputs
A1: Direct Cash Forecast Inputs
B3: Control Assumptions | F3: Funding Controls | I3: Legend | J3: Link | K3: Control | L3: Note
B4: Selected Scenario | D4: ='Training Data'!D4 -> Stress | F4: Opening Revolver | G4: ='Training Data'!G4 -> 0
B5: Opening Cash Balance | D5: ='Training Data'!D5 -> 4500000 | F5: Revolver APR | G5: ='Training Data'!G5 -> 0.08 | I5: Liquidity Trigger Framework
B6: Minimum Cash Buffer | D6: ='Training Data'!D6 -> 1000000 | F6: Weeks / Year | G6: ='Training Data'!G6 -> 52 | I6: Level | J6: Definition | K6: Threshold
B7: Opening AR Balance | D7: ='Training Data'!D7 -> 2400000 | F7: Cash Sweep % | G7: ='Training Data'!G7 -> 1 | I7: Review | J7: Facility use | K7: 0.8
B8: Opening AP Balance | D8: ='Training Data'!D8 -> 1600000 | F8: Facility Limit | G8: ='Training Data'!G8 -> 10000000 | I8: Warning | J8: Facility use | K8: 0.9
I9: Breach | J9: Facility use | K9: 1
A12: Weekly Operating Inputs
B13: Input | C13: Units | D13: Week 1 | E13: Week 2 | F13: Week 3 | G13: Week 4 | H13: Week 5 | I13: Week 6 | J13: Week 7 | K13: Week 8 | L13: Week 9 | M13: Week 10 | N13: Week 11 | O13: Week 12 | P13: Week 13 | Q13: 13-Week Total
B14: Sales Billings | C14: $ | D14: ='Training Data'!D12 -> 950000 | E14: ='Training Data'!E12 -> 1000000 | F14: ='Training Data'!F12 -> 1050000 | G14: ='Training Data'!G12 -> 1100000 | H14: ='Training Data'!H12 -> 1000000 | I14: ='Training Data'!I12 -> 1150000 | J14: ='Training Data'!J12 -> 1200000 | K14: ='Training Data'!K12 -> 1250000 | ... P14: ='Training Data'!P12 -> 1450000 | Q14: =SUM(D14:P14) -> 15400000
B15: Cash Sales % | C15: % | D15: ='Training Data'!D13 -> 0.3 | E15: ='Training Data'!E13 -> 0.3 | F15: ='Training Data'!F13 -> 0.3 | G15: ='Training Data'!G13 -> 0.3 | H15: ='Training Data'!H13 -> 0.3 | I15: ='Training Data'!I13 -> 0.3 | J15: ='Training Data'!J13 -> 0.3 | K15: ='Training Data'!K13 -> 0.3 | ... P15: ='Training Data'!P13 -> 0.3
B16: Existing AR Collections | C16: $ | D16: ='Training Data'!D14 -> 700000 | E16: ='Training Data'!E14 -> 650000 | F16: ='Training Data'!F14 -> 600000 | G16: ='Training Data'!G14 -> 550000 | H16: ='Training Data'!H14 -> 450000 | I16: ='Training Data'!I14 -> 300000 | J16: ='Training Data'!J14 -> 1500000 | K16: ='Training Data'!K14 -> 1500000 | ... P16: ='Training Data'!P14 -> 1500000
B17: Current Week Credit Collection % | C17: % | D17: ='Training Data'!D15 -> 0.2 | E17: ='Training Data'!E15 -> 0.2 | F17: ='Training Data'!F15 -> 0.2 | G17: ='Training Data'!G15 -> 0.2 | H17: ='Training Data'!H15 -> 0.2 | I17: ='Training Data'!I15 -> 0.2 | J17: ='Training Data'!J15 -> 0.2 | K17: ='Training Data'!K15 -> 0.2 | ... P17: ='Training Data'!P15 -> 0.2
B18: 1 Week Lag Collection % | C18: % | D18: ='Training Data'!D16 -> 0.35 | E18: ='Training Data'!E16 -> 0.35 | F18: ='Training Data'!F16 -> 0.35 | G18: ='Training Data'!G16 -> 0.35 | H18: ='Training Data'!H16 -> 0.35 | I18: ='Training Data'!I16 -> 0.35 | J18: ='Training Data'!J16 -> 0.35 | K18: ='Training Data'!K16 -> 0.35 | ... P18: ='Training Data'!P16 -> 0.35
B19: 2 Week Lag Collection % | C19: % | D19: ='Training Data'!D17 -> 0.25 | E19: ='Training Data'!E17 -> 0.25 | F19: ='Training Data'!F17 -> 0.25 | G19: ='Training Data'!G17 -> 0.25 | H19: ='Training Data'!H17 -> 0.25 | I19: ='Training Data'!I17 -> 0.25 | J19: ='Training Data'!J17 -> 0.25 | K19: ='Training Data'!K17 -> 0.25 | ... P19: ='Training Data'!P17 -> 0.25
B20: Other Receipts | C20: $ | D20: ='Training Data'!D18 -> 20000 | E20: ='Training Data'!E18 -> 20000 | F20: ='Training Data'!F18 -> 15000 | G20: ='Training Data'!G18 -> 20000 | H20: ='Training Data'!H18 -> 20000 | I20: ='Training Data'!I18 -> 25000 | J20: ='Training Data'!J18 -> 20000 | K20: ='Training Data'!K18 -> 20000 | ... P20: ='Training Data'!P18 -> 30000
A21: Purchasing & AP Forecasts
B22: AP Purchases | C22: $ | D22: ='Training Data'!D20 -> 1100000 | E22: ='Training Data'!E20 -> 1150000 | F22: ='Training Data'!F20 -> 1200000 | G22: ='Training Data'!G20 -> 1250000 | H22: ='Training Data'!H20 -> 1180000 | I22: ='Training Data'!I20 -> 1400000 | J22: ='Training Data'!J20 -> 1300000 | K22: ='Training Data'!K20 -> 1350000 | ... P22: ='Training Data'!P20 -> 1500000 | Q22: =SUM(D22:P22) -> 17000000
B23: Existing AP Payments | C23: $ | D23: ='Training Data'!D21 -> 450000 | E23: ='Training Data'!E21 -> 430000 | F23: ='Training Data'!F21 -> 440000 | G23: ='Training Data'!G21 -> 460000 | H23: ='Training Data'!H21 -> 480000 | I23: ='Training Data'!I21 -> 520000 | J23: ='Training Data'!J21 -> 500000 | K23: ='Training Data'!K21 -> 490000 | ... P23: ='Training Data'!P21 -> 580000 | Q23: =SUM(D23:P23) -> 6470000
B24: Current Week AP Payment % | C24: % | D24: ='Training Data'!D22 -> 0.3 | E24: ='Training Data'!E22 -> 0.3 | F24: ='Training Data'!F22 -> 0.3 | G24: ='Training Data'!G22 -> 0.3 | H24: ='Training Data'!H22 -> 0.3 | I24: ='Training Data'!I22 -> 0.3 | J24: ='Training Data'!J22 -> 0.3 | K24: ='Training Data'!K22 -> 0.3 | ... P24: ='Training Data'!P22 -> 0.3
B25: 1 Week Lag AP Payment % | C25: % | D25: ='Training Data'!D23 -> 0.45 | E25: ='Training Data'!E23 -> 0.45 | F25: ='Training Data'!F23 -> 0.45 | G25: ='Training Data'!G23 -> 0.45 | H25: ='Training Data'!H23 -> 0.45 | I25: ='Training Data'!I23 -> 0.45 | J25: ='Training Data'!J23 -> 0.45 | K25: ='Training Data'!K23 -> 0.45 | ... P25: ='Training Data'!P23 -> 0.45
B26: 2 Week Lag AP Payment % | C26: % | D26: ='Training Data'!D24 -> 0.25 | E26: ='Training Data'!E24 -> 0.25 | F26: ='Training Data'!F24 -> 0.25 | G26: ='Training Data'!G24 -> 0.25 | H26: ='Training Data'!H24 -> 0.25 | I26: ='Training Data'!I24 -> 0.25 | J26: ='Training Data'!J24 -> 0.25 | K26: ='Training Data'!K24 -> 0.25 | ... P26: ='Training Data'!P24 -> 0.25
A27: HR, Treasury & Other Payments
B28: Payroll | C28: $ | D28: ='Training Data'!D26 -> 180000 | E28: ='Training Data'!E26 -> 180000 | F28: ='Training Data'!F26 -> 185000 | G28: ='Training Data'!G26 -> 185000 | H28: ='Training Data'!H26 -> 190000 | I28: ='Training Data'!I26 -> 190000 | J28: ='Training Data'!J26 -> 195000 | K28: ='Training Data'!K26 -> 195000 | ... P28: ='Training Data'!P26 -> 210000 | Q28: =SUM(D28:P28) -> 2520000
B29: Taxes & Statutory | C29: $ | D29: ='Training Data'!D27 -> 75000 | E29: ='Training Data'!E27 -> 80000 | F29: ='Training Data'!F27 -> 85000 | G29: ='Training Data'!G27 -> 90000 | H29: ='Training Data'!H27 -> 100000 | I29: ='Training Data'!I27 -> 250000 | J29: ='Training Data'!J27 -> 110000 | K29: ='Training Data'!K27 -> 115000 | ... P29: ='Training Data'!P27 -> 140000 | Q29: =SUM(D29:P29) -> 1555000
B30: CapEx | C30: $ | D30: ='Training Data'!D28 -> 120000 | E30: ='Training Data'!E28 -> 100000 | F30: ='Training Data'!F28 -> 150000 | G30: ='Training Data'!G28 -> 130000 | H30: ='Training Data'!H28 -> 140000 | I30: ='Training Data'!I28 -> 1500000 | J30: ='Training Data'!J28 -> 150000 | K30: ='Training Data'!K28 -> 140000 | ... P30: ='Training Data'!P28 -> 130000 | Q30: =SUM(D30:P30) -> 3140000
B31: Debt Service | C31: $ | D31: ='Training Data'!D29 -> 50000 | E31: ='Training Data'!E29 -> 50000 | F31: ='Training Data'!F29 -> 50000 | G31: ='Training Data'!G29 -> 50000 | H31: ='Training Data'!H29 -> 50000 | I31: ='Training Data'!I29 -> 600000 | J31: ='Training Data'!J29 -> 50000 | K31: ='Training Data'!K29 -> 50000 | ... P31: ='Training Data'!P29 -> 50000 | Q31: =SUM(D31:P31) -> 1200000
B32: Other Operating Payments | C32: $ | D32: ='Training Data'!D30 -> 35000 | E32: ='Training Data'!E30 -> 35000 | F32: ='Training Data'!F30 -> 40000 | G32: ='Training Data'!G30 -> 40000 | H32: ='Training Data'!H30 -> 45000 | I32: ='Training Data'!I30 -> 45000 | J32: ='Training Data'!J30 -> 45000 | K32: ='Training Data'!K30 -> 45000 | ... P32: ='Training Data'!P30 -> 55000 | Q32: =SUM(D32:P32) -> 590000
A35: Finance & Treasury Forecasts
B36: Input | C36: Units | D36: Week 1 | E36: Week 2 | F36: Week 3 | G36: Week 4 | H36: Week 5 | I36: Week 6 | J36: Week 7 | K36: Week 8 | L36: Week 9 | M36: Week 10 | N36: Week 11 | O36: Week 12 | P36: Week 13 | Q36: 13-Week Total
B37: Cash Transfers In | C37: $ | D37: ='Training Data'!D35 -> 0 | E37: ='Training Data'!E35 -> 0 | F37: ='Training Data'!F35 -> 0 | G37: ='Training Data'!G35 -> 0 | H37: ='Training Data'!H35 -> 0 | I37: ='Training Data'!I35 -> 0 | J37: ='Training Data'!J35 -> 0 | K37: ='Training Data'!K35 -> 0 | ... P37: ='Training Data'!P35 -> 0 | Q37: =SUM(D37:P37) -> 0
B38: Cash Transfers Out | C38: $ | D38: ='Training Data'!D36 -> 0 | E38: ='Training Data'!E36 -> 0 | F38: ='Training Data'!F36 -> 0 | G38: ='Training Data'!G36 -> 0 | H38: ='Training Data'!H36 -> 0 | I38: ='Training Data'!I36 -> 250000 | J38: ='Training Data'!J36 -> 0 | K38: ='Training Data'!K36 -> 0 | ... P38: ='Training Data'!P36 -> 0 | Q38: =SUM(D38:P38) -> 250000
B39: Bank Fees & Charges | C39: $ | D39: ='Training Data'!D37 -> 12000 | E39: ='Training Data'!E37 -> 12000 | F39: ='Training Data'!F37 -> 12000 | G39: ='Training Data'!G37 -> 12000 | H39: ='Training Data'!H37 -> 12000 | I39: ='Training Data'!I37 -> 12000 | J39: ='Training Data'!J37 -> 12000 | K39: ='Training Data'!K37 -> 12000 | ... P39: ='Training Data'!P37 -> 12000 | Q39: =SUM(D39:P39) -> 156000
B40: Other Financing Inflows | C40: $ | D40: ='Training Data'!D38 -> 0 | E40: ='Training Data'!E38 -> 0 | F40: ='Training Data'!F38 -> 0 | G40: ='Training Data'!G38 -> 0 | H40: ='Training Data'!H38 -> 0 | I40: ='Training Data'!I38 -> 0 | J40: ='Training Data'!J38 -> 0 | K40: ='Training Data'!K38 -> 0 | ... P40: ='Training Data'!P38 -> 0 | Q40: =SUM(D40:P40) -> 0
B41: Other Financing Outflows | C41: $ | D41: ='Training Data'!D39 -> 0 | E41: ='Training Data'!E39 -> 0 | F41: ='Training Data'!F39 -> 0 | G41: ='Training Data'!G39 -> 0 | H41: ='Training Data'!H39 -> 0 | I41: ='Training Data'!I39 -> 100000 | J41: ='Training Data'!J39 -> 0 | K41: ='Training Data'!K39 -> 0 | ... P41: ='Training Data'!P39 -> 0 | Q41: =SUM(D41:P41) -> 100000
B42: Revolver Repayments Planned | C42: $ | D42: ='Training Data'!D40 -> 0 | E42: ='Training Data'!E40 -> 0 | F42: ='Training Data'!F40 -> 0 | G42: ='Training Data'!G40 -> 0 | H42: ='Training Data'!H40 -> 0 | I42: ='Training Data'!I40 -> 0 | J42: ='Training Data'!J40 -> 0 | K42: ='Training Data'!K40 -> 0 | ... P42: ='Training Data'!P40 -> 0 | Q42: =SUM(D42:P42) -> 0
A43: Scenario Assumptions
B44: Scenario | C44: Sales Factor | D44: AR Collection Factor | E44: AP Payment Factor | F44: CapEx Factor
B45: Base | C45: ='Training Data'!C43 -> 1 | D45: ='Training Data'!D43 -> 1 | E45: ='Training Data'!E43 -> 1 | F45: ='Training Data'!F43 -> 1
...

Sheet Cash Forecast
A1: Direct Cash Forecast
B3: Selected Scenario | D3: ='Cash Inputs'!D4 -> Stress | F3: Funding Controls
B4: Opening Cash Balance | D4: ='Cash Inputs'!D5 -> 4500000 | F4: Facility Limit | G4: ='Cash Inputs'!G8 -> 10000000
B5: Minimum Cash Buffer | D5: ='Cash Inputs'!D6 -> 1000000 | F5: Cash Sweep % | G5: ='Cash Inputs'!G7 -> 1
B6: Sales Factor | D6: =INDEX('Cash Inputs'!$C$45:$C$47,MATCH($D$3,'Cash Inputs'!$B$45:$B$47,0)) -> 0.85 | F6: Weeks / Year | G6: ='Cash Inputs'!G6 -> 52
B7: AR Collection Factor | D7: =INDEX('Cash Inputs'!$D$45:$D$47,MATCH($D$3,'Cash Inputs'!$B$45:$B$47,0)) -> 0.75 | F7: Revolver APR | G7: ='Cash Inputs'!G5 -> 0.08
B8: AP Payment Factor | D8: =INDEX('Cash Inputs'!$E$45:$E$47,MATCH($D$3,'Cash Inputs'!$B$45:$B$47,0)) -> 0.9
B9: CapEx Factor | D9: =INDEX('Cash Inputs'!$F$45:$F$47,MATCH($D$3,'Cash Inputs'!$B$45:$B$47,0)) -> 0.5
B10: Revolver APR | D10: ='Cash Inputs'!G5 -> 0.08
B11: Line Item | C11: Units | D11: Week 1 | E11: Week 2 | F11: Week 3 | G11: Week 4 | H11: Week 5 | I11: Week 6 | J11: Week 7 | K11: Week 8 | L11: Week 9 | M11: Week 10 | N11: Week 11 | O11: Week 12 | P11: Week 13
B12: Opening Cash Balance | C12: $ | D12: ='Cash Inputs'!D5 -> 4500000 | E12: =D39 -> 4258037.5 | F12: =E39 -> 3708165.6 | G12: =F39 -> 2916550 | H12: =G39 -> 2108234.4 | I12: =H39 -> 1500001.2 | J12: =I39 -> 1000000 | K12: =J39 -> 1000000 | L12: =K39 -> 1000000 | ... P12: =O39 -> 1000000 | S12: Billings to Cash Inflow Bridge
B13: Cash Inflows | S13: Gross Sales Billings | T13: =SUM('Cash Inputs'!D14:P14) -> 15400000
B14: Cash Sales | C14: $ | D14: ='Cash Inputs'!D14*'Cash Inputs'!D15*$D$6 -> 242250 | E14: ='Cash Inputs'!E14*'Cash Inputs'!E15*$D$6 -> 255000 | F14: ='Cash Inputs'!F14*'Cash Inputs'!F15*$D$6 -> 267750 | G14: ='Cash Inputs'!G14*'Cash Inputs'!G15*$D$6 -> 280500 | H14: ='Cash Inputs'!H14*'Cash Inputs'!H15*$D$6 -> 255000 | I14: ='Cash Inputs'!I14*'Cash Inputs'!I15*$D$6 -> 293250 | J14: ='Cash Inputs'!J14*'Cash Inputs'!J15*$D$6 -> 306000 | K14: ='Cash Inputs'!K14*'Cash Inputs'!K15*$D$6 -> 318750 | ... P14: ='Cash Inputs'!P14*'Cash Inputs'!P15*$D$6 -> 369750 | S14: Scenario Factor | T14: =$D$6 -> 0.85
B15: Credit Collections | C15: $ | D15: =SUM(D46:D49) -> 609787.5 | E15: =SUM(E46:E49) -> 725128.12 | F15: =SUM(F46:F49) -> 805884.38 | G15: =SUM(G46:G49) -> 786234.38 | H15: =SUM(H46:H49) -> 715696.88 | I15: =SUM(I46:I49) -> 522168.75 | J15: =SUM(J46:J49) -> 433434.38 | K15: =SUM(K46:K49) -> 436073.44 | ... P15: =SUM(P46:P49) -> 498692.96 | S15: Forecasted Billings | T15: =T13*T14 -> 13090000
B16: Other Receipts | C16: $ | D16: ='Cash Inputs'!D20 -> 20000 | E16: ='Cash Inputs'!E20 -> 20000 | F16: ='Cash Inputs'!F20 -> 15000 | G16: ='Cash Inputs'!G20 -> 20000 | H16: ='Cash Inputs'!H20 -> 20000 | I16: ='Cash Inputs'!I20 -> 25000 | J16: ='Cash Inputs'!J20 -> 20000 | K16: ='Cash Inputs'!K20 -> 20000 | ... P16: ='Cash Inputs'!P20 -> 30000 | S16: Cash Sales | T16: =SUM(D14:P14) -> 3927000
B17: Total Cash Inflows | C17: $ | D17: =SUM(D14:D16) -> 872037.5 | E17: =SUM(E14:E16) -> 1000128.1 | F17: =SUM(F14:F16) -> 1088634.4 | G17: =SUM(G14:G16) -> 1086734.4 | H17: =SUM(H14:H16) -> 990696.88 | I17: =SUM(I14:I16) -> 840418.75 | J17: =SUM(J14:J16) -> 759434.38 | K17: =SUM(K14:K16) -> 774823.44 | ... P17: =SUM(P14:P16) -> 898442.96 | S17: Credit Sales | T17: =T15-T16 -> 9163000
S18: Credit Collections | T18: =SUM(D15:P15) -> 7353372.1
B19: Cash Outflows | S19: Timing / Collection Gap | T19: =T17-T18 -> 1809627.9
B20: AP Payments | C20: $ | D20: =D50+'Cash Inputs'!D22*'Cash Inputs'!D24*$D$8 -> 702000 | E20: =E50+'Cash Inputs'!E22*'Cash Inputs'!E24*$D$8+'Cash Inputs'!D22*'Cash Inputs'!E25*$D$8 -> 1143000 | F20: =F50+'Cash Inputs'!F22*'Cash Inputs'!F24*$D$8+'Cash Inputs'!E22*'Cash Inputs'!F25*$D$8+'Cash Inputs'!D22*'Cash Inputs'!F26*$D$8 -> 1433250 | G20: =G50+'Cash Inputs'!G22*'Cash Inputs'!G24*$D$8+'Cash Inputs'!F22*'Cash Inputs'!G25*$D$8+'Cash Inputs'!E22*'Cash Inputs'!G26*$D$8 -> 1453050 | H20: =H50+'Cash Inputs'!H22*'Cash Inputs'!H24*$D$8+'Cash Inputs'!G22*'Cash Inputs'!H25*$D$8+'Cash Inputs'!F22*'Cash Inputs'!H26*$D$8 -> 1131930 | I20: =I50+'Cash Inputs'!I22*'Cash Inputs'!I24*$D$8+'Cash Inputs'!H22*'Cash Inputs'!I25*$D$8+'Cash Inputs'!G22*'Cash Inputs'!I26*$D$8 -> 1140858 | J20: =J50+'Cash Inputs'!J22*'Cash Inputs'!J24*$D$8+'Cash Inputs'!I22*'Cash Inputs'!J25*$D$8+'Cash Inputs'!H22*'Cash Inputs'!J26*$D$8 -> 1183870.8 | K20: =K50+'Cash Inputs'!K22*'Cash Inputs'!K24*$D$8+'Cash Inputs'!J22*'Cash Inputs'!K25*$D$8+'Cash Inputs'!I22*'Cash Inputs'!K26*$D$8 -> 1206037.1 | L20: =L50+'Cash Inputs'!L22*'Cash Inputs'!L24*$D$8+'Cash Inputs'!K22*'Cash Inputs'!L25*$D$8+'Cash Inputs'!J22*'Cash Inputs'!L26*$D$8 -> 1195653.7 | M20: =M50+'Cash Inputs'!M22*'Cash Inputs'!M24*$D$8+'Cash Inputs'!L22*'Cash Inputs'!M25*$D$8+'Cash Inputs'!K22*'Cash Inputs'!M26*$D$8 -> 1210950.4 | ... P20: =P50+'Cash Inputs'!P22*'Cash Inputs'!P24*$D$8+'Cash Inputs'!O22*'Cash Inputs'!P25*$D$8+'Cash Inputs'!N22*'Cash Inputs'!P26*$D$8 -> 1311750
B21: Payroll | C21: $ | D21: ='Cash Inputs'!D28 -> 180000 | E21: ='Cash Inputs'!E28 -> 180000 | F21: ='Cash Inputs'!F28 -> 185000 | G21: ='Cash Inputs'!G28 -> 185000 | H21: ='Cash Inputs'!H28 -> 190000 | I21: ='Cash Inputs'!I28 -> 190000 | J21: ='Cash Inputs'!J28 -> 195000 | K21: ='Cash Inputs'!K28 -> 195000 | ... P21: ='Cash Inputs'!P28 -> 210000
B22: Taxes & Statutory | C22: $ | D22: ='Cash Inputs'!D29 -> 75000 | E22: ='Cash Inputs'!E29 -> 80000 | F22: ='Cash Inputs'!F29 -> 85000 | G22: ='Cash Inputs'!G29 -> 90000 | H22: ='Cash Inputs'!H29 -> 100000 | I22: ='Cash Inputs'!I29 -> 250000 | J22: ='Cash Inputs'!J29 -> 110000 | K22: ='Cash Inputs'!K29 -> 115000 | ... P22: ='Cash Inputs'!P29 -> 140000
B23: CapEx | C23: $ | D23: ='Cash Inputs'!D30*$D$9 -> 60000 | E23: ='Cash Inputs'!E30*$D$9 -> 50000 | F23: ='Cash Inputs'!F30*$D$9 -> 75000 | G23: ='Cash Inputs'!G30*$D$9 -> 65000 | H23: ='Cash Inputs'!H30*$D$9 -> 70000 | I23: ='Cash Inputs'!I30*$D$9 -> 750000 | J23: ='Cash Inputs'!J30*$D$9 -> 75000 | K23: ='Cash Inputs'!K30*$D$9 -> 70000 | ... P23: ='Cash Inputs'!P30*$D$9 -> 65000
B24: Debt Service | C24: $ | D24: ='Cash Inputs'!D31 -> 50000 | E24: ='Cash Inputs'!E31 -> 50000 | F24: ='Cash Inputs'!F31 -> 50000 | G24: ='Cash Inputs'!G31 -> 50000 | H24: ='Cash Inputs'!H31 -> 50000 | I24: ='Cash Inputs'!I31 -> 600000 | J24: ='Cash Inputs'!J31 -> 50000 | K24: ='Cash Inputs'!K31 -> 50000 | ... P24: ='Cash Inputs'!P31 -> 50000
B25: Other Operating Payments | C25: $ | D25: ='Cash Inputs'!D32 -> 35000 | E25: ='Cash Inputs'!E32 -> 35000 | F25: ='Cash Inputs'!F32 -> 40000 | G25: ='Cash Inputs'!G32 -> 40000 | H25: ='Cash Inputs'!H32 -> 45000 | I25: ='Cash Inputs'!I32 -> 45000 | J25: ='Cash Inputs'!J32 -> 45000 | K25: ='Cash Inputs'!K32 -> 45000 | ... P25: ='Cash Inputs'!P32 -> 55000
B26: Total Cash Outflows | C26: $ | D26: =SUM(D20:D25) -> 1102000 | E26: =SUM(E20:E25) -> 1538000 | F26: =SUM(F20:F25) -> 1868250 | G26: =SUM(G20:G25) -> 1883050 | H26: =SUM(H20:H25) -> 1586930 | I26: =SUM(I20:I25) -> 2975858 | J26: =SUM(J20:J25) -> 1658870.8 | K26: =SUM(K20:K25) -> 1681037.1 | ... P26: =SUM(P20:P25) -> 1831750
B28: Finance & Treasury Cash Flows
B29: Other Financing Inflows | C29: $ | D29: ='Cash Inputs'!D40 -> 0 | E29: ='Cash Inputs'!E40 -> 0 | F29: ='Cash Inputs'!F40 -> 0 | G29: ='Cash Inputs'!G40 -> 0 | H29: ='Cash Inputs'!H40 -> 0 | I29: ='Cash Inputs'!I40 -> 0 | J29: ='Cash Inputs'!J40 -> 0 | K29: ='Cash Inputs'!K40 -> 0 | ... P29: ='Cash Inputs'!P40 -> 0
B30: Cash Transfers In | C30: $ | D30: ='Cash Inputs'!D37 -> 0 | E30: ='Cash Inputs'!E37 -> 0 | F30: ='Cash Inputs'!F37 -> 0 | G30: ='Cash Inputs'!G37 -> 0 | H30: ='Cash Inputs'!H37 -> 0 | I30: ='Cash Inputs'!I37 -> 0 | J30: ='Cash Inputs'!J37 -> 0 | K30: ='Cash Inputs'!K37 -> 0 | ... P30: ='Cash Inputs'!P37 -> 0
B31: Cash Transfers Out | C31: $ | D31: ='Cash Inputs'!D38 -> 0 | E31: ='Cash Inputs'!E38 -> 0 | F31: ='Cash Inputs'!F38 -> 0 | G31: ='Cash Inputs'!G38 -> 0 | H31: ='Cash Inputs'!H38 -> 0 | I31: ='Cash Inputs'!I38 -> 250000 | J31: ='Cash Inputs'!J38 -> 0 | K31: ='Cash Inputs'!K38 -> 0 | ... P31: ='Cash Inputs'!P38 -> 0
B32: Bank Fees & Charges | C32: $ | D32: ='Cash Inputs'!D39 -> 12000 | E32: ='Cash Inputs'!E39 -> 12000 | F32: ='Cash Inputs'!F39 -> 12000 | G32: ='Cash Inputs'!G39 -> 12000 | H32: ='Cash Inputs'!H39 -> 12000 | I32: ='Cash Inputs'!I39 -> 12000 | J32: ='Cash Inputs'!J39 -> 12000 | K32: ='Cash Inputs'!K39 -> 12000 | ... P32: ='Cash Inputs'!P39 -> 12000
B33: Other Financing Outflows | C33: $ | D33: ='Cash Inputs'!D41 -> 0 | E33: ='Cash Inputs'!E41 -> 0 | F33: ='Cash Inputs'!F41 -> 0 | G33: ='Cash Inputs'!G41 -> 0 | H33: ='Cash Inputs'!H41 -> 0 | I33: ='Cash Inputs'!I41 -> 100000 | J33: ='Cash Inputs'!J41 -> 0 | K33: ='Cash Inputs'!K41 -> 0 | ... P33: ='Cash Inputs'!P41 -> 0
B34: Total Finance & Treasury CF | C34: $ | D34: =D29+D30-D31-D32-D33-D42 -> -12000 | E34: =E29+E30-E31-E32-E33-E42 -> -12000 | F34: =F29+F30-F31-F32-F33-F42 -> -12000 | G34: =G29+G30-G31-G32-G33-G42 -> -12000 | H34: =H29+H30-H31-H32-H33-H42 -> -12000 | I34: =I29+I30-I31-I32-I33-I42 -> -362000 | J34: =J29+J30-J31-J32-J33-J42 -> -12000 | K34: =K29+K30-K31-K32-K33-K42 -> -12000 | ... P34: =P29+P30-P31-P32-P33-P42 -> -12000
B35: Net Cash Movement | C35: $ | D35: =D17-D26+D34-D44 -> -241962.5 | E35: =E17-E26+E34-E44 -> -549871.88 | F35: =F17-F26+F34-F44 -> -791615.62 | G35: =G17-G26+G34-G44 -> -808315.62 | H35: =H17-H26+H34-H44 -> -608233.12 | I35: =I17-I26+I34-I44 -> -2497439.2 | J35: =J17-J26+J34-J44 -> -914509.41 | K35: =K17-K26+K34-K44 -> -922693.56 | ... P35: =P17-P26+P34-P44 -> -956982.18
B36: Ending Cash Before Financing | C36: $ | D36: =D12+D35 -> 4258037.5 | E36: =E12+E35 -> 3708165.6 | F36: =F12+F35 -> 2916550 | G36: =G12+G35 -> 2108234.4 | H36: =H12+H35 -> 1500001.2 | I36: =I12+I35 -> -997438 | J36: =J12+J35 -> 85490.593 | K36: =K12+K35 -> 77306.438 | ... P36: =P12+P35 -> 43017.821
B37: Funding Need — Minimum Buffer | C37: $ | D37: =MAX(0,$D$5-D36) -> 0 | E37: =MAX(0,$D$5-E36) -> 0 | F37: =MAX(0,$D$5-F36) -> 0 | G37: =MAX(0,$D$5-G36) -> 0 | H37: =MAX(0,$D$5-H36) -> 0 | I37: =MAX(0,$D$5-I36) -> 1997438 | J37: =MAX(0,$D$5-J36) -> 914509.41 | K37: =MAX(0,$D$5-K36) -> 922693.56 | ... P37: =MAX(0,$D$5-P36) -> 956982.18
B38: Funding Action — Suggested Revolver Draw | C38: $ | D38: =MIN(D37,MAX(0,$G$4-D40)) -> 0 | E38: =MIN(E37,MAX(0,$G$4-E40)) -> 0 | F38: =MIN(F37,MAX(0,$G$4-F40)) -> 0 | G38: =MIN(G37,MAX(0,$G$4-G40)) -> 0 | H38: =MIN(H37,MAX(0,$G$4-H40)) -> 0 | I38: =MIN(I37,MAX(0,$G$4-I40)) -> 1997438 | J38: =MIN(J37,MAX(0,$G$4-J40)) -> 914509.41 | K38: =MIN(K37,MAX(0,$G$4-K40)) -> 922693.56 | ... P38: =MIN(P37,MAX(0,$G$4-P40)) -> 956982.18
B39: Post-Funding Cash Balance | C39: $ | D39: =D36+D38 -> 4258037.5 | E39: =E36+E38 -> 3708165.6 | F39: =F36+F38 -> 2916550 | G39: =G36+G38 -> 2108234.4 | H39: =H36+H38 -> 1500001.2 | I39: =I36+I38 -> 1000000 | J39: =J36+J38 -> 1000000 | K39: =K36+K38 -> 1000000 | ... P39: =P36+P38 -> 1000000
B40: Debt Opening Balance | C40: $ | D40: ='Cash Inputs'!G4 -> 0 | E40: =D43 -> 0 | F40: =E43 -> 0 | G40: =F43 -> 0 | H40: =G43 -> 0 | I40: =H43 -> 0 | J40: =I43 -> 1997438 | K40: =J43 -> 2911947.4 | L40: =K43 -> 3834641 | ... P40: =O43 -> 7588839
B41: Debt Draw | C41: $ | D41: =D38 -> 0 | E41: =E38 -> 0 | F41: =F38 -> 0 | G41: =G38 -> 0 | H41: =H38 -> 0 | I41: =I38 -> 1997438 | J41: =J38 -> 914509.41 | K41: =K38 -> 922693.56 | ... P41: =P38 -> 956982.18
B42: Debt Repayment / Cash Sweep | C42: $ | D42: =MIN('Cash Inputs'!D42+D53*$G$5,D40) -> 0 | E42: =MIN('Cash Inputs'!E42+E53*$G$5,E40) -> 0 | F42: =MIN('Cash Inputs'!F42+F53*$G$5,F40) -> 0 | G42: =MIN('Cash Inputs'!G42+G53*$G$5,G40) -> 0 | H42: =MIN('Cash Inputs'!H42+H53*$G$5,H40) -> 0 | I42: =MIN('Cash Inputs'!I42+I53*$G$5,I40) -> 0 | J42: =MIN('Cash Inputs'!J42+J53*$G$5,J40) -> 0 | K42: =MIN('Cash Inputs'!K42+K53*$G$5,K40) -> 0 | ... P42: =MIN('Cash Inputs'!P42+P53*$G$5,P40) -> 0
...

Sheet Executive Dashboard
A1: Executive Dashboard
A2: 13-Week Liquidity & Funding Monitor
B3: Selected Scenario | D3: ='Cash Forecast'!D3 -> Stress | F3: Forecast Horizon | H3: 13 weeks | J3: Utilization Thresholds | L3: GREEN <60% | O3: AMBER 60%-<80% | Q3: RED ≥80%
B4: Opening Cash | D4: ='Cash Forecast'!D4 -> 4500000 | F4: Minimum Buffer | H4: ='Cash Forecast'!D5 -> 1000000 | J4: Peak Funding | L4: ='Cash Forecast'!D45 -> 1997438 | N4: Peak Funding Week | P4: ='Cash Forecast'!T45 -> Week 6
B7: Ending Revolver | D7: ='Cash Forecast'!P85 -> 8545821.2 | F7: Revolver Utilization | H7: ='Cash Forecast'!D65 -> 0.85458212 | J7: Facility Headroom | L7: ='Cash Forecast'!D66 -> 1454178.8 | N7: Ending Cash | P7: ='Cash Forecast'!P39 -> 1000000
B10: Maximum Unfunded Gap | D10: ='Cash Forecast'!H60 -> 0 | F10: Average Operating Burn | H10: =-('Cash Forecast'!D145/13) -> 883721.37 | J10: Risk Status | L10: ="●" -> ● | N10: =IF(H7>='Dashboard Support'!$K$3,"Above upper trigger",IF(H7>='Dashboard Support'!$K$2,"Between triggers","Below warning trigger")) -> Above upper trigger
A16: Weekly Liquidity Trends
A17: Cash position and funding profile | J17: Revolver usage and capacity
A36: Operating Cash Movement | J36: Management Insights & Exceptions
J37: ="Peak funding of "&TEXT(L4,"$#,##0")&" occurs in "&P4 -> Peak funding of $1,997,438 occurs in Week 6
J38: ="Ending revolver balance: "&TEXT(D7,"$#,##0") -> Ending revolver balance: $8,545,821
J39: ="Ending utilization: "&TEXT(H7,"0.0%")&" | Remaining headroom: "&TEXT(L7,"$#,##0") -> Ending utilization: 85.5% | Remaining headroom: $1,454,179
J40: =IF(D10=0,"Unfunded gap: none — funding is covered","Unfunded gap remains: "&TEXT(D10,"$#,##0")) -> Unfunded gap: none — funding is covered
J41: =IF(AVERAGE('Cash Forecast'!J35:P35)<0,"Post-peak cash burn remains negative","Post-peak cash stabilizes") -> Post-peak cash burn remains negative
J42: =COUNTIF('Cash Forecast'!D36:P36,"<"&H4)&" week(s) below minimum buffer before financing" -> 8 week(s) below minimum buffer before financing
J44: =IF(H7>='Dashboard Support'!$K$3,"ACTION: preserve liquidity headroom and review funding plan",IF(H7>='Dashboard Support'!$K$2,"WATCH: utilization is elevated; monitor weekly funding need","OK: liquidity remains within policy thresholds")) -> ACTION: preserve liquidity headroom and review funding plan
B57: Liquidity Runway Analysis
B59: Ending Revolver Balance | C59: $ | D59: ='Cash Forecast'!P85 -> 8545821.2 | F59: Revolver Utilization % | G59: % | H59: ='Cash Forecast'!P86 -> 0.85458212 | J59: Remaining Revolver Headroom | K59: $ | L59: ='Cash Forecast'!P87 -> 1454178.8 | N59: Peak Funding Week | O59: Week | P59: ='Cash Forecast'!T45 -> Week 6
N60: Peak Week Index | O60: Index | P60: =MATCH($P$59,'Cash Forecast'!$D$11:$P$11,0) -> 6
B61: Average Weekly Cash Burn | C61: $ | D61: =IF(D62>0,0,ABS(D62)) -> 935483.31 | F61: Liquidity Runway (Weeks) | G61: weeks | H61: =IF(D62>0,"N/A – Positive Cash Generation",IF(D61=0,"N/A – Positive Cash Generation",L59/D61)) -> 1.5544679 | J61: Liquidity Risk Indicator | K61: Status | L61: ="●" -> ● | N61: Burn Window | O61: Window | P61: ="Week "&($P$60+1)&"–"&COLUMNS('Cash Forecast'!$D$35:$P$35) -> Week 7–13
B62: Post-Peak Average Cash Flow | C62: $ | D62: =IF($P$60>=COLUMNS('Cash Forecast'!$D$35:$P$35),0,AVERAGE(INDEX('Cash Forecast'!$D$35:$P$35,1,$P$60+1):INDEX('Cash Forecast'!$D$35:$P$35,1,COLUMNS('Cash Forecast'!$D$35:$P$35)))) -> -935483.31
B63: Liquidity Runway estimates how many weeks of projected cash burn can be funded using the remaining unused revolver capacity.
B64: ="Risk bands: GREEN > "&TEXT('Dashboard Support'!$N$2,"0")&" weeks | AMBER "&TEXT('Dashboard Support'!$N$3,"0")&"–"&TEXT('Dashboard Support'!$N$2,"0")&" weeks | RED < "&TEXT('Dashboard Support'!$N$3,"0")&" weeks" -> Risk bands: GREEN > 6 weeks | AMBER 3–6 weeks | RED < 3 weeks
B65: =IF(D62>0,"Forecast generates sufficient cash to avoid further borrowing under this scenario.","Liquidity Runway assumes the post-peak burn rate continues and no additional financing is obtained.") -> Liquidity Runway assumes the post-peak burn rate continues and no additional financing is obtained.

Sheet Dashboard Support
A1: Chart Data | 13-Week Liquidity Profile | J1: Utilization Risk Framework | M1: Runway Risk Framework
A2: Week | B2: Cash Before Financing | C2: Post-Funding Cash | D2: Minimum Buffer | E2: Ending Revolver | F2: Facility Limit | G2: Inflows | H2: Outflows | J2: Amber Trigger | K2: 0.6 | M2: Green > | N2: 6
A3: {=INDEX('Cash Forecast'!$D$11:$P$11,1,ROW()-2)} -> Week 1 | B3: {=INDEX('Cash Forecast'!$D$51:$P$51,1,ROW()-2)} -> 4270037.5 | C3: {=INDEX('Cash Forecast'!$D$39:$P$39,1,ROW()-2)} -> 4258037.5 | D3: ='Cash Forecast'!$D$5 -> 1000000 | E3: {=INDEX('Cash Forecast'!$D$85:$P$85,1,ROW()-2)} -> 0 | F3: ='Cash Forecast'!$G$4 -> 10000000 | G3: {=INDEX('Cash Forecast'!$D$17:$P$17,1,ROW()-2)} -> 872037.5 | H3: {=-INDEX('Cash Forecast'!$D$26:$P$26,1,ROW()-2)} -> -1102000 | J3: Red Trigger | K3: 0.8 | M3: Amber ≥ | N3: 3
A4: {=INDEX('Cash Forecast'!$D$11:$P$11,1,ROW()-2)} -> Week 2 | B4: {=INDEX('Cash Forecast'!$D$51:$P$51,1,ROW()-2)} -> 3720165.6 | C4: {=INDEX('Cash Forecast'!$D$39:$P$39,1,ROW()-2)} -> 3708165.6 | D4: ='Cash Forecast'!$D$5 -> 1000000 | E4: {=INDEX('Cash Forecast'!$D$85:$P$85,1,ROW()-2)} -> 0 | F4: ='Cash Forecast'!$G$4 -> 10000000 | G4: {=INDEX('Cash Forecast'!$D$17:$P$17,1,ROW()-2)} -> 1000128.1 | H4: {=-INDEX('Cash Forecast'!$D$26:$P$26,1,ROW()-2)} -> -1538000
A5: {=INDEX('Cash Forecast'!$D$11:$P$11,1,ROW()-2)} -> Week 3 | B5: {=INDEX('Cash Forecast'!$D$51:$P$51,1,ROW()-2)} -> 2928550 | C5: {=INDEX('Cash Forecast'!$D$39:$P$39,1,ROW()-2)} -> 2916550 | D5: ='Cash Forecast'!$D$5 -> 1000000 | E5: {=INDEX('Cash Forecast'!$D$85:$P$85,1,ROW()-2)} -> 0 | F5: ='Cash Forecast'!$G$4 -> 10000000 | G5: {=INDEX('Cash Forecast'!$D$17:$P$17,1,ROW()-2)} -> 1088634.4 | H5: {=-INDEX('Cash Forecast'!$D$26:$P$26,1,ROW()-2)} -> -1868250
A6: {=INDEX('Cash Forecast'!$D$11:$P$11,1,ROW()-2)} -> Week 4 | B6: {=INDEX('Cash Forecast'!$D$51:$P$51,1,ROW()-2)} -> 2120234.4 | C6: {=INDEX('Cash Forecast'!$D$39:$P$39,1,ROW()-2)} -> 2108234.4 | D6: ='Cash Forecast'!$D$5 -> 1000000 | E6: {=INDEX('Cash Forecast'!$D$85:$P$85,1,ROW()-2)} -> 0 | F6: ='Cash Forecast'!$G$4 -> 10000000 | G6: {=INDEX('Cash Forecast'!$D$17:$P$17,1,ROW()-2)} -> 1086734.4 | H6: {=-INDEX('Cash Forecast'!$D$26:$P$26,1,ROW()-2)} -> -1883050
A7: {=INDEX('Cash Forecast'!$D$11:$P$11,1,ROW()-2)} -> Week 5 | B7: {=INDEX('Cash Forecast'!$D$51:$P$51,1,ROW()-2)} -> 1512001.2 | C7: {=INDEX('Cash Forecast'!$D$39:$P$39,1,ROW()-2)} -> 1500001.2 | D7: ='Cash Forecast'!$D$5 -> 1000000 | E7: {=INDEX('Cash Forecast'!$D$85:$P$85,1,ROW()-2)} -> 0 | F7: ='Cash Forecast'!$G$4 -> 10000000 | G7: {=INDEX('Cash Forecast'!$D$17:$P$17,1,ROW()-2)} -> 990696.88 | H7: {=-INDEX('Cash Forecast'!$D$26:$P$26,1,ROW()-2)} -> -1586930
A8: {=INDEX('Cash Forecast'!$D$11:$P$11,1,ROW()-2)} -> Week 6 | B8: {=INDEX('Cash Forecast'!$D$51:$P$51,1,ROW()-2)} -> -635438 | C8: {=INDEX('Cash Forecast'!$D$39:$P$39,1,ROW()-2)} -> 1000000 | D8: ='Cash Forecast'!$D$5 -> 1000000 | E8: {=INDEX('Cash Forecast'!$D$85:$P$85,1,ROW()-2)} -> 1997438 | F8: ='Cash Forecast'!$G$4 -> 10000000 | G8: {=INDEX('Cash Forecast'!$D$17:$P$17,1,ROW()-2)} -> 840418.75 | H8: {=-INDEX('Cash Forecast'!$D$26:$P$26,1,ROW()-2)} -> -2975858
A9: {=INDEX('Cash Forecast'!$D$11:$P$11,1,ROW()-2)} -> Week 7 | B9: {=INDEX('Cash Forecast'!$D$51:$P$51,1,ROW()-2)} -> 100563.57 | C9: {=INDEX('Cash Forecast'!$D$39:$P$39,1,ROW()-2)} -> 1000000 | D9: ='Cash Forecast'!$D$5 -> 1000000 | E9: {=INDEX('Cash Forecast'!$D$85:$P$85,1,ROW()-2)} -> 2911947.4 | F9: ='Cash Forecast'!$G$4 -> 10000000 | G9: {=INDEX('Cash Forecast'!$D$17:$P$17,1,ROW()-2)} -> 759434.38 | H9: {=-INDEX('Cash Forecast'!$D$26:$P$26,1,ROW()-2)} -> -1658870.8
A10: {=INDEX('Cash Forecast'!$D$11:$P$11,1,ROW()-2)} -> Week 8 | B10: {=INDEX('Cash Forecast'!$D$51:$P$51,1,ROW()-2)} -> 93786.357 | C10: {=INDEX('Cash Forecast'!$D$39:$P$39,1,ROW()-2)} -> 1000000 | D10: ='Cash Forecast'!$D$5 -> 1000000 | E10: {=INDEX('Cash Forecast'!$D$85:$P$85,1,ROW()-2)} -> 3834641 | F10: ='Cash Forecast'!$G$4 -> 10000000 | G10: {=INDEX('Cash Forecast'!$D$17:$P$17,1,ROW()-2)} -> 774823.44 | H10: {=-INDEX('Cash Forecast'!$D$26:$P$26,1,ROW()-2)} -> -1681037.1
A11: {=INDEX('Cash Forecast'!$D$11:$P$11,1,ROW()-2)} -> Week 9 | B11: {=INDEX('Cash Forecast'!$D$51:$P$51,1,ROW()-2)} -> 88752.933 | C11: {=INDEX('Cash Forecast'!$D$39:$P$39,1,ROW()-2)} -> 1000000 | D11: ='Cash Forecast'!$D$5 -> 1000000 | E11: {=INDEX('Cash Forecast'!$D$85:$P$85,1,ROW()-2)} -> 4763787.5 | F11: ='Cash Forecast'!$G$4 -> 10000000 | G11: {=INDEX('Cash Forecast'!$D$17:$P$17,1,ROW()-2)} -> 769406.64 | H11: {=-INDEX('Cash Forecast'!$D$26:$P$26,1,ROW()-2)} -> -1680653.7
A12: {=INDEX('Cash Forecast'!$D$11:$P$11,1,ROW()-2)} -> Week 10 | B12: {=INDEX('Cash Forecast'!$D$51:$P$51,1,ROW()-2)} -> 84002.071 | C12: {=INDEX('Cash Forecast'!$D$39:$P$39,1,ROW()-2)} -> 1000000 | D12: ='Cash Forecast'!$D$5 -> 1000000 | E12: {=INDEX('Cash Forecast'!$D$85:$P$85,1,ROW()-2)} -> 5699114.3 | F12: ='Cash Forecast'!$G$4 -> 10000000 | G12: {=INDEX('Cash Forecast'!$D$17:$P$17,1,ROW()-2)} -> 799952.44 | H12: {=-INDEX('Cash Forecast'!$D$26:$P$26,1,ROW()-2)} -> -1715950.4
A13: {=INDEX('Cash Forecast'!$D$11:$P$11,1,ROW()-2)} -> Week 11 | B13: {=INDEX('Cash Forecast'!$D$51:$P$51,1,ROW()-2)} -> 77493.542 | C13: {=INDEX('Cash Forecast'!$D$39:$P$39,1,ROW()-2)} -> 1000000 | D13: ='Cash Forecast'!$D$5 -> 1000000 | E13: {=INDEX('Cash Forecast'!$D$85:$P$85,1,ROW()-2)} -> 6642388.6 | F13: ='Cash Forecast'!$G$4 -> 10000000 | G13: {=INDEX('Cash Forecast'!$D$17:$P$17,1,ROW()-2)} -> 826793.58 | H13: {=-INDEX('Cash Forecast'!$D$26:$P$26,1,ROW()-2)} -> -1749300
A14: {=INDEX('Cash Forecast'!$D$11:$P$11,1,ROW()-2)} -> Week 12 | B14: {=INDEX('Cash Forecast'!$D$51:$P$51,1,ROW()-2)} -> 75768.704 | C14: {=INDEX('Cash Forecast'!$D$39:$P$39,1,ROW()-2)} -> 1000000 | D14: ='Cash Forecast'!$D$5 -> 1000000 | E14: {=INDEX('Cash Forecast'!$D$85:$P$85,1,ROW()-2)} -> 7588839 | F14: ='Cash Forecast'!$G$4 -> 10000000 | G14: {=INDEX('Cash Forecast'!$D$17:$P$17,1,ROW()-2)} -> 867868.71 | H14: {=-INDEX('Cash Forecast'!$D$26:$P$26,1,ROW()-2)} -> -1792100
A15: {=INDEX('Cash Forecast'!$D$11:$P$11,1,ROW()-2)} -> Week 13 | B15: {=INDEX('Cash Forecast'!$D$51:$P$51,1,ROW()-2)} -> 66692.958 | C15: {=INDEX('Cash Forecast'!$D$39:$P$39,1,ROW()-2)} -> 1000000 | D15: ='Cash Forecast'!$D$5 -> 1000000 | E15: {=INDEX('Cash Forecast'!$D$85:$P$85,1,ROW()-2)} -> 8545821.2 | F15: ='Cash Forecast'!$G$4 -> 10000000 | G15: {=INDEX('Cash Forecast'!$D$17:$P$17,1,ROW()-2)} -> 898442.96 | H15: {=-INDEX('Cash Forecast'!$D$26:$P$26,1,ROW()-2)} -> -1831750

Sheet __tracelight_scratchpad__
