Workbook

Sheet Entries
B2: Income & Expense Entries
B4: Date | C4: Month | D4: Amount | E4: Category | F4: Income / Expense | G4: Description (optional) | I4: Category | J4: Income / Expense
B5: 46023 | C5: =TEXT(Table1[[#This Row],[Date]],"mmmm") -> January | D5: 850 | E5: Rent | F5: =_xlfn.XLOOKUP(Table1[[#This Row],[Category]],Table2[Category],Table2[Income / Expense]) -> Expense | G5: Apartment | I5: Salary | J5: Income
B6: 46024 | C6: =TEXT(Table1[[#This Row],[Date]],"mmmm") -> January | D6: 110 | E6: Utilities | F6: =_xlfn.XLOOKUP(Table1[[#This Row],[Category]],Table2[Category],Table2[Income / Expense]) -> Expense | G6: Mild month | I6: Bonus | J6: Income
B7: 46025 | C7: =TEXT(Table1[[#This Row],[Date]],"mmmm") -> January | D7: 60 | E7: Transport | F7: =_xlfn.XLOOKUP(Table1[[#This Row],[Category]],Table2[Category],Table2[Income / Expense]) -> Expense | G7: Monthly metro card | I7: Side Hustle | J7: Income
B8: 46026 | C8: =TEXT(Table1[[#This Row],[Date]],"mmmm") -> January | D8: 17 | E8: Other | F8: =_xlfn.XLOOKUP(Table1[[#This Row],[Category]],Table2[Category],Table2[Income / Expense]) -> Expense | G8: Books | I8: Rent | J8: Expense
B9: 46027 | C9: =TEXT(Table1[[#This Row],[Date]],"mmmm") -> January | D9: 40 | E9: Transport | F9: =_xlfn.XLOOKUP(Table1[[#This Row],[Category]],Table2[Category],Table2[Income / Expense]) -> Expense | G9: Gas | I9: Utilities | J9: Expense
B10: 46028 | C10: =TEXT(Table1[[#This Row],[Date]],"mmmm") -> January | D10: 116 | E10: Entertainment | F10: =_xlfn.XLOOKUP(Table1[[#This Row],[Category]],Table2[Category],Table2[Income / Expense]) -> Expense | G10: Theatre | I10: Transport | J10: Expense
B11: 46029 | C11: =TEXT(Table1[[#This Row],[Date]],"mmmm") -> January | D11: 176 | E11: Groceries | F11: =_xlfn.XLOOKUP(Table1[[#This Row],[Category]],Table2[Category],Table2[Income / Expense]) -> Expense | I11: Groceries | J11: Expense
B12: 46030 | C12: =TEXT(Table1[[#This Row],[Date]],"mmmm") -> January | D12: 102 | E12: Groceries | F12: =_xlfn.XLOOKUP(Table1[[#This Row],[Category]],Table2[Category],Table2[Income / Expense]) -> Expense | I12: Entertainment | J12: Expense
B13: 46031 | C13: =TEXT(Table1[[#This Row],[Date]],"mmmm") -> January | D13: 457 | E13: Side Hustle | F13: =_xlfn.XLOOKUP(Table1[[#This Row],[Category]],Table2[Category],Table2[Income / Expense]) -> Income | G13: Freelance design | I13: Other | J13: Expense
B14: 46032 | C14: =TEXT(Table1[[#This Row],[Date]],"mmmm") -> January | D14: 79 | E14: Groceries | F14: =_xlfn.XLOOKUP(Table1[[#This Row],[Category]],Table2[Category],Table2[Income / Expense]) -> Expense
B15: 46033 | C15: =TEXT(Table1[[#This Row],[Date]],"mmmm") -> January | D15: 169 | E15: Groceries | F15: =_xlfn.XLOOKUP(Table1[[#This Row],[Category]],Table2[Category],Table2[Income / Expense]) -> Expense
B16: 46034 | C16: =TEXT(Table1[[#This Row],[Date]],"mmmm") -> January | D16: 25 | E16: Entertainment | F16: =_xlfn.XLOOKUP(Table1[[#This Row],[Category]],Table2[Category],Table2[Income / Expense]) -> Expense | G16: Museum visit
B17: 46035 | C17: =TEXT(Table1[[#This Row],[Date]],"mmmm") -> January | D17: 56 | E17: Transport | F17: =_xlfn.XLOOKUP(Table1[[#This Row],[Category]],Table2[Category],Table2[Income / Expense]) -> Expense | G17: Taxi
B18: 46036 | C18: =TEXT(Table1[[#This Row],[Date]],"mmmm") -> January | D18: 32 | E18: Other | F18: =_xlfn.XLOOKUP(Table1[[#This Row],[Category]],Table2[Category],Table2[Income / Expense]) -> Expense | G18: Gift
B19: 46037 | C19: =TEXT(Table1[[#This Row],[Date]],"mmmm") -> January | D19: 132 | E19: Groceries | F19: =_xlfn.XLOOKUP(Table1[[#This Row],[Category]],Table2[Category],Table2[Income / Expense]) -> Expense
B20: 46038 | C20: =TEXT(Table1[[#This Row],[Date]],"mmmm") -> January | D20: 3000 | E20: Salary | F20: =_xlfn.XLOOKUP(Table1[[#This Row],[Category]],Table2[Category],Table2[Income / Expense]) -> Income | G20: 9-5 job
B21: 46039 | C21: =TEXT(Table1[[#This Row],[Date]],"mmmm") -> January | D21: 850 | E21: Rent | F21: =_xlfn.XLOOKUP(Table1[[#This Row],[Category]],Table2[Category],Table2[Income / Expense]) -> Expense | G21: Apartment
B22: 46040 | C22: =TEXT(Table1[[#This Row],[Date]],"mmmm") -> January | D22: 140 | E22: Utilities | F22: =_xlfn.XLOOKUP(Table1[[#This Row],[Category]],Table2[Category],Table2[Income / Expense]) -> Expense | G22: AC running
B23: 46041 | C23: =TEXT(Table1[[#This Row],[Date]],"mmmm") -> January | D23: 55 | E23: Transport | F23: =_xlfn.XLOOKUP(Table1[[#This Row],[Category]],Table2[Category],Table2[Income / Expense]) -> Expense | G23: Monthly metro card
B24: 46042 | C24: =TEXT(Table1[[#This Row],[Date]],"mmmm") -> January | D24: 51 | E24: Transport | F24: =_xlfn.XLOOKUP(Table1[[#This Row],[Category]],Table2[Category],Table2[Income / Expense]) -> Expense | G24: Uber
B25: 46043 | C25: =TEXT(Table1[[#This Row],[Date]],"mmmm") -> January | D25: 19 | E25: Entertainment | F25: =_xlfn.XLOOKUP(Table1[[#This Row],[Category]],Table2[Category],Table2[Income / Expense]) -> Expense | G25: Museum visit
B26: 46044 | C26: =TEXT(Table1[[#This Row],[Date]],"mmmm") -> January | D26: 40 | E26: Transport | F26: =_xlfn.XLOOKUP(Table1[[#This Row],[Category]],Table2[Category],Table2[Income / Expense]) -> Expense | G26: Uber
B27: 46045 | C27: =TEXT(Table1[[#This Row],[Date]],"mmmm") -> January | D27: 130 | E27: Groceries | F27: =_xlfn.XLOOKUP(Table1[[#This Row],[Category]],Table2[Category],Table2[Income / Expense]) -> Expense
B28: 46046 | C28: =TEXT(Table1[[#This Row],[Date]],"mmmm") -> January | D28: 182 | E28: Groceries | F28: =_xlfn.XLOOKUP(Table1[[#This Row],[Category]],Table2[Category],Table2[Income / Expense]) -> Expense
B29: 46047 | C29: =TEXT(Table1[[#This Row],[Date]],"mmmm") -> January | D29: 31 | E29: Other | F29: =_xlfn.XLOOKUP(Table1[[#This Row],[Category]],Table2[Category],Table2[Income / Expense]) -> Expense | G29: Gift
B30: 46048 | C30: =TEXT(Table1[[#This Row],[Date]],"mmmm") -> January | D30: 20 | E30: Other | F30: =_xlfn.XLOOKUP(Table1[[#This Row],[Category]],Table2[Category],Table2[Income / Expense]) -> Expense | G30: Haircut
B31: 46049 | C31: =TEXT(Table1[[#This Row],[Date]],"mmmm") -> January | D31: 22 | E31: Entertainment | F31: =_xlfn.XLOOKUP(Table1[[#This Row],[Category]],Table2[Category],Table2[Income / Expense]) -> Expense | G31: Movie night
B32: 46050 | C32: =TEXT(Table1[[#This Row],[Date]],"mmmm") -> January | D32: 56 | E32: Groceries | F32: =_xlfn.XLOOKUP(Table1[[#This Row],[Category]],Table2[Category],Table2[Income / Expense]) -> Expense
B33: 46051 | C33: =TEXT(Table1[[#This Row],[Date]],"mmmm") -> January | D33: 76 | E33: Groceries | F33: =_xlfn.XLOOKUP(Table1[[#This Row],[Category]],Table2[Category],Table2[Income / Expense]) -> Expense
B34: 46052 | C34: =TEXT(Table1[[#This Row],[Date]],"mmmm") -> January | D34: 53 | E34: Entertainment | F34: =_xlfn.XLOOKUP(Table1[[#This Row],[Category]],Table2[Category],Table2[Income / Expense]) -> Expense | G34: Bar night
B35: 46053 | C35: =TEXT(Table1[[#This Row],[Date]],"mmmm") -> January | D35: 616 | E35: Side Hustle | F35: =_xlfn.XLOOKUP(Table1[[#This Row],[Category]],Table2[Category],Table2[Income / Expense]) -> Income | G35: Freelance design
B36: 46054 | C36: =TEXT(Table1[[#This Row],[Date]],"mmmm") -> February | D36: 172 | E36: Groceries | F36: =_xlfn.XLOOKUP(Table1[[#This Row],[Category]],Table2[Category],Table2[Income / Expense]) -> Expense
B37: 46055 | C37: =TEXT(Table1[[#This Row],[Date]],"mmmm") -> February | D37: 3000 | E37: Salary | F37: =_xlfn.XLOOKUP(Table1[[#This Row],[Category]],Table2[Category],Table2[Income / Expense]) -> Income | G37: 9-5 job
B38: 46056 | C38: =TEXT(Table1[[#This Row],[Date]],"mmmm") -> February | D38: 850 | E38: Rent | F38: =_xlfn.XLOOKUP(Table1[[#This Row],[Category]],Table2[Category],Table2[Income / Expense]) -> Expense | G38: Apartment
B39: 46057 | C39: =TEXT(Table1[[#This Row],[Date]],"mmmm") -> February | D39: 110 | E39: Utilities | F39: =_xlfn.XLOOKUP(Table1[[#This Row],[Category]],Table2[Category],Table2[Income / Expense]) -> Expense | G39: AC running
B40: 46058 | C40: =TEXT(Table1[[#This Row],[Date]],"mmmm") -> February | D40: 60 | E40: Transport | F40: =_xlfn.XLOOKUP(Table1[[#This Row],[Category]],Table2[Category],Table2[Income / Expense]) -> Expense | G40: Monthly metro card
B41: 46059 | C41: =TEXT(Table1[[#This Row],[Date]],"mmmm") -> February | D41: 124 | E41: Groceries | F41: =_xlfn.XLOOKUP(Table1[[#This Row],[Category]],Table2[Category],Table2[Income / Expense]) -> Expense
B42: 46060 | C42: =TEXT(Table1[[#This Row],[Date]],"mmmm") -> February | D42: 44 | E42: Transport | F42: =_xlfn.XLOOKUP(Table1[[#This Row],[Category]],Table2[Category],Table2[Income / Expense]) -> Expense | G42: Gas
...

Sheet Budget Targets
A1: Category | B1: Type | C1: Jan | D1: Feb | E1: Mar | F1: Apr | G1: May | H1: Jun | I1: Jul | J1: Aug | K1: Sep | L1: Oct | M1: Nov | N1: Dec
A2: Salary | B2: Income | C2: 3000 | D2: 3000 | E2: 3000 | F2: 3000 | G2: 3000 | H2: 3000 | I2: 3000 | J2: 3000 | K2: 3000 | L2: 3000 | M2: 3000 | N2: 3000
A3: Bonus | B3: Income | C3: 0 | D3: 750 | E3: 0 | F3: 500 | G3: 0 | H3: 0 | I3: 1500 | J3: 0 | K3: 0 | L3: 0 | M3: 0 | N3: 6000
A4: Side Hustle | B4: Income | C4: 500 | D4: 300 | E4: 300 | F4: 500 | G4: 300 | H4: 200 | I4: 1500 | J4: 2000 | K4: 5000 | L4: 6000 | M4: 4000 | N4: 0
A5: Total Income | C5: =SUM(C2:C4) -> 3500 | D5: =SUM(D2:D4) -> 4050 | E5: =SUM(E2:E4) -> 3300 | F5: =SUM(F2:F4) -> 4000 | G5: =SUM(G2:G4) -> 3300 | H5: =SUM(H2:H4) -> 3200 | I5: =SUM(I2:I4) -> 6000 | J5: =SUM(J2:J4) -> 5000 | ... N5: =SUM(N2:N4) -> 9000
A6: Rent | B6: Expense | C6: 1700 | D6: 1700 | E6: 1700 | F6: 1700 | G6: 1700 | H6: 1700 | I6: 1700 | J6: 1700 | K6: 1700 | L6: 1700 | M6: 1700 | N6: 1700
A7: Utilities | B7: Expense | C7: 110 | D7: 110 | E7: 110 | F7: 110 | G7: 110 | H7: 110 | I7: 110 | J7: 110 | K7: 110 | L7: 110 | M7: 110 | N7: 110
A8: Transport | B8: Expense | C8: 150 | D8: 150 | E8: 150 | F8: 150 | G8: 150 | H8: 150 | I8: 150 | J8: 150 | K8: 150 | L8: 150 | M8: 150 | N8: 150
A9: Groceries | B9: Expense | C9: 400 | D9: 400 | E9: 400 | F9: 400 | G9: 400 | H9: 400 | I9: 400 | J9: 400 | K9: 400 | L9: 400 | M9: 400 | N9: 400
A10: Entertainment | B10: Expense | C10: 200 | D10: 200 | E10: 200 | F10: 200 | G10: 200 | H10: 200 | I10: 200 | J10: 200 | K10: 200 | L10: 200 | M10: 200 | N10: 200
A11: Other | B11: Expense | C11: 100 | D11: 100 | E11: 100 | F11: 100 | G11: 100 | H11: 100 | I11: 100 | J11: 100 | K11: 100 | L11: 100 | M11: 100 | N11: 100
A12: Total Expense | C12: =SUM(C6:C11) -> 2660 | D12: =SUM(D6:D11) -> 2660 | E12: =SUM(E6:E11) -> 2660 | F12: =SUM(F6:F11) -> 2660 | G12: =SUM(G6:G11) -> 2660 | H12: =SUM(H6:H11) -> 2660 | I12: =SUM(I6:I11) -> 2660 | J12: =SUM(J6:J11) -> 2660 | ... N12: =SUM(N6:N11) -> 2660
A13: Net Savings | C13: =C5-C12 -> 840 | D13: =D5-D12 -> 1390 | E13: =E5-E12 -> 640 | F13: =F5-F12 -> 1340 | G13: =G5-G12 -> 640 | H13: =H5-H12 -> 540 | I13: =I5-I12 -> 3340 | J13: =J5-J12 -> 2340 | ... N13: =N5-N12 -> 6340

Sheet Budget vs Actual
A2: Select Month | C2: January
B4: Summary
B5: Metric | C5: Budget | D5: Actual | E5: Variance
B6: Total Income | C6: =SUMIFS(INDEX('Budget Targets'!$C$2:$N$4,0,MATCH(LEFT($C$2,3),'Budget Targets'!$C$1:$N$1,0)),'Budget Targets'!$B$2:$B$4,"Income") -> 3500 | D6: =SUMIFS(Entries!$D:$D,Entries!$C:$C,$C$2,Entries!$F:$F,"Income") -> 4073 | E6: =D6-C6 -> 573
B7: Total Expense | C7: =SUMIFS(INDEX('Budget Targets'!$C$6:$N$11,0,MATCH(LEFT($C$2,3),'Budget Targets'!$C$1:$N$1,0)),'Budget Targets'!$B$6:$B$11,"Expense") -> 2660 | D7: =SUMIFS(Entries!$D:$D,Entries!$C:$C,$C$2,Entries!$F:$F,"Expense") -> 3689 | E7: =D7-C7 -> 1029
B8: Net Savings | C8: =C6-C7 -> 840 | D8: =D6-D7 -> 384 | E8: =D8-C8 -> -456
B9: Savings Rate | C9: =IFERROR(C8/C6,0) -> 0.24 | D9: =IFERROR(D8/D6,0) -> 0.094279401 | E9: =D9-C9 -> -0.1457206
A11: Detail by Category
A12: Category | B12: Type | C12: Budget | D12: Actual | E12: Variance $ | F12: Variance % | G12: Status
A13: Salary | B13: =IFERROR(INDEX('Budget Targets'!$B$2:$B$11,MATCH(A13,'Budget Targets'!$A$2:$A$11,0)),"") -> Income | C13: =IFERROR(INDEX('Budget Targets'!$C$2:$N$11,MATCH(A13,'Budget Targets'!$A$2:$A$11,0),MATCH(LEFT($C$2,3),'Budget Targets'!$C$1:$N$1,0)),0) -> 3000 | D13: =SUMIFS(Entries!$D:$D,Entries!$C:$C,$C$2,Entries!$E:$E,A13,Entries!$F:$F,B13) -> 3000 | E13: =D13-C13 -> 0 | F13: =IFERROR(E13/C13,0) -> 0 | G13: =IF(B13="Income",IF(E13=0,"ON TARGET",IF(E13>0,"AHEAD","BELOW TARGET")),IF(E13=0,"ON TARGET",IF(E13<0,"UNDER BUDGET","OVER BUDGET"))) -> ON TARGET
A14: Bonus | B14: =IFERROR(INDEX('Budget Targets'!$B$2:$B$11,MATCH(A14,'Budget Targets'!$A$2:$A$11,0)),"") -> Income | C14: =IFERROR(INDEX('Budget Targets'!$C$2:$N$11,MATCH(A14,'Budget Targets'!$A$2:$A$11,0),MATCH(LEFT($C$2,3),'Budget Targets'!$C$1:$N$1,0)),0) -> 0 | D14: =SUMIFS(Entries!$D:$D,Entries!$C:$C,$C$2,Entries!$E:$E,A14,Entries!$F:$F,B14) -> 0 | E14: =D14-C14 -> 0 | F14: =IFERROR(E14/C14,0) -> 0 | G14: =IF(B14="Income",IF(E14=0,"ON TARGET",IF(E14>0,"AHEAD","BELOW TARGET")),IF(E14=0,"ON TARGET",IF(E14<0,"UNDER BUDGET","OVER BUDGET"))) -> ON TARGET
A15: Side Hustle | B15: =IFERROR(INDEX('Budget Targets'!$B$2:$B$11,MATCH(A15,'Budget Targets'!$A$2:$A$11,0)),"") -> Income | C15: =IFERROR(INDEX('Budget Targets'!$C$2:$N$11,MATCH(A15,'Budget Targets'!$A$2:$A$11,0),MATCH(LEFT($C$2,3),'Budget Targets'!$C$1:$N$1,0)),0) -> 500 | D15: =SUMIFS(Entries!$D:$D,Entries!$C:$C,$C$2,Entries!$E:$E,A15,Entries!$F:$F,B15) -> 1073 | E15: =D15-C15 -> 573 | F15: =IFERROR(E15/C15,0) -> 1.146 | G15: =IF(B15="Income",IF(E15=0,"ON TARGET",IF(E15>0,"AHEAD","BELOW TARGET")),IF(E15=0,"ON TARGET",IF(E15<0,"UNDER BUDGET","OVER BUDGET"))) -> AHEAD
A16: Rent | B16: =IFERROR(INDEX('Budget Targets'!$B$2:$B$11,MATCH(A16,'Budget Targets'!$A$2:$A$11,0)),"") -> Expense | C16: =IFERROR(INDEX('Budget Targets'!$C$2:$N$11,MATCH(A16,'Budget Targets'!$A$2:$A$11,0),MATCH(LEFT($C$2,3),'Budget Targets'!$C$1:$N$1,0)),0) -> 1700 | D16: =SUMIFS(Entries!$D:$D,Entries!$C:$C,$C$2,Entries!$E:$E,A16,Entries!$F:$F,B16) -> 1700 | E16: =D16-C16 -> 0 | F16: =IFERROR(E16/C16,0) -> 0 | G16: =IF(B16="Income",IF(E16=0,"ON TARGET",IF(E16>0,"AHEAD","BELOW TARGET")),IF(E16=0,"ON TARGET",IF(E16<0,"UNDER BUDGET","OVER BUDGET"))) -> ON TARGET
A17: Utilities | B17: =IFERROR(INDEX('Budget Targets'!$B$2:$B$11,MATCH(A17,'Budget Targets'!$A$2:$A$11,0)),"") -> Expense | C17: =IFERROR(INDEX('Budget Targets'!$C$2:$N$11,MATCH(A17,'Budget Targets'!$A$2:$A$11,0),MATCH(LEFT($C$2,3),'Budget Targets'!$C$1:$N$1,0)),0) -> 110 | D17: =SUMIFS(Entries!$D:$D,Entries!$C:$C,$C$2,Entries!$E:$E,A17,Entries!$F:$F,B17) -> 250 | E17: =D17-C17 -> 140 | F17: =IFERROR(E17/C17,0) -> 1.2727273 | G17: =IF(B17="Income",IF(E17=0,"ON TARGET",IF(E17>0,"AHEAD","BELOW TARGET")),IF(E17=0,"ON TARGET",IF(E17<0,"UNDER BUDGET","OVER BUDGET"))) -> OVER BUDGET
A18: Transport | B18: =IFERROR(INDEX('Budget Targets'!$B$2:$B$11,MATCH(A18,'Budget Targets'!$A$2:$A$11,0)),"") -> Expense | C18: =IFERROR(INDEX('Budget Targets'!$C$2:$N$11,MATCH(A18,'Budget Targets'!$A$2:$A$11,0),MATCH(LEFT($C$2,3),'Budget Targets'!$C$1:$N$1,0)),0) -> 150 | D18: =SUMIFS(Entries!$D:$D,Entries!$C:$C,$C$2,Entries!$E:$E,A18,Entries!$F:$F,B18) -> 302 | E18: =D18-C18 -> 152 | F18: =IFERROR(E18/C18,0) -> 1.0133333 | G18: =IF(B18="Income",IF(E18=0,"ON TARGET",IF(E18>0,"AHEAD","BELOW TARGET")),IF(E18=0,"ON TARGET",IF(E18<0,"UNDER BUDGET","OVER BUDGET"))) -> OVER BUDGET
A19: Groceries | B19: =IFERROR(INDEX('Budget Targets'!$B$2:$B$11,MATCH(A19,'Budget Targets'!$A$2:$A$11,0)),"") -> Expense | C19: =IFERROR(INDEX('Budget Targets'!$C$2:$N$11,MATCH(A19,'Budget Targets'!$A$2:$A$11,0),MATCH(LEFT($C$2,3),'Budget Targets'!$C$1:$N$1,0)),0) -> 400 | D19: =SUMIFS(Entries!$D:$D,Entries!$C:$C,$C$2,Entries!$E:$E,A19,Entries!$F:$F,B19) -> 1102 | E19: =D19-C19 -> 702 | F19: =IFERROR(E19/C19,0) -> 1.755 | G19: =IF(B19="Income",IF(E19=0,"ON TARGET",IF(E19>0,"AHEAD","BELOW TARGET")),IF(E19=0,"ON TARGET",IF(E19<0,"UNDER BUDGET","OVER BUDGET"))) -> OVER BUDGET
A20: Entertainment | B20: =IFERROR(INDEX('Budget Targets'!$B$2:$B$11,MATCH(A20,'Budget Targets'!$A$2:$A$11,0)),"") -> Expense | C20: =IFERROR(INDEX('Budget Targets'!$C$2:$N$11,MATCH(A20,'Budget Targets'!$A$2:$A$11,0),MATCH(LEFT($C$2,3),'Budget Targets'!$C$1:$N$1,0)),0) -> 200 | D20: =SUMIFS(Entries!$D:$D,Entries!$C:$C,$C$2,Entries!$E:$E,A20,Entries!$F:$F,B20) -> 235 | E20: =D20-C20 -> 35 | F20: =IFERROR(E20/C20,0) -> 0.175 | G20: =IF(B20="Income",IF(E20=0,"ON TARGET",IF(E20>0,"AHEAD","BELOW TARGET")),IF(E20=0,"ON TARGET",IF(E20<0,"UNDER BUDGET","OVER BUDGET"))) -> OVER BUDGET
A21: Other | B21: =IFERROR(INDEX('Budget Targets'!$B$2:$B$11,MATCH(A21,'Budget Targets'!$A$2:$A$11,0)),"") -> Expense | C21: =IFERROR(INDEX('Budget Targets'!$C$2:$N$11,MATCH(A21,'Budget Targets'!$A$2:$A$11,0),MATCH(LEFT($C$2,3),'Budget Targets'!$C$1:$N$1,0)),0) -> 100 | D21: =SUMIFS(Entries!$D:$D,Entries!$C:$C,$C$2,Entries!$E:$E,A21,Entries!$F:$F,B21) -> 100 | E21: =D21-C21 -> 0 | F21: =IFERROR(E21/C21,0) -> 0 | G21: =IF(B21="Income",IF(E21=0,"ON TARGET",IF(E21>0,"AHEAD","BELOW TARGET")),IF(E21=0,"ON TARGET",IF(E21<0,"UNDER BUDGET","OVER BUDGET"))) -> ON TARGET

Sheet Dashboard
B1: PERSONAL FINANCE DASHBOARD
B2: ="As of: "&TEXT(TODAY(),"MMMM DD, YYYY") -> As of: June 17, 2026
B4: YTD INCOME | E4: YTD EXPENSE | H4: YTD SAVINGS | K4: SAVINGS RATE
B5: =SUM(C11:C22) -> 71239 | E5: =SUM(E11:E22) -> 34057 | H5: =B5-E5 -> 37182 | K5: =IFERROR(H5/B5,0) -> 0.52193321
B6: ="Budget: $"&TEXT(SUM(D11:D22),"#,##0") -> Budget: $65,350 | E6: ="Budget: $"&TEXT(SUM(F11:F22),"#,##0") -> Budget: $31,920 | H6: ="Budget: $"&TEXT(SUM(H11:H22),"#,##0") -> Budget: $33,430 | K6: Target: 45%
B7: =IF(B5>=SUM(D11:D22),"▲ $"&TEXT(B5-SUM(D11:D22),"#,##0")&" ahead of target","▼ $"&TEXT(SUM(D11:D22)-B5,"#,##0")&" behind target") -> ▲ $5,889 ahead of target | E7: =IF(E5<=SUM(F11:F22),"▼ $"&TEXT(SUM(F11:F22)-E5,"#,##0")&" under budget","▲ $"&TEXT(E5-SUM(F11:F22),"#,##0")&" over budget") -> ▲ $2,137 over budget | H7: =IF(H5>=SUM(H11:H22),"▲ $"&TEXT(H5-SUM(H11:H22),"#,##0")&" ahead of target","▼ $"&TEXT(SUM(H11:H22)-H5,"#,##0")&" behind target") -> ▲ $3,752 ahead of target | K7: =IF(K5>=0.45,"ON TRACK","BELOW TARGET") -> ON TRACK
B9: MONTHLY BREAKDOWN
B10: Month | C10: Income | D10: Bud.Inc | E10: Exp | F10: Bud.Exp | G10: Savings | H10: Bud.Sav | I10: Var $ | J10: Var % | K10: Status
B11: January | C11: =SUMIFS(Table1[Amount],Table1[Month],B11,Table1[Income / Expense],"Income") -> 4073 | D11: =INDEX('Budget Targets'!$C$5:$N$5,MATCH(LEFT(B11,3),'Budget Targets'!$C$1:$N$1,0)) -> 3500 | E11: =SUMIFS(Table1[Amount],Table1[Month],B11,Table1[Income / Expense],"Expense") -> 3689 | F11: =INDEX('Budget Targets'!$C$12:$N$12,MATCH(LEFT(B11,3),'Budget Targets'!$C$1:$N$1,0)) -> 2660 | G11: =C11-E11 -> 384 | H11: =D11-F11 -> 840 | I11: =G11-H11 -> -456 | J11: =IFERROR(I11/H11,0) -> -0.54285714 | K11: =IF(G11>=H11,"ON TRACK",IF(G11>=H11*0.9,"WARNING","BELOW TARGET")) -> BELOW TARGET
B12: February | C12: =SUMIFS(Table1[Amount],Table1[Month],B12,Table1[Income / Expense],"Income") -> 7008 | D12: =INDEX('Budget Targets'!$C$5:$N$5,MATCH(LEFT(B12,3),'Budget Targets'!$C$1:$N$1,0)) -> 4050 | E12: =SUMIFS(Table1[Amount],Table1[Month],B12,Table1[Income / Expense],"Expense") -> 3416 | F12: =INDEX('Budget Targets'!$C$12:$N$12,MATCH(LEFT(B12,3),'Budget Targets'!$C$1:$N$1,0)) -> 2660 | G12: =C12-E12 -> 3592 | H12: =D12-F12 -> 1390 | I12: =G12-H12 -> 2202 | J12: =IFERROR(I12/H12,0) -> 1.5841727 | K12: =IF(G12>=H12,"ON TRACK",IF(G12>=H12*0.9,"WARNING","BELOW TARGET")) -> ON TRACK
B13: March | C13: =SUMIFS(Table1[Amount],Table1[Month],B13,Table1[Income / Expense],"Income") -> 6000 | D13: =INDEX('Budget Targets'!$C$5:$N$5,MATCH(LEFT(B13,3),'Budget Targets'!$C$1:$N$1,0)) -> 3300 | E13: =SUMIFS(Table1[Amount],Table1[Month],B13,Table1[Income / Expense],"Expense") -> 3785 | F13: =INDEX('Budget Targets'!$C$12:$N$12,MATCH(LEFT(B13,3),'Budget Targets'!$C$1:$N$1,0)) -> 2660 | G13: =C13-E13 -> 2215 | H13: =D13-F13 -> 640 | I13: =G13-H13 -> 1575 | J13: =IFERROR(I13/H13,0) -> 2.4609375 | K13: =IF(G13>=H13,"ON TRACK",IF(G13>=H13*0.9,"WARNING","BELOW TARGET")) -> ON TRACK
B14: April | C14: =SUMIFS(Table1[Amount],Table1[Month],B14,Table1[Income / Expense],"Income") -> 6989 | D14: =INDEX('Budget Targets'!$C$5:$N$5,MATCH(LEFT(B14,3),'Budget Targets'!$C$1:$N$1,0)) -> 4000 | E14: =SUMIFS(Table1[Amount],Table1[Month],B14,Table1[Income / Expense],"Expense") -> 3657 | F14: =INDEX('Budget Targets'!$C$12:$N$12,MATCH(LEFT(B14,3),'Budget Targets'!$C$1:$N$1,0)) -> 2660 | G14: =C14-E14 -> 3332 | H14: =D14-F14 -> 1340 | I14: =G14-H14 -> 1992 | J14: =IFERROR(I14/H14,0) -> 1.4865672 | K14: =IF(G14>=H14,"ON TRACK",IF(G14>=H14*0.9,"WARNING","BELOW TARGET")) -> ON TRACK
B15: May | C15: =SUMIFS(Table1[Amount],Table1[Month],B15,Table1[Income / Expense],"Income") -> 6000 | D15: =INDEX('Budget Targets'!$C$5:$N$5,MATCH(LEFT(B15,3),'Budget Targets'!$C$1:$N$1,0)) -> 3300 | E15: =SUMIFS(Table1[Amount],Table1[Month],B15,Table1[Income / Expense],"Expense") -> 3919 | F15: =INDEX('Budget Targets'!$C$12:$N$12,MATCH(LEFT(B15,3),'Budget Targets'!$C$1:$N$1,0)) -> 2660 | G15: =C15-E15 -> 2081 | H15: =D15-F15 -> 640 | I15: =G15-H15 -> 1441 | J15: =IFERROR(I15/H15,0) -> 2.2515625 | K15: =IF(G15>=H15,"ON TRACK",IF(G15>=H15*0.9,"WARNING","BELOW TARGET")) -> ON TRACK
B16: June | C16: =SUMIFS(Table1[Amount],Table1[Month],B16,Table1[Income / Expense],"Income") -> 6169 | D16: =INDEX('Budget Targets'!$C$5:$N$5,MATCH(LEFT(B16,3),'Budget Targets'!$C$1:$N$1,0)) -> 3200 | E16: =SUMIFS(Table1[Amount],Table1[Month],B16,Table1[Income / Expense],"Expense") -> 4098 | F16: =INDEX('Budget Targets'!$C$12:$N$12,MATCH(LEFT(B16,3),'Budget Targets'!$C$1:$N$1,0)) -> 2660 | G16: =C16-E16 -> 2071 | H16: =D16-F16 -> 540 | I16: =G16-H16 -> 1531 | J16: =IFERROR(I16/H16,0) -> 2.8351852 | K16: =IF(G16>=H16,"ON TRACK",IF(G16>=H16*0.9,"WARNING","BELOW TARGET")) -> ON TRACK
B17: July | C17: =SUMIFS(Table1[Amount],Table1[Month],B17,Table1[Income / Expense],"Income") -> 12000 | D17: =INDEX('Budget Targets'!$C$5:$N$5,MATCH(LEFT(B17,3),'Budget Targets'!$C$1:$N$1,0)) -> 6000 | E17: =SUMIFS(Table1[Amount],Table1[Month],B17,Table1[Income / Expense],"Expense") -> 2590 | F17: =INDEX('Budget Targets'!$C$12:$N$12,MATCH(LEFT(B17,3),'Budget Targets'!$C$1:$N$1,0)) -> 2660 | G17: =C17-E17 -> 9410 | H17: =D17-F17 -> 3340 | I17: =G17-H17 -> 6070 | J17: =IFERROR(I17/H17,0) -> 1.8173653 | K17: =IF(G17>=H17,"ON TRACK",IF(G17>=H17*0.9,"WARNING","BELOW TARGET")) -> ON TRACK
B18: August | C18: =SUMIFS(Table1[Amount],Table1[Month],B18,Table1[Income / Expense],"Income") -> 2000 | D18: =INDEX('Budget Targets'!$C$5:$N$5,MATCH(LEFT(B18,3),'Budget Targets'!$C$1:$N$1,0)) -> 5000 | E18: =SUMIFS(Table1[Amount],Table1[Month],B18,Table1[Income / Expense],"Expense") -> 1645 | F18: =INDEX('Budget Targets'!$C$12:$N$12,MATCH(LEFT(B18,3),'Budget Targets'!$C$1:$N$1,0)) -> 2660 | G18: =C18-E18 -> 355 | H18: =D18-F18 -> 2340 | I18: =G18-H18 -> -1985 | J18: =IFERROR(I18/H18,0) -> -0.8482906 | K18: =IF(G18>=H18,"ON TRACK",IF(G18>=H18*0.9,"WARNING","BELOW TARGET")) -> BELOW TARGET
B19: September | C19: =SUMIFS(Table1[Amount],Table1[Month],B19,Table1[Income / Expense],"Income") -> 5000 | D19: =INDEX('Budget Targets'!$C$5:$N$5,MATCH(LEFT(B19,3),'Budget Targets'!$C$1:$N$1,0)) -> 8000 | E19: =SUMIFS(Table1[Amount],Table1[Month],B19,Table1[Income / Expense],"Expense") -> 1787 | F19: =INDEX('Budget Targets'!$C$12:$N$12,MATCH(LEFT(B19,3),'Budget Targets'!$C$1:$N$1,0)) -> 2660 | G19: =C19-E19 -> 3213 | H19: =D19-F19 -> 5340 | I19: =G19-H19 -> -2127 | J19: =IFERROR(I19/H19,0) -> -0.39831461 | K19: =IF(G19>=H19,"ON TRACK",IF(G19>=H19*0.9,"WARNING","BELOW TARGET")) -> BELOW TARGET
B20: October | C20: =SUMIFS(Table1[Amount],Table1[Month],B20,Table1[Income / Expense],"Income") -> 6000 | D20: =INDEX('Budget Targets'!$C$5:$N$5,MATCH(LEFT(B20,3),'Budget Targets'!$C$1:$N$1,0)) -> 9000 | E20: =SUMIFS(Table1[Amount],Table1[Month],B20,Table1[Income / Expense],"Expense") -> 1768 | F20: =INDEX('Budget Targets'!$C$12:$N$12,MATCH(LEFT(B20,3),'Budget Targets'!$C$1:$N$1,0)) -> 2660 | G20: =C20-E20 -> 4232 | H20: =D20-F20 -> 6340 | I20: =G20-H20 -> -2108 | J20: =IFERROR(I20/H20,0) -> -0.33249211 | K20: =IF(G20>=H20,"ON TRACK",IF(G20>=H20*0.9,"WARNING","BELOW TARGET")) -> BELOW TARGET
B21: November | C21: =SUMIFS(Table1[Amount],Table1[Month],B21,Table1[Income / Expense],"Income") -> 4000 | D21: =INDEX('Budget Targets'!$C$5:$N$5,MATCH(LEFT(B21,3),'Budget Targets'!$C$1:$N$1,0)) -> 7000 | E21: =SUMIFS(Table1[Amount],Table1[Month],B21,Table1[Income / Expense],"Expense") -> 1996 | F21: =INDEX('Budget Targets'!$C$12:$N$12,MATCH(LEFT(B21,3),'Budget Targets'!$C$1:$N$1,0)) -> 2660 | G21: =C21-E21 -> 2004 | H21: =D21-F21 -> 4340 | I21: =G21-H21 -> -2336 | J21: =IFERROR(I21/H21,0) -> -0.53824885 | K21: =IF(G21>=H21,"ON TRACK",IF(G21>=H21*0.9,"WARNING","BELOW TARGET")) -> BELOW TARGET
B22: December | C22: =SUMIFS(Table1[Amount],Table1[Month],B22,Table1[Income / Expense],"Income") -> 6000 | D22: =INDEX('Budget Targets'!$C$5:$N$5,MATCH(LEFT(B22,3),'Budget Targets'!$C$1:$N$1,0)) -> 9000 | E22: =SUMIFS(Table1[Amount],Table1[Month],B22,Table1[Income / Expense],"Expense") -> 1707 | F22: =INDEX('Budget Targets'!$C$12:$N$12,MATCH(LEFT(B22,3),'Budget Targets'!$C$1:$N$1,0)) -> 2660 | G22: =C22-E22 -> 4293 | H22: =D22-F22 -> 6340 | I22: =G22-H22 -> -2047 | J22: =IFERROR(I22/H22,0) -> -0.32287066 | K22: =IF(G22>=H22,"ON TRACK",IF(G22>=H22*0.9,"WARNING","BELOW TARGET")) -> BELOW TARGET
B23: Total | C23: =SUM(C11:C22) -> 71239 | D23: =SUM(D11:D22) -> 65350 | E23: =SUM(E11:E22) -> 34057 | F23: =SUM(F11:F22) -> 31920 | G23: =SUM(G11:G22) -> 37182 | H23: =SUM(H11:H22) -> 33430 | I23: =SUM(I11:I22) -> 3752 | J23: =IFERROR(I23/H23,0) -> 0.11223452
B24: Average | C24: =AVERAGEIF(C11:C22,">0") -> 5936.5833 | D24: =AVERAGEIF(D11:D22,">0") -> 5445.8333 | E24: =AVERAGEIF(E11:E22,">0") -> 2838.0833 | F24: =AVERAGEIF(F11:F22,">0") -> 2660 | G24: =AVERAGEIF(G11:G22,">0") -> 3098.5 | H24: =AVERAGEIF(H11:H22,">0") -> 2785.8333 | I24: =AVERAGEIF(I11:I22,">0") -> 2468.5 | J24: =IFERROR(AVERAGE(J11:J22),0) -> 0.78772636
B26: YEAR TO DATE CATEGORY BREAKDOWN
B27: INCOME SOURCES | G27: EXPENSE BREAKDOWN
B28: Category | C28: Amount | D28: % of Total | E28: Distribution | F28: vs Budget | G28: Category | H28: Amount | I28: % of Total | J28: Distribution | K28: vs Budget
B29: Salary | C29: =SUMIFS(Table1[Amount],Table1[Category],B29) -> 42000 | D29: =IFERROR(C29/$C$32,0) -> 0.5895647 | E29: =C29 -> 42000 | F29: =C29-SUM(INDEX('Budget Targets'!$C$2:$N$11,MATCH(B29,'Budget Targets'!$A$2:$A$11,0),0)) -> 6000 | G29: Rent | H29: =SUMIFS(Table1[Amount],Table1[Category],G29) -> 11900 | I29: =IFERROR(H29/$H$35,0) -> 0.34941422 | J29: =H29 -> 11900 | K29: =H29-SUM(INDEX('Budget Targets'!$C$2:$N$11,MATCH(G29,'Budget Targets'!$A$2:$A$11,0),0)) -> -8500
B30: Bonus | C30: =SUMIFS(Table1[Amount],Table1[Category],B30) -> 8750 | D30: =IFERROR(C30/$C$32,0) -> 0.12282598 | E30: =C30 -> 8750 | F30: =C30-SUM(INDEX('Budget Targets'!$C$2:$N$11,MATCH(B30,'Budget Targets'!$A$2:$A$11,0),0)) -> 0 | G30: Utilities | H30: =SUMIFS(Table1[Amount],Table1[Category],G30) -> 1445 | I30: =IFERROR(H30/$H$35,0) -> 0.042428869 | J30: =H30 -> 1445 | K30: =H30-SUM(INDEX('Budget Targets'!$C$2:$N$11,MATCH(G30,'Budget Targets'!$A$2:$A$11,0),0)) -> 125
B31: Side Hustle | C31: =SUMIFS(Table1[Amount],Table1[Category],B31) -> 20489 | D31: =IFERROR(C31/$C$32,0) -> 0.28760932 | E31: =C31 -> 20489 | F31: =C31-SUM(INDEX('Budget Targets'!$C$2:$N$11,MATCH(B31,'Budget Targets'!$A$2:$A$11,0),0)) -> -111 | G31: Transport | H31: =SUMIFS(Table1[Amount],Table1[Category],G31) -> 2532 | I31: =IFERROR(H31/$H$35,0) -> 0.074345949 | J31: =H31 -> 2532 | K31: =H31-SUM(INDEX('Budget Targets'!$C$2:$N$11,MATCH(G31,'Budget Targets'!$A$2:$A$11,0),0)) -> 732
B32: Total | C32: =SUM(C29:C31) -> 71239 | D32: =IFERROR(C32/C32,0) -> 1 | F32: =C32-SUM('Budget Targets'!$C$5:$N$5) -> 5889 | G32: Groceries | H32: =SUMIFS(Table1[Amount],Table1[Category],G32) -> 11450 | I32: =IFERROR(H32/$H$35,0) -> 0.33620107 | J32: =H32 -> 11450 | K32: =H32-SUM(INDEX('Budget Targets'!$C$2:$N$11,MATCH(G32,'Budget Targets'!$A$2:$A$11,0),0)) -> 6650
G33: Entertainment | H33: =SUMIFS(Table1[Amount],Table1[Category],G33) -> 4802 | I33: =IFERROR(H33/$H$35,0) -> 0.14099891 | J33: =H33 -> 4802 | K33: =H33-SUM(INDEX('Budget Targets'!$C$2:$N$11,MATCH(G33,'Budget Targets'!$A$2:$A$11,0),0)) -> 2402
G34: Other | H34: =SUMIFS(Table1[Amount],Table1[Category],G34) -> 1928 | I34: =IFERROR(H34/$H$35,0) -> 0.056610976 | J34: =H34 -> 1928 | K34: =H34-SUM(INDEX('Budget Targets'!$C$2:$N$11,MATCH(G34,'Budget Targets'!$A$2:$A$11,0),0)) -> 728
G35: Total | H35: =SUM(H29:H34) -> 34057 | I35: =IFERROR(H35/H35,0) -> 1 | K35: =SUM(K29:K34) -> 2137

Sheet Net Worth
A1: Liquid Assets | B1: 46023 | C1: 46054 | D1: 46082 | E1: 46113 | F1: 46143 | G1: 46174 | H1: 46204 | I1: 46235 | J1: 46266 | K1: 46296 | L1: 46327 | M1: 46357
A2: Checking Account
A3: Savings Account | B3: 0 | C3: 0 | D3: 0 | E3: 0 | F3: 0 | G3: 0 | H3: 0 | I3: 0 | J3: 0 | K3: 0 | L3: 0 | M3: 0
A4: Vodafone Cash | B4: 0 | C4: 0 | D4: 0 | E4: 0 | F4: 0 | G4: 0 | H4: 0 | I4: 0 | J4: 0 | K4: 0 | L4: 0 | M4: 0
A5: Physical Cash / Wallet | B5: 0 | C5: 0 | D5: 0 | E5: 0 | F5: 0 | G5: 0 | H5: 0 | I5: 0 | J5: 0 | K5: 0 | L5: 0 | M5: 0
A6: Investment Assets (Gold/Stocks) | B6: 0 | C6: 0 | D6: 0 | E6: 0 | F6: 0 | G6: 0 | H6: 0 | I6: 0 | J6: 0 | K6: 0 | L6: 0 | M6: 0
A7: Total Assets | B7: =SUM(B2:B6) -> 0 | C7: =SUM(C2:C6) -> 0 | D7: =SUM(D2:D6) -> 0 | E7: =SUM(E2:E6) -> 0 | F7: =SUM(F2:F6) -> 0 | G7: =SUM(G2:G6) -> 0 | H7: =SUM(H2:H6) -> 0 | I7: =SUM(I2:I6) -> 0 | ... M7: =SUM(M2:M6) -> 0
A9: Liabilities & Debts
A10: Credit Card Debt | B10: 0 | C10: 0 | D10: 0 | E10: 0 | F10: 0 | G10: 0 | H10: 0 | I10: 0 | J10: 0 | K10: 0 | L10: 0 | M10: 0
A11: Personal Loans / Installments | B11: 0 | C11: 0 | D11: 0 | E11: 0 | F11: 0 | G11: 0 | H11: 0 | I11: 0 | J11: 0 | K11: 0 | L11: 0 | M11: 0
A12: Total Liabilities | B12: =SUM(B10:B11) -> 0 | C12: =SUM(C10:C11) -> 0 | D12: =SUM(D10:D11) -> 0 | E12: =SUM(E10:E11) -> 0 | F12: =SUM(F10:F11) -> 0 | G12: =SUM(G10:G11) -> 0 | H12: =SUM(H10:H11) -> 0 | I12: =SUM(I10:I11) -> 0 | ... M12: =SUM(M10:M11) -> 0
A14: Actual Net Worth
A16: Financial Control & Reconciliation
A17: Cumulative Total Savings (From Dashboard) | B17: {=INDEX(Dashboard!$G:$G,10+COLUMN(A1))} -> 384 | C17: {=INDEX(Dashboard!$G:$G,10+COLUMN(B1))} -> 3592 | D17: {=INDEX(Dashboard!$G:$G,10+COLUMN(C1))} -> 2215 | E17: {=INDEX(Dashboard!$G:$G,10+COLUMN(D1))} -> 3332 | F17: {=INDEX(Dashboard!$G:$G,10+COLUMN(E1))} -> 2081 | G17: {=INDEX(Dashboard!$G:$G,10+COLUMN(F1))} -> 2071 | H17: {=INDEX(Dashboard!$G:$G,10+COLUMN(G1))} -> 9410 | I17: {=INDEX(Dashboard!$G:$G,10+COLUMN(H1))} -> 355 | ... M17: {=INDEX(Dashboard!$G:$G,10+COLUMN(L1))} -> 4293
A18: Variance / Verification Check | B18: =B14-B17 -> -384 | C18: =C14-C17 -> -3592 | D18: =D14-D17 -> -2215 | E18: =E14-E17 -> -3332 | F18: =F14-F17 -> -2081 | G18: =G14-G17 -> -2071 | H18: =H14-H17 -> -9410 | I18: =I14-I17 -> -355 | ... M18: =M14-M17 -> -4293

Sheet __tracelight_scratchpad__
