Workbook
Name Circ: Complete!$I$13

Sheet Cover
B1: LBO MODEL | EXECUTIVE COVER
B2: Mohamed Magdy | FP&A Analyst
B4: Decision-ready overview of the transaction, operating case, returns and model controls
B6: PROFILE | F6: MODEL SCOPE | J6: CONNECT WITH ME
B7: Role | C7: FP&A Analyst | F7: Model type | G7: Leveraged Buyout | J7: Email | K7: =HYPERLINK("mailto:mohamedeones123@gmail.com","Email me") -> Email me
B8: Location | C8: Tanta, Egypt | F8: Core outputs | G8: IRR | MOIC | Leverage | J8: LinkedIn | K8: =HYPERLINK("https://linkedin.com/in/mohamed-magdy-finance","LinkedIn profile") -> LinkedIn profile
B9: Focus | C9: FP&A / Modeling | F9: Analysis mode | G9: Base + sensitivity | J9: GitHub | K9: =HYPERLINK("https://github.com/Mohamed-Magdy-Finance","GitHub profile") -> GitHub profile
B10: Model | C10: Basic LBO model | F10: Decision use | G10: Returns & leverage | J10: Workbook | K10: Basic LBO model
B12: TRANSACTION SNAPSHOT | F12: OPERATING CASE | J12: MODEL STATUS
B13: LTM EBITDA | C13: =Summary!B5 -> 100 | F13: Revenue Growth | G13: =Summary!E5 -> 0.1 | J13: Checks | K13: =IF(Complete!D30=0,"PASS","REVIEW") -> PASS
B14: Purchase EV | C14: =Summary!B7 -> 1000 | F14: EBITDA Margin | G14: =Summary!E6 -> 0.1 | J14: Base Case IRR | K14: =Complete!I127 -> 0
B15: Sponsor Equity | C15: =Summary!B8 -> 427 | F15: Exit Multiple | G15: =Summary!E8 -> 10 | J15: Base Case MOIC | K15: =Complete!I128 -> 0
J16: Exit Debt | K16: =ABS(Complete!I114) -> 0
B18: VALUE CREATION
B19: Value drivers: operating growth | deleveraging | entry / exit discipline
B23: NAVIGATION
B24: Summary | C24: =HYPERLINK("#'Summary'!A1","Open executive summary") -> Open executive summary | F24: Complete | G24: =HYPERLINK("#'Complete'!A1","Open full model") -> Open full model | J24: Empty | K24: =HYPERLINK("#'Empty'!A1","Open blank template") -> Open blank template

Sheet Empty
B2: Basic LBO Model
B3: Template Structure | enter assumptions in blue cells; formulas and outputs should remain protected
B5: Step 1. Model Assumptions
B7: Entry Valuation | F7: Transaction Assumptions
B8: LTM EBITDA | F8: Transaction Fees
B9: Entry Multiple | F9: Financing Fees
B10: Purchase Enterprise Value | F10: Financing Fees Amortization Period
F11: Cash to B/S
F13: Circularity Toggle | I13: 1
B15: Debt Assumptions | C15: x EBITDA | D15: $ Amount | E15: Rate | F15: Floor | G15: % Amort. | H15: % Fee | I15: $ Fee
B16: Revolver
B17: Term Loan B
B18: Senior Notes
B19: Total Debt
B21: Step 2. Sources & Uses Table
B23: Sources & Uses
B24: Sources | C24: x EBITDA | D24: $ Amount | F24: Uses | I24: $ Amount
B25: Revolver | F25: Purchase Enterprise Value
B26: Term Loan B | F26: Cash to B/S
B27: Senior Notes | F27: Transaction Fees
B28: Sponsor Equity | F28: Financing Fees
B29: Total Sources | F29: Total Uses
B31: Step 3. Free Cash Flow Projection
B33: FCF Projection | D33: 2020 | E33: =+D33+1 -> 2021 | F33: =+E33+1 -> 2022 | G33: =+F33+1 -> 2023 | H33: =+G33+1 -> 2024 | I33: =+H33+1 -> 2025
B34: ($ in millions)
B36: Revenue
B37: Operating Forecast
B38: EBITDA
B39: Less: D&A
B40: EBIT
B41: Less: Interest
B42: Less: Amortization of Financing Fees
B43: EBT
B44: Less: Taxes
B45: Net Income
B46: Plus: D&A
... B67: Step 4. Debt Schedule
B69: Debt Schedule | E69: 2021 | F69: =+E69+1 -> 2022 | G69: =+F69+1 -> 2023 | H69: =+G69+1 -> 2024 | I69: =+H69+1 -> 2025
B70: ($ in millions)
B72: LIBOR (%) | E72: 0.015 | F72: =+E72+0.2% -> 0.017 | G72: =+F72+0.2% -> 0.019 | H72: =+G72+0.2% -> 0.021 | I72: =+H72+0.2% -> 0.023
...

Sheet Summary
A1: LBO MODEL | EXECUTIVE SUMMARY
A2: Decision Dashboard
A4: Transaction Overview | D4: Operating Case
A5: LTM EBITDA | B5: =Complete!D8 -> 100 | D5: Revenue Growth | E5: =Complete!D60 -> 0.1
A6: Entry Multiple | B6: =Complete!D9 -> 10 | D6: EBITDA Margin | E6: =Complete!D61 -> 0.1
A7: Purchase Enterprise Value | B7: =Complete!D10 -> 1000 | D7: Tax Rate | E7: =Complete!E65 -> 0.35
A8: Sponsor Equity | B8: =Complete!D28 -> 427 | D8: Exit Multiple | E8: =Complete!E112 -> 10
A9: Initial Leverage | B9: =Complete!C19 -> 6 | D9: Minimum Cash | E9: =MIN(Complete!E57:I57)+0 -> 0
A12: Returns by Exit Year
A13: Metric | B13: =+Complete!E108 -> 2021 | C13: =+Complete!F108 -> 2022 | D13: =+Complete!G108 -> 2023 | E13: =+Complete!H108 -> 2024 | F13: =+Complete!I108 -> 2025
A14: IRR | B14: =+Complete!E127+0 -> 0 | C14: =+Complete!F127+0 -> 0 | D14: =+Complete!G127+0 -> 0 | E14: =+Complete!H127+0 -> 0 | F14: =+Complete!I127+0 -> 0
A15: MOIC | B15: =+Complete!E128+0 -> 0 | C15: =+Complete!F128+0 -> 0 | D15: =+Complete!G128+0 -> 0 | E15: =+Complete!H128+0 -> 0 | F15: =+Complete!I128+0 -> 0
A17: Model Checks | D17: Decision Notes
A18: Sources & Uses Check | B18: =+Complete!D30+0 -> 0 | D18: Base case IRR | E18: =+Complete!I127+0 -> 0
A19: Cash Roll-Forward Check | B19: =MAX(Complete!E58:I58)-MIN(Complete!E58:I58)+0 -> 0 | D19: Base case MOIC | E19: =+Complete!I128+0 -> 0
A20: Liquidity Check | B20: =MIN(Complete!E118:I118)+0 -> 0 | D20: Exit Debt | E20: =ABS(Complete!I114) -> 0
A21: Exit Equity Check | B21: =MAX(Complete!E117:I117)-MIN(Complete!E117:I117)+0 -> 0 | D21: Exit Cash | E21: =+Complete!I115+0 -> 0

Sheet Complete
B2: Basic LBO Model
B3: ($ in millions)
B5: Step 1. Model Assumptions
B7: Entry Valuation | F7: Transaction Assumptions
B8: LTM EBITDA | D8: 100 | F8: Transaction Fees | I8: 10
B9: Entry Multiple | D9: 10 | F9: Financing Fees | I9: 0.02
B10: Purchase Enterprise Value | D10: =+D8*D9 -> 1000 | F10: Financing Fees Amortization Period | I10: 7
F11: Cash to B/S | I11: 5
F13: Circularity Toggle | I13: 1
B15: Debt Assumptions | C15: x EBITDA | D15: $ Amount | E15: Rate | F15: Floor | G15: % Amort. | H15: % Fee | I15: $ Fee
B16: Revolver | C16: 0 | D16: =+C16*$D$8 -> 0 | E16: 400 | F16: 0 | G16: 0 | H16: =+$I$9 -> 0.02 | I16: =+D16*H16 -> 0
B17: Term Loan B | C17: 4 | D17: =+C17*$D$8 -> 400 | E17: 400 | F17: 0.02 | G17: 0.05 | H17: =+$I$9 -> 0.02 | I17: =+D17*H17 -> 8
B18: Senior Notes | C18: 2 | D18: =+C18*$D$8 -> 200 | E18: 0.085 | F18: 0 | G18: 0 | H18: =+$I$9 -> 0.02 | I18: =+D18*H18 -> 4
B19: Total Debt | C19: =SUM(C16:C18) -> 6 | D19: =SUM(D16:D18) -> 600 | I19: =SUM(I16:I18) -> 12
B21: Step 2. Sources & Uses Table
B23: Sources & Uses
B24: Sources | C24: x EBITDA | D24: $ Amount | F24: Uses | I24: $ Amount
B25: Revolver | C25: =+D25/$D$8 -> 0 | D25: =+D16 -> 0 | F25: Purchase Enterprise Value | I25: =+D10 -> 1000
B26: Term Loan B | C26: =+D26/$D$8 -> 4 | D26: =+D17 -> 400 | F26: Cash to B/S | I26: =+I11 -> 5
B27: Senior Notes | C27: =+D27/$D$8 -> 2 | D27: =+D18 -> 200 | F27: Transaction Fees | I27: =+I8 -> 10
B28: Sponsor Equity | C28: =+D28/$D$8 -> 4.27 | D28: =+I29-SUM(D25:D27) -> 427 | F28: Financing Fees | I28: =+I19 -> 12
B29: Total Sources | D29: =SUM(D25:D28) -> 1027 | F29: Total Uses | I29: =SUM(I25:I28) -> 1027
B30: Sources & Uses Check | D30: =D29-I29 -> 0
B31: Step 3. Free Cash Flow Projection
B33: FCF Projection | D33: 2020 | E33: =+D33+1 -> 2021 | F33: =+E33+1 -> 2022 | G33: =+F33+1 -> 2023 | H33: =+G33+1 -> 2024 | I33: =+H33+1 -> 2025
B34: ($ in millions)
B36: Revenue | D36: 1000 | E36: =+D36*(1+E60) -> 1100 | F36: =+E36*(1+F60) -> 1210 | G36: =+F36*(1+G60) -> 1331 | H36: =+G36*(1+H60) -> 1464.1 | I36: =+H36*(1+I60) -> 1610.51
B37: Operating Forecast
B38: EBITDA | D38: =+D8 -> 100 | E38: =+E61*E$36 -> 110 | F38: =+F61*F36 -> 121 | G38: =+G61*G36 -> 133.1 | H38: =+H61*H36 -> 146.41 | I38: =+I61*I36 -> 161.051
B39: Less: D&A | E39: =-E62*E36 -> -22 | F39: =-F62*F36 -> -24.2 | G39: =-G62*G36 -> -26.62 | H39: =-H62*H36 -> -29.282 | I39: =-I62*I36 -> -32.2102
B40: EBIT | E40: =SUM(E38:E39) -> 88 | F40: =SUM(F38:F39) -> 96.8 | G40: =SUM(G38:G39) -> 106.48 | H40: =SUM(H38:H39) -> 117.128 | I40: =SUM(I38:I39) -> 128.8408
B41: Less: Interest | E41: =-SUM(E85,E88,E96,E104) -> -40.525 | F41: =-SUM(F85,F88,F96,F104) -> -39.325 | G41: =-SUM(G85,G88,G96,G104) -> -38.125 | H41: =-SUM(H85,H88,H96,H104) -> -37.255 | I41: =-SUM(I85,I88,I96,I104) -> -36.655
B42: Less: Amortization of Financing Fees | E42: =-$I$19/$I$10 -> -1.7142857 | F42: =-$I$19/$I$10 -> -1.7142857 | G42: =-$I$19/$I$10 -> -1.7142857 | H42: =-$I$19/$I$10 -> -1.7142857 | I42: =-$I$19/$I$10 -> -1.7142857
B43: EBT | E43: =+SUM(E40:E42) -> 45.760714 | F43: =+SUM(F40:F42) -> 55.760714 | G43: =+SUM(G40:G42) -> 66.640714 | H43: =+SUM(H40:H42) -> 78.158714 | I43: =+SUM(I40:I42) -> 90.471514
B44: Less: Taxes | E44: =-E65*E43 -> -16.01625 | F44: =-F65*F43 -> -19.51625 | G44: =-G65*G43 -> -23.32425 | H44: =-H65*H43 -> -27.35555 | I44: =-I65*I43 -> -31.66503
B45: Net Income | E45: =+SUM(E43:E44) -> 29.744464 | F45: =+SUM(F43:F44) -> 36.244464 | G45: =+SUM(G43:G44) -> 43.316464 | H45: =+SUM(H43:H44) -> 50.803164 | I45: =+SUM(I43:I44) -> 58.806484
B46: Plus: D&A | E46: =-E39 -> 22 | F46: =-F39 -> 24.2 | G46: =-G39 -> 26.62 | H46: =-H39 -> 29.282 | I46: =-I39 -> 32.2102
B47: Plus: Amortization of Financing Fees | E47: =-E42 -> 1.7142857 | F47: =-F42 -> 1.7142857 | G47: =-G42 -> 1.7142857 | H47: =-H42 -> 1.7142857 | I47: =-I42 -> 1.7142857
B48: Less: Capex | E48: =-E63*E$36 -> -22 | F48: =-F63*F$36 -> -24.2 | G48: =-G63*G$36 -> -26.62 | H48: =-H63*H$36 -> -29.282 | I48: =-I63*I$36 -> -32.2102
B49: Less: Δ in NWC | E49: =-E64*E$36 -> -11 | F49: =-F64*F$36 -> -12.1 | G49: =-G64*G$36 -> -13.31 | H49: =-H64*H$36 -> -14.641 | I49: =-I64*I$36 -> -16.1051
...

Sheet __tracelight_scratchpad__
