Workbook

Sheet Home padge

Sheet Chart Of Account
B2: شركة المتحدة
B3: قسم الحسابات
B4: السنة المالية2021
B5: دليل الحسابات
I7: القائمة | J7: الطبيعة | K7: نوع الحساب | L7: اسم الحساب | M7: رقم الحساب
I8: B.S | J8: مدين | K8: اصول | L8: النقدية | M8: 111
I9: B.S | J9: مدين | K9: اصول | L9: بنك مصر | M9: 112
I10: B.S | J10: مدين | K10: اصول | L10: مدينونTele | M10: 113
I11: B.S | J11: مدين | K11: اصول | L11: Teachمدينون | M11: 114
I12: B.S | J12: مدين | K12: اصول | L12: ادوات كتابية | M12: 115
I13: B.S | J13: مدين | K13: اصول | L13: السيارات | M13: 121
I14: B.S | J14: دائن | K14: مقابل الاصول | L14: مجمع اهلاك سيارات | M14: 122
I15: B.S | J15: مدين | K15: اصول | L15: الاثاث | M15: 123
I16: B.S | J16: دائن | K16: مقابل الاصول | L16: مجمع اهلاك الاثاث | M16: 124
I17: B.S | J17: مدين | K17: اصول | L17: مباني | M17: 125
I18: B.S | J18: مدين | K18: اصول | L18: معدات | M18: 126
I19: B.S | J19: مدين | K19: اصول | L19: الاراضي | M19: 127
... I26: B.S | J26: مدين | K26: حق ملكية | L26: مسحوبات | M26: 502
L27: حساب1 | M27: 0
L28: حساب2 | M28: 0

Sheet opining
A1: شركة المتحدة
A2: قسم الحسابات
A3: السنة المالية2021 | H3: الرصيد | I3: =I29-J29 -> 0 | K3: =K29-L29 -> 0 | M3: =M29-N29 -> 0 | O3: =O29-P29 -> 0 | Q3: =Q29-R29 -> 0 | S3: =S29-T29 -> 0 | U3: =U29-V29 -> 0 | W3: =W29-X29 -> 0 | Y3: =Y29-Z29 -> 0 | AA3: =AA29-AB29 -> 0 | AC3: =AC29-AD29 -> 0 | AE3: =AE29-AF29 -> 0 | AG3: =AG29-AH29 -> 0 | AI3: =AI29-AJ29 -> 0 | AK3: =AK29-AL29 -> 0 | AM3: =AM29-AN29 -> 0 | AO3: =AO29-AP29 -> 0 | AQ3: =AQ29-AR29 -> 0 | AS3: =AS29-AT29 -> 0 | AU3: =AU29-AV29 -> 0 | AW3: =AW29-AX29 -> 0
A4: دليل الحسابات
A6: رقم القيد | B6: التاريخ | C6: البيان | D6: الاجمالي | F6: contorl | G6: الفرق | I6: النقدية | K6: بنك مصر | M6: مدينونTele | O6: Teachمدينون | Q6: ادوات كتابية | S6: السيارات | U6: مجمع اهلاك سيارات | W6: الاثاث | Y6: مجمع اهلاك الاثاث | AA6: مباني | AC6: معدات | AE6: الاراضي | AG6: دائنونGlobal | AI6: مصروف صيانة | AK6: رواتب واجور | AM6: مصروف اهلاك | AO6: ايرادات | AQ6: راس المال | AS6: مسحوبات | AU6: حساب1 | AW6: حساب2
D7: مدين | E7: دائن | I7: مدين | J7: دائن | K7: مدين | L7: دائن | M7: مدين | N7: دائن | O7: مدين | P7: دائن | Q7: مدين | R7: دائن | S7: مدين | T7: دائن | U7: مدين | V7: دائن | W7: مدين | X7: دائن | Y7: مدين | Z7: دائن | AA7: مدين | AB7: دائن | AC7: مدين | AD7: دائن | AE7: مدين | AF7: دائن | AG7: مدين | AH7: دائن | AI7: مدين | AJ7: دائن | AK7: مدين | AL7: دائن | AM7: مدين | AN7: دائن | AO7: مدين | AP7: دائن | AQ7: مدين | AR7: دائن | AS7: مدين | AT7: دائن | AU7: مدين | AV7: دائن | AW7: مدين | AX7: دائن
D8: 0 | E8: =SUMIF($I$7:$AX$7,$I$7,I17:AX17) -> 0 | F8: =IF(D8=E8,"palance","unpalance") -> palance | G8: =IF(D8>E8,D8-E8,E8-D8) -> 0 | H8: =IF(D8>E8,"مدين اكبر",IF(E8>D8,"دائن اكبر","~")) -> ~ | I8: 0 | K8: 0 | L8: 0 | AP8: 0
D9: =SUMIF($I$7:$AX$7,$I$7,I9:AX9) -> 0 | E9: =SUMIF($I$7:$AX$7,$I$7,I18:AX18) -> 0 | F9: =IF(D9=E9,"palance","unpalance") -> palance | G9: =IF(D9>E9,D9-E9,E9-D9) -> 0 | H9: =IF(D9>E9,"مدين اكبر",IF(E9>D9,"دائن اكبر","~")) -> ~ | AP9: 0
D10: =SUMIF($I$7:$AX$7,$I$7,I10:AX10) -> 0 | E10: =SUMIF($I$7:$AX$7,$I$7,I19:AX19) -> 0 | F10: =IF(D10=E10,"palance","unpalance") -> palance | G10: =IF(D10>E10,D10-E10,E10-D10) -> 0 | H10: =IF(D10>E10,"مدين اكبر",IF(E10>D10,"دائن اكبر","~")) -> ~ | AP10: 0
D11: =SUMIF($I$7:$AX$7,$I$7,I11:AX11) -> 0 | E11: =SUMIF($I$7:$AX$7,$I$7,I20:AX20) -> 0 | F11: =IF(D11=E11,"palance","unpalance") -> palance | G11: =IF(D11>E11,D11-E11,E11-D11) -> 0 | H11: =IF(D11>E11,"مدين اكبر",IF(E11>D11,"دائن اكبر","~")) -> ~ | AP11: 0
D12: =SUMIF($I$7:$AX$7,$I$7,I12:AX12) -> 0 | E12: =SUMIF($I$7:$AX$7,$I$7,I21:AX21) -> 0 | F12: =IF(D12=E12,"palance","unpalance") -> palance | G12: =IF(D12>E12,D12-E12,E12-D12) -> 0 | H12: =IF(D12>E12,"مدين اكبر",IF(E12>D12,"دائن اكبر","~")) -> ~ | AP12: 0
D13: =SUMIF($I$7:$AX$7,$I$7,I13:AX13) -> 0 | E13: =SUMIF($I$7:$AX$7,$I$7,I22:AX22) -> 0 | F13: =IF(D13=E13,"palance","unpalance") -> palance | G13: =IF(D13>E13,D13-E13,E13-D13) -> 0 | H13: =IF(D13>E13,"مدين اكبر",IF(E13>D13,"دائن اكبر","~")) -> ~ | AP13: 0
D14: =SUMIF($I$7:$AX$7,$I$7,I14:AX14) -> 0 | E14: =SUMIF($I$7:$AX$7,$I$7,I23:AX23) -> 0 | F14: =IF(D14=E14,"palance","unpalance") -> palance | G14: =IF(D14>E14,D14-E14,E14-D14) -> 0 | H14: =IF(D14>E14,"مدين اكبر",IF(E14>D14,"دائن اكبر","~")) -> ~ | AP14: 0
D15: =SUMIF($I$7:$AX$7,$I$7,I15:AX15) -> 0 | E15: =SUMIF($I$7:$AX$7,$I$7,I24:AX24) -> 0 | F15: =IF(D15=E15,"palance","unpalance") -> palance | G15: =IF(D15>E15,D15-E15,E15-D15) -> 0 | H15: =IF(D15>E15,"مدين اكبر",IF(E15>D15,"دائن اكبر","~")) -> ~ | AP15: 0
D16: =SUMIF($I$7:$AX$7,$I$7,I16:AX16) -> 0 | E16: =SUMIF($I$7:$AX$7,$I$7,I25:AX25) -> 0 | F16: =IF(D16=E16,"palance","unpalance") -> palance | G16: =IF(D16>E16,D16-E16,E16-D16) -> 0 | H16: =IF(D16>E16,"مدين اكبر",IF(E16>D16,"دائن اكبر","~")) -> ~ | AP16: 0
D17: =SUMIF($I$7:$AX$7,$I$7,I17:AX17) -> 0 | E17: =SUMIF($I$7:$AX$7,$I$7,I26:AX26) -> 0 | F17: =IF(D17=E17,"palance","unpalance") -> palance | G17: =IF(D17>E17,D17-E17,E17-D17) -> 0 | H17: =IF(D17>E17,"مدين اكبر",IF(E17>D17,"دائن اكبر","~")) -> ~ | AP17: 0
D18: =SUMIF($I$7:$AX$7,$I$7,I18:AX18) -> 0 | E18: =SUMIF($I$7:$AX$7,$I$7,I27:AX27) -> 0 | F18: =IF(D18=E18,"palance","unpalance") -> palance | G18: =IF(D18>E18,D18-E18,E18-D18) -> 0 | H18: =IF(D18>E18,"مدين اكبر",IF(E18>D18,"دائن اكبر","~")) -> ~ | AP18: 0
D19: =SUMIF($I$7:$AX$7,$I$7,I19:AX19) -> 0 | E19: =SUMIF($I$7:$AX$7,$I$7,I28:AX28) -> 0 | F19: =IF(D19=E19,"palance","unpalance") -> palance | G19: =IF(D19>E19,D19-E19,E19-D19) -> 0 | H19: =IF(D19>E19,"مدين اكبر",IF(E19>D19,"دائن اكبر","~")) -> ~ | AP19: 0
D20: =SUMIF($I$7:$AX$7,$I$7,I20:AX20) -> 0 | E20: 0 | F20: =IF(D20=E20,"palance","unpalance") -> palance | G20: =IF(D20>E20,D20-E20,E20-D20) -> 0 | H20: =IF(D20>E20,"مدين اكبر",IF(E20>D20,"دائن اكبر","~")) -> ~ | AP20: 0
D21: =SUMIF($I$7:$AX$7,$I$7,I21:AX21) -> 0 | E21: =SUMIF($I$7:$AX$7,$I$7,I30:AX30) -> 0 | F21: =IF(D21=E21,"palance","unpalance") -> palance | G21: =IF(D21>E21,D21-E21,E21-D21) -> 0 | H21: =IF(D21>E21,"مدين اكبر",IF(E21>D21,"دائن اكبر","~")) -> ~ | AP21: 0
D22: =SUMIF($I$7:$AX$7,$I$7,I22:AX22) -> 0 | E22: =SUMIF($I$7:$AX$7,$I$7,I31:AX31) -> 0 | F22: =IF(D22=E22,"palance","unpalance") -> palance | G22: =IF(D22>E22,D22-E22,E22-D22) -> 0 | H22: =IF(D22>E22,"مدين اكبر",IF(E22>D22,"دائن اكبر","~")) -> ~ | AP22: 0
D23: =SUMIF($I$7:$AX$7,$I$7,I23:AX23) -> 0 | E23: =SUMIF($I$7:$AX$7,$I$7,I32:AX32) -> 0 | F23: =IF(D23=E23,"palance","unpalance") -> palance | G23: =IF(D23>E23,D23-E23,E23-D23) -> 0 | H23: =IF(D23>E23,"مدين اكبر",IF(E23>D23,"دائن اكبر","~")) -> ~ | AP23: 0
D24: =SUMIF($I$7:$AX$7,$I$7,I24:AX24) -> 0 | E24: =SUMIF($I$7:$AX$7,$I$7,I33:AX33) -> 0 | F24: =IF(D24=E24,"palance","unpalance") -> palance | G24: =IF(D24>E24,D24-E24,E24-D24) -> 0 | H24: =IF(D24>E24,"مدين اكبر",IF(E24>D24,"دائن اكبر","~")) -> ~ | AP24: 0
D25: =SUMIF($I$7:$AX$7,$I$7,I25:AX25) -> 0 | E25: =SUMIF($I$7:$AX$7,$I$7,I34:AX34) -> 0 | F25: =IF(D25=E25,"palance","unpalance") -> palance | G25: =IF(D25>E25,D25-E25,E25-D25) -> 0 | H25: =IF(D25>E25,"مدين اكبر",IF(E25>D25,"دائن اكبر","~")) -> ~ | AP25: 0
D26: =SUMIF($I$7:$AX$7,$I$7,I26:AX26) -> 0 | E26: =SUMIF($I$7:$AX$7,$I$7,I35:AX35) -> 0 | F26: =IF(D26=E26,"palance","unpalance") -> palance | G26: =IF(D26>E26,D26-E26,E26-D26) -> 0 | H26: =IF(D26>E26,"مدين اكبر",IF(E26>D26,"دائن اكبر","~")) -> ~ | AP26: 0
D27: =SUMIF($I$7:$AX$7,$I$7,I27:AX27) -> 0 | E27: =SUMIF($I$7:$AX$7,$I$7,I36:AX36) -> 0 | F27: =IF(D27=E27,"palance","unpalance") -> palance | G27: =IF(D27>E27,D27-E27,E27-D27) -> 0 | H27: =IF(D27>E27,"مدين اكبر",IF(E27>D27,"دائن اكبر","~")) -> ~ | AP27: 0
D28: =SUMIF($I$7:$AX$7,$I$7,I28:AX28) -> 0 | E28: =SUMIF($I$7:$AX$7,$I$7,I37:AX37) -> 0 | F28: =IF(D28=E28,"palance","unpalance") -> palance | G28: =IF(D28>E28,D28-E28,E28-D28) -> 0 | H28: =IF(D28>E28,"مدين اكبر",IF(E28>D28,"دائن اكبر","~")) -> ~ | AP28: 0
A29: الاجمالي | D29: 0 | E29: =SUMIF($I$7:$AX$7,$I$7,I38:AX38) -> 0 | F29: =IF(D29=E29,"palance","unpalance") -> palance | G29: =IF(D29>E29,D29-E29,E29-D29) -> 0 | H29: =IF(D29>E29,"مدين اكبر",IF(E29>D29,"دائن اكبر","~")) -> ~ | I29: =SUM(I8:I28) -> 0 | J29: =SUM(J8:J28) -> 0 | K29: =SUM(K8:K28) -> 0 | L29: =SUM(L8:L28) -> 0 | M29: =SUM(M8:M28) -> 0 | N29: =SUM(N8:N28) -> 0 | O29: =SUM(O8:O28) -> 0 | P29: =SUM(P8:P28) -> 0 | ... AX29: =SUM(AX8:AX28) -> 0

Sheet 1
A1: شركة المتحدة
A2: قسم الحسابات
A3: السنة المالية2021 | I3: =I29-J29+opining!I3 -> 0 | K3: =K29-L29+opining!K3 -> 0 | M3: =M29-N29+opining!M3 -> 0 | O3: =O29-P29+opining!O3 -> 0 | Q3: =Q29-R29+opining!Q3 -> 0 | S3: =S29-T29+opining!S3 -> 0 | U3: =U29-V29+opining!U3 -> 0 | W3: =W29-X29+opining!W3 -> 0 | Y3: =Y29-Z29+opining!Y3 -> 0 | AA3: =AA29-AB29+opining!AA3 -> 0 | AC3: =AC29-AD29+opining!AC3 -> 0 | AE3: =AE29-AF29+opining!AE3 -> 0 | AG3: =AG29-AH29+opining!AG3 -> 0 | AI3: =AI29-AJ29+opining!AI3 -> 0 | AK3: =AK29-AL29+opining!AK3 -> 0 | AM3: =AM29-AN29+opining!AM3 -> 0 | AO3: =AO29-AP29+opining!AO3 -> 0 | AQ3: =AQ29-AR29+opining!AQ3 -> 0 | AS3: =AS29-AT29+opining!AS3 -> 0 | AU3: =AU29-AV29+opining!AU3 -> 0 | AW3: =AW29-AX29+opining!AW3 -> 0
A4: دليل الحسابات
A6: رقم القيد | B6: التاريخ | C6: البيان | D6: الاجمالي | F6: contorl | G6: الفرق | I6: النقدية | K6: بنك مصر | M6: مدينونTele | O6: Teachمدينون | Q6: ادوات كتابية | S6: السيارات | U6: مجمع اهلاك سيارات | W6: الاثاث | Y6: مجمع اهلاك الاثاث | AA6: مباني | AC6: معدات | AE6: الاراضي | AG6: دائنونGlobal | AI6: مصروف صيانة | AK6: رواتب واجور | AM6: مصروف اهلاك | AO6: ايرادات | AQ6: راس المال | AS6: مسحوبات | AU6: حساب1 | AW6: حساب2
D7: مدين | E7: دائن | I7: مدين | J7: دائن | K7: مدين | L7: دائن | M7: مدين | N7: دائن | O7: مدين | P7: دائن | Q7: مدين | R7: دائن | S7: مدين | T7: دائن | U7: مدين | V7: دائن | W7: مدين | X7: دائن | Y7: مدين | Z7: دائن | AA7: مدين | AB7: دائن | AC7: مدين | AD7: دائن | AE7: مدين | AF7: دائن | AG7: مدين | AH7: دائن | AI7: مدين | AJ7: دائن | AK7: مدين | AL7: دائن | AM7: مدين | AN7: دائن | AO7: مدين | AP7: دائن | AQ7: مدين | AR7: دائن | AS7: مدين | AT7: دائن | AU7: مدين | AV7: دائن | AW7: مدين | AX7: دائن
D8: =SUMIF($I$7:$AX$7,$I$7,I8:AX8) -> 0 | E8: 0 | F8: =IF(D8=E8,"palance","unpalance") -> palance | G8: =IF(D8>E8,D8-E8,E8-D8) -> 0 | H8: =IF(D8>E8,"مدين اكبر",IF(E8>D8,"دائن اكبر","~")) -> ~ | AP8: 0
D9: =SUMIF($I$7:$AX$7,$I$7,I9:AX9) -> 0 | E9: 0 | F9: =IF(D9=E9,"palance","unpalance") -> palance | G9: =IF(D9>E9,D9-E9,E9-D9) -> 0 | H9: =IF(D9>E9,"مدين اكبر",IF(E9>D9,"دائن اكبر","~")) -> ~ | I9: 0 | AP9: 0
D10: =SUMIF($I$7:$AX$7,$I$7,I10:AX10) -> 0 | E10: =SUMIF($I$7:$AX$7,$J$7,I10:AX10) -> 0 | F10: =IF(D10=E10,"palance","unpalance") -> palance | G10: =IF(D10>E10,D10-E10,E10-D10) -> 0 | H10: =IF(D10>E10,"مدين اكبر",IF(E10>D10,"دائن اكبر","~")) -> ~
D11: =SUMIF($I$7:$AX$7,$I$7,I11:AX11) -> 0 | E11: =SUMIF($I$7:$AX$7,$J$7,I11:AX11) -> 0 | F11: =IF(D11=E11,"palance","unpalance") -> palance | G11: =IF(D11>E11,D11-E11,E11-D11) -> 0 | H11: =IF(D11>E11,"مدين اكبر",IF(E11>D11,"دائن اكبر","~")) -> ~
D12: =SUMIF($I$7:$AX$7,$I$7,I12:AX12) -> 0 | E12: 0 | F12: =IF(D12=E12,"palance","unpalance") -> palance | G12: =IF(D12>E12,D12-E12,E12-D12) -> 0 | H12: =IF(D12>E12,"مدين اكبر",IF(E12>D12,"دائن اكبر","~")) -> ~
D13: 0 | E13: =SUMIF($I$7:$AX$7,$J$7,I13:AX13) -> 0 | F13: =IF(D13=E13,"palance","unpalance") -> palance | G13: =IF(D13>E13,D13-E13,E13-D13) -> 0 | H13: =IF(D13>E13,"مدين اكبر",IF(E13>D13,"دائن اكبر","~")) -> ~
D14: =SUMIF($I$7:$AX$7,$I$7,I14:AX14) -> 0 | E14: =SUMIF($I$7:$AX$7,$J$7,I14:AX14) -> 0 | F14: =IF(D14=E14,"palance","unpalance") -> palance | G14: =IF(D14>E14,D14-E14,E14-D14) -> 0 | H14: =IF(D14>E14,"مدين اكبر",IF(E14>D14,"دائن اكبر","~")) -> ~
D15: =SUMIF($I$7:$AX$7,$I$7,I15:AX15) -> 0 | E15: =SUMIF($I$7:$AX$7,$J$7,I15:AX15) -> 0 | F15: =IF(D15=E15,"palance","unpalance") -> palance | G15: =IF(D15>E15,D15-E15,E15-D15) -> 0 | H15: =IF(D15>E15,"مدين اكبر",IF(E15>D15,"دائن اكبر","~")) -> ~
D16: =SUMIF($I$7:$AX$7,$I$7,I16:AX16) -> 0 | E16: =SUMIF($I$7:$AX$7,$J$7,I16:AX16) -> 0 | F16: =IF(D16=E16,"palance","unpalance") -> palance | G16: =IF(D16>E16,D16-E16,E16-D16) -> 0 | H16: =IF(D16>E16,"مدين اكبر",IF(E16>D16,"دائن اكبر","~")) -> ~
D17: =SUMIF($I$7:$AX$7,$I$7,I17:AX17) -> 0 | E17: =SUMIF($I$7:$AX$7,$J$7,I17:AX17) -> 0 | F17: =IF(D17=E17,"palance","unpalance") -> palance | G17: =IF(D17>E17,D17-E17,E17-D17) -> 0 | H17: =IF(D17>E17,"مدين اكبر",IF(E17>D17,"دائن اكبر","~")) -> ~
D18: =SUMIF($I$7:$AX$7,$I$7,I18:AX18) -> 0 | E18: =SUMIF($I$7:$AX$7,$J$7,I18:AX18) -> 0 | F18: =IF(D18=E18,"palance","unpalance") -> palance | G18: =IF(D18>E18,D18-E18,E18-D18) -> 0 | H18: =IF(D18>E18,"مدين اكبر",IF(E18>D18,"دائن اكبر","~")) -> ~
D19: =SUMIF($I$7:$AX$7,$I$7,I19:AX19) -> 0 | E19: =SUMIF($I$7:$AX$7,$J$7,I19:AX19) -> 0 | F19: =IF(D19=E19,"palance","unpalance") -> palance | G19: =IF(D19>E19,D19-E19,E19-D19) -> 0 | H19: =IF(D19>E19,"مدين اكبر",IF(E19>D19,"دائن اكبر","~")) -> ~
D20: =SUMIF($I$7:$AX$7,$I$7,I20:AX20) -> 0 | E20: =SUMIF($I$7:$AX$7,$J$7,I20:AX20) -> 0 | F20: =IF(D20=E20,"palance","unpalance") -> palance | G20: =IF(D20>E20,D20-E20,E20-D20) -> 0 | H20: =IF(D20>E20,"مدين اكبر",IF(E20>D20,"دائن اكبر","~")) -> ~
D21: =SUMIF($I$7:$AX$7,$I$7,I21:AX21) -> 0 | E21: =SUMIF($I$7:$AX$7,$J$7,I21:AX21) -> 0 | F21: =IF(D21=E21,"palance","unpalance") -> palance | G21: =IF(D21>E21,D21-E21,E21-D21) -> 0 | H21: =IF(D21>E21,"مدين اكبر",IF(E21>D21,"دائن اكبر","~")) -> ~
D22: =SUMIF($I$7:$AX$7,$I$7,I22:AX22) -> 0 | E22: =SUMIF($I$7:$AX$7,$J$7,I22:AX22) -> 0 | F22: =IF(D22=E22,"palance","unpalance") -> palance | G22: =IF(D22>E22,D22-E22,E22-D22) -> 0 | H22: =IF(D22>E22,"مدين اكبر",IF(E22>D22,"دائن اكبر","~")) -> ~
D23: =SUMIF($I$7:$AX$7,$I$7,I23:AX23) -> 0 | E23: =SUMIF($I$7:$AX$7,$J$7,I23:AX23) -> 0 | F23: =IF(D23=E23,"palance","unpalance") -> palance | G23: =IF(D23>E23,D23-E23,E23-D23) -> 0 | H23: =IF(D23>E23,"مدين اكبر",IF(E23>D23,"دائن اكبر","~")) -> ~
E24: =SUMIF($I$7:$AX$7,$J$7,I24:AX24) -> 0 | F24: =IF(D24=E24,"palance","unpalance") -> palance | G24: =IF(D24>E24,D24-E24,E24-D24) -> 0 | H24: =IF(D24>E24,"مدين اكبر",IF(E24>D24,"دائن اكبر","~")) -> ~
D25: =SUMIF($I$7:$AX$7,$I$7,I25:AX25) -> 0 | E25: =SUMIF($I$7:$AX$7,$J$7,I25:AX25) -> 0 | F25: =IF(D25=E25,"palance","unpalance") -> palance | G25: =IF(D25>E25,D25-E25,E25-D25) -> 0 | H25: =IF(D25>E25,"مدين اكبر",IF(E25>D25,"دائن اكبر","~")) -> ~
D26: =SUMIF($I$7:$AX$7,$I$7,I26:AX26) -> 0 | E26: =SUMIF($I$7:$AX$7,$J$7,I26:AX26) -> 0 | F26: =IF(D26=E26,"palance","unpalance") -> palance | G26: =IF(D26>E26,D26-E26,E26-D26) -> 0 | H26: =IF(D26>E26,"مدين اكبر",IF(E26>D26,"دائن اكبر","~")) -> ~ | AQ26: 0 | AR26: 0
D27: =SUMIF($I$7:$AX$7,$I$7,I27:AX27) -> 0 | E27: =SUMIF($I$7:$AX$7,$J$7,I27:AX27) -> 0 | F27: =IF(D27=E27,"palance","unpalance") -> palance | G27: =IF(D27>E27,D27-E27,E27-D27) -> 0 | H27: =IF(D27>E27,"مدين اكبر",IF(E27>D27,"دائن اكبر","~")) -> ~
D28: 0 | E28: =SUMIF($I$7:$AX$7,$J$7,I28:AX28) -> 0 | F28: =IF(D28=E28,"palance","unpalance") -> palance | G28: =IF(D28>E28,D28-E28,E28-D28) -> 0 | H28: =IF(D28>E28,"مدين اكبر",IF(E28>D28,"دائن اكبر","~")) -> ~ | I28: 0 | AQ28: 0
A29: الاجمالي | F29: =IF(D29=E29,"palance","unpalance") -> palance | G29: =IF(D29>E29,D29-E29,E29-D29) -> 0 | H29: =IF(D29>E29,"مدين اكبر",IF(E29>D29,"دائن اكبر","~")) -> ~ | I29: =SUM(I8:I28) -> 0 | J29: =SUM(J8:J28) -> 0 | K29: =SUM(K8:K28) -> 0 | L29: =SUM(L8:L28) -> 0 | M29: =SUM(M8:M28) -> 0 | N29: =SUM(N8:N28) -> 0 | O29: =SUM(O8:O28) -> 0 | P29: =SUM(P8:P28) -> 0 | ... AX29: =SUM(AX8:AX28) -> 0

Sheet 2
A1: شركة المتحدة
A2: قسم الحسابات
A3: السنة المالية2021 | I3: 0 | K3: =K29-L29+'1'!K3 -> 0 | M3: =M29-N29+'1'!M3 -> 0 | O3: =O29-P29+'1'!O3 -> 0 | Q3: =Q29-R29+'1'!Q3 -> 0 | S3: =S29-T29+'1'!S3 -> 0 | U3: =U29-V29+'1'!U3 -> 0 | W3: =W29-X29+'1'!W3 -> 0 | Y3: =Y29-Z29+'1'!Y3 -> 0 | AA3: =AA29-AB29+'1'!AA3 -> 0 | AC3: =AC29-AD29+'1'!AC3 -> 0 | AE3: =AE29-AF29+'1'!AE3 -> 0 | AG3: =AG29-AH29+'1'!AG3 -> 0 | AI3: =AI29-AJ29+'1'!AI3 -> 0 | AK3: =AK29-AL29+'1'!AK3 -> 0 | AM3: =AM29-AN29+'1'!AM3 -> 0 | AO3: =AO29-AP29+'1'!AO3 -> 0 | AQ3: =AQ29-AR29+'1'!AQ3 -> 0 | AS3: =AS29-AT29+'1'!AS3 -> 0 | AU3: =AU29-AV29+'1'!AU3 -> 0 | AW3: =AW29-AX29+'1'!AW3 -> 0
A4: دليل الحسابات
A6: رقم القيد | B6: التاريخ | C6: البيان | D6: الاجمالي | F6: contorl | G6: الفرق | I6: النقدية | K6: بنك مصر | M6: مدينونTele | O6: Teachمدينون | Q6: ادوات كتابية | S6: السيارات | U6: مجمع اهلاك سيارات | W6: الاثاث | Y6: مجمع اهلاك الاثاث | AA6: مباني | AC6: معدات | AE6: الاراضي | AG6: دائنونGlobal | AI6: مصروف صيانة | AK6: رواتب واجور | AM6: مصروف اهلاك | AO6: ايرادات | AQ6: راس المال | AS6: مسحوبات | AU6: حساب1 | AW6: حساب2
D7: مدين | E7: دائن | I7: مدين | J7: دائن | K7: مدين | L7: دائن | M7: مدين | N7: دائن | O7: مدين | P7: دائن | Q7: مدين | R7: دائن | S7: مدين | T7: دائن | U7: مدين | V7: دائن | W7: مدين | X7: دائن | Y7: مدين | Z7: دائن | AA7: مدين | AB7: دائن | AC7: مدين | AD7: دائن | AE7: مدين | AF7: دائن | AG7: مدين | AH7: دائن | AI7: مدين | AJ7: دائن | AK7: مدين | AL7: دائن | AM7: مدين | AN7: دائن | AO7: مدين | AP7: دائن | AQ7: مدين | AR7: دائن | AS7: مدين | AT7: دائن | AU7: مدين | AV7: دائن | AW7: مدين | AX7: دائن
D8: 500 | E8: =SUMIF($I$7:$AX$7,$J$7,I8:AX8) -> 0 | F8: =IF(D8=E8,"palance","unpalance") -> unpalance | G8: =IF(D8>E8,D8-E8,E8-D8) -> 500 | H8: =IF(D8>E8,"مدين اكبر",IF(E8>D8,"دائن اكبر","~")) -> مدين اكبر | AP8: 0
D9: =SUMIF($I$7:$AX$7,$I$7,I9:AX9) -> 0 | E9: =SUMIF($I$7:$AX$7,$J$7,I9:AX9) -> 0 | F9: =IF(D9=E9,"palance","unpalance") -> palance | G9: =IF(D9>E9,D9-E9,E9-D9) -> 0 | H9: =IF(D9>E9,"مدين اكبر",IF(E9>D9,"دائن اكبر","~")) -> ~ | AP9: 0
D10: =SUMIF($I$7:$AX$7,$I$7,I10:AX10) -> 0 | E10: =SUMIF($I$7:$AX$7,$J$7,I10:AX10) -> 0 | F10: =IF(D10=E10,"palance","unpalance") -> palance | G10: =IF(D10>E10,D10-E10,E10-D10) -> 0 | H10: =IF(D10>E10,"مدين اكبر",IF(E10>D10,"دائن اكبر","~")) -> ~
D11: =SUMIF($I$7:$AX$7,$I$7,I11:AX11) -> 0 | E11: =SUMIF($I$7:$AX$7,$J$7,I11:AX11) -> 0 | F11: =IF(D11=E11,"palance","unpalance") -> palance | G11: =IF(D11>E11,D11-E11,E11-D11) -> 0 | H11: =IF(D11>E11,"مدين اكبر",IF(E11>D11,"دائن اكبر","~")) -> ~
D12: =SUMIF($I$7:$AX$7,$I$7,I12:AX12) -> 0 | E12: =SUMIF($I$7:$AX$7,$J$7,I12:AX12) -> 0 | F12: =IF(D12=E12,"palance","unpalance") -> palance | G12: =IF(D12>E12,D12-E12,E12-D12) -> 0 | H12: =IF(D12>E12,"مدين اكبر",IF(E12>D12,"دائن اكبر","~")) -> ~
D13: =SUMIF($I$7:$AX$7,$I$7,I13:AX13) -> 0 | E13: =SUMIF($I$7:$AX$7,$J$7,I13:AX13) -> 0 | F13: =IF(D13=E13,"palance","unpalance") -> palance | G13: =IF(D13>E13,D13-E13,E13-D13) -> 0 | H13: =IF(D13>E13,"مدين اكبر",IF(E13>D13,"دائن اكبر","~")) -> ~
D14: =SUMIF($I$7:$AX$7,$I$7,I14:AX14) -> 0 | E14: =SUMIF($I$7:$AX$7,$J$7,I14:AX14) -> 0 | F14: =IF(D14=E14,"palance","unpalance") -> palance | G14: =IF(D14>E14,D14-E14,E14-D14) -> 0 | H14: =IF(D14>E14,"مدين اكبر",IF(E14>D14,"دائن اكبر","~")) -> ~
D15: =SUMIF($I$7:$AX$7,$I$7,I15:AX15) -> 0 | E15: =SUMIF($I$7:$AX$7,$J$7,I15:AX15) -> 0 | F15: =IF(D15=E15,"palance","unpalance") -> palance | G15: =IF(D15>E15,D15-E15,E15-D15) -> 0 | H15: =IF(D15>E15,"مدين اكبر",IF(E15>D15,"دائن اكبر","~")) -> ~
D16: =SUMIF($I$7:$AX$7,$I$7,I16:AX16) -> 0 | E16: =SUMIF($I$7:$AX$7,$J$7,I16:AX16) -> 0 | F16: =IF(D16=E16,"palance","unpalance") -> palance | G16: =IF(D16>E16,D16-E16,E16-D16) -> 0 | H16: =IF(D16>E16,"مدين اكبر",IF(E16>D16,"دائن اكبر","~")) -> ~
D17: =SUMIF($I$7:$AX$7,$I$7,I17:AX17) -> 0 | E17: =SUMIF($I$7:$AX$7,$J$7,I17:AX17) -> 0 | F17: =IF(D17=E17,"palance","unpalance") -> palance | G17: =IF(D17>E17,D17-E17,E17-D17) -> 0 | H17: =IF(D17>E17,"مدين اكبر",IF(E17>D17,"دائن اكبر","~")) -> ~
D18: =SUMIF($I$7:$AX$7,$I$7,I18:AX18) -> 0 | E18: =SUMIF($I$7:$AX$7,$J$7,I18:AX18) -> 0 | F18: =IF(D18=E18,"palance","unpalance") -> palance | G18: =IF(D18>E18,D18-E18,E18-D18) -> 0 | H18: =IF(D18>E18,"مدين اكبر",IF(E18>D18,"دائن اكبر","~")) -> ~
D19: =SUMIF($I$7:$AX$7,$I$7,I19:AX19) -> 0 | E19: =SUMIF($I$7:$AX$7,$J$7,I19:AX19) -> 0 | F19: =IF(D19=E19,"palance","unpalance") -> palance | G19: =IF(D19>E19,D19-E19,E19-D19) -> 0 | H19: =IF(D19>E19,"مدين اكبر",IF(E19>D19,"دائن اكبر","~")) -> ~
D20: =SUMIF($I$7:$AX$7,$I$7,I20:AX20) -> 0 | E20: =SUMIF($I$7:$AX$7,$J$7,I20:AX20) -> 0 | F20: =IF(D20=E20,"palance","unpalance") -> palance | G20: =IF(D20>E20,D20-E20,E20-D20) -> 0 | H20: =IF(D20>E20,"مدين اكبر",IF(E20>D20,"دائن اكبر","~")) -> ~
D21: =SUMIF($I$7:$AX$7,$I$7,I21:AX21) -> 0 | E21: =SUMIF($I$7:$AX$7,$J$7,I21:AX21) -> 0 | F21: =IF(D21=E21,"palance","unpalance") -> palance | G21: =IF(D21>E21,D21-E21,E21-D21) -> 0 | H21: =IF(D21>E21,"مدين اكبر",IF(E21>D21,"دائن اكبر","~")) -> ~
... D28: =SUMIF($I$7:$AX$7,$I$7,I28:AX28) -> 0 | E28: =SUMIF($I$7:$AX$7,$J$7,I28:AX28) -> 0 | F28: =IF(D28=E28,"palance","unpalance") -> palance | G28: =IF(D28>E28,D28-E28,E28-D28) -> 0 | H28: =IF(D28>E28,"مدين اكبر",IF(E28>D28,"دائن اكبر","~")) -> ~
A29: الاجمالي | F29: =IF(D29=E29,"palance","unpalance") -> palance | G29: =IF(D29>E29,D29-E29,E29-D29) -> 0 | H29: =IF(D29>E29,"مدين اكبر",IF(E29>D29,"دائن اكبر","~")) -> ~ | I29: =SUM(I8:I28) -> 0 | J29: =SUM(J8:J28) -> 0 | K29: =SUM(K8:K28) -> 0 | L29: =SUM(L8:L28) -> 0 | M29: =SUM(M8:M28) -> 0 | N29: =SUM(N8:N28) -> 0 | O29: =SUM(O8:O28) -> 0 | P29: =SUM(P8:P28) -> 0 | ... AX29: =SUM(AX8:AX28) -> 0

Sheet 3
A1: شركة المتحدة
A2: قسم الحسابات
A3: السنة المالية2021 | I3: =I29-J29+'2'!I3 -> 0 | K3: =K29-L29+'2'!K3 -> 0 | M3: =M29-N29+'2'!M3 -> 0 | O3: =O29-P29+'2'!O3 -> 0 | Q3: =Q29-R29+'2'!Q3 -> 0 | S3: =S29-T29+'2'!S3 -> 0 | U3: =U29-V29+'2'!U3 -> 0 | W3: =W29-X29+'2'!W3 -> 0 | Y3: =Y29-Z29+'2'!Y3 -> 0 | AA3: =AA29-AB29+'2'!AA3 -> 0 | AC3: =AC29-AD29+'2'!AC3 -> 0 | AE3: =AE29-AF29+'2'!AE3 -> 0 | AG3: =AG29-AH29+'2'!AG3 -> 0 | AI3: =AI29-AJ29+'2'!AI3 -> 0 | AK3: =AK29-AL29+'2'!AK3 -> 0 | AM3: =AM29-AN29+'2'!AM3 -> 0 | AO3: =AO29-AP29+'2'!AO3 -> 0 | AQ3: =AQ29-AR29+'2'!AQ3 -> 0 | AS3: =AS29-AT29+'2'!AS3 -> 0 | AU3: =AU29-AV29+'2'!AU3 -> 0 | AW3: =AW29-AX29+'2'!AW3 -> 0
A4: دليل الحسابات
A6: رقم القيد | B6: التاريخ | C6: البيان | D6: الاجمالي | F6: contorl | G6: الفرق | I6: النقدية | K6: بنك مصر | M6: مدينونTele | O6: Teachمدينون | Q6: ادوات كتابية | S6: السيارات | U6: مجمع اهلاك سيارات | W6: الاثاث | Y6: مجمع اهلاك الاثاث | AA6: مباني | AC6: معدات | AE6: الاراضي | AG6: دائنونGlobal | AI6: مصروف صيانة | AK6: رواتب واجور | AM6: مصروف اهلاك | AO6: ايرادات | AQ6: راس المال | AS6: مسحوبات | AU6: حساب1 | AW6: حساب2
D7: مدين | E7: دائن | I7: مدين | J7: دائن | K7: مدين | L7: دائن | M7: مدين | N7: دائن | O7: مدين | P7: دائن | Q7: مدين | R7: دائن | S7: مدين | T7: دائن | U7: مدين | V7: دائن | W7: مدين | X7: دائن | Y7: مدين | Z7: دائن | AA7: مدين | AB7: دائن | AC7: مدين | AD7: دائن | AE7: مدين | AF7: دائن | AG7: مدين | AH7: دائن | AI7: مدين | AJ7: دائن | AK7: مدين | AL7: دائن | AM7: مدين | AN7: دائن | AO7: مدين | AP7: دائن | AQ7: مدين | AR7: دائن | AS7: مدين | AT7: دائن | AU7: مدين | AV7: دائن | AW7: مدين | AX7: دائن
D8: 0 | E8: =SUMIF($I$7:$AX$7,$J$7,I8:AX8) -> 0 | F8: =IF(D8=E8,"palance","unpalance") -> palance | G8: =IF(D8>E8,D8-E8,E8-D8) -> 0 | H8: =IF(D8>E8,"مدين اكبر",IF(E8>D8,"دائن اكبر","~")) -> ~ | AP8: 0
D9: 0 | E9: =SUMIF($I$7:$AX$7,$J$7,I9:AX9) -> 0 | F9: =IF(D9=E9,"palance","unpalance") -> palance | G9: =IF(D9>E9,D9-E9,E9-D9) -> 0 | H9: =IF(D9>E9,"مدين اكبر",IF(E9>D9,"دائن اكبر","~")) -> ~ | AP9: 0
D10: =SUMIF($I$7:$AX$7,$I$7,I10:AX10) -> 0 | E10: =SUMIF($I$7:$AX$7,$J$7,I10:AX10) -> 0 | F10: =IF(D10=E10,"palance","unpalance") -> palance | G10: =IF(D10>E10,D10-E10,E10-D10) -> 0 | H10: =IF(D10>E10,"مدين اكبر",IF(E10>D10,"دائن اكبر","~")) -> ~
D11: =SUMIF($I$7:$AX$7,$I$7,I11:AX11) -> 0 | E11: =SUMIF($I$7:$AX$7,$J$7,I11:AX11) -> 0 | F11: =IF(D11=E11,"palance","unpalance") -> palance | G11: =IF(D11>E11,D11-E11,E11-D11) -> 0 | H11: =IF(D11>E11,"مدين اكبر",IF(E11>D11,"دائن اكبر","~")) -> ~
D12: =SUMIF($I$7:$AX$7,$I$7,I12:AX12) -> 0 | E12: =SUMIF($I$7:$AX$7,$J$7,I12:AX12) -> 0 | F12: =IF(D12=E12,"palance","unpalance") -> palance | G12: =IF(D12>E12,D12-E12,E12-D12) -> 0 | H12: =IF(D12>E12,"مدين اكبر",IF(E12>D12,"دائن اكبر","~")) -> ~
D13: =SUMIF($I$7:$AX$7,$I$7,I13:AX13) -> 0 | E13: =SUMIF($I$7:$AX$7,$J$7,I13:AX13) -> 0 | F13: =IF(D13=E13,"palance","unpalance") -> palance | G13: =IF(D13>E13,D13-E13,E13-D13) -> 0 | H13: =IF(D13>E13,"مدين اكبر",IF(E13>D13,"دائن اكبر","~")) -> ~
D14: =SUMIF($I$7:$AX$7,$I$7,I14:AX14) -> 0 | E14: =SUMIF($I$7:$AX$7,$J$7,I14:AX14) -> 0 | F14: =IF(D14=E14,"palance","unpalance") -> palance | G14: =IF(D14>E14,D14-E14,E14-D14) -> 0 | H14: =IF(D14>E14,"مدين اكبر",IF(E14>D14,"دائن اكبر","~")) -> ~
D15: =SUMIF($I$7:$AX$7,$I$7,I15:AX15) -> 0 | E15: =SUMIF($I$7:$AX$7,$J$7,I15:AX15) -> 0 | F15: =IF(D15=E15,"palance","unpalance") -> palance | G15: =IF(D15>E15,D15-E15,E15-D15) -> 0 | H15: =IF(D15>E15,"مدين اكبر",IF(E15>D15,"دائن اكبر","~")) -> ~
D16: =SUMIF($I$7:$AX$7,$I$7,I16:AX16) -> 0 | E16: =SUMIF($I$7:$AX$7,$J$7,I16:AX16) -> 0 | F16: =IF(D16=E16,"palance","unpalance") -> palance | G16: =IF(D16>E16,D16-E16,E16-D16) -> 0 | H16: =IF(D16>E16,"مدين اكبر",IF(E16>D16,"دائن اكبر","~")) -> ~
D17: =SUMIF($I$7:$AX$7,$I$7,I17:AX17) -> 0 | E17: =SUMIF($I$7:$AX$7,$J$7,I17:AX17) -> 0 | F17: =IF(D17=E17,"palance","unpalance") -> palance | G17: =IF(D17>E17,D17-E17,E17-D17) -> 0 | H17: =IF(D17>E17,"مدين اكبر",IF(E17>D17,"دائن اكبر","~")) -> ~
D18: =SUMIF($I$7:$AX$7,$I$7,I18:AX18) -> 0 | E18: =SUMIF($I$7:$AX$7,$J$7,I18:AX18) -> 0 | F18: =IF(D18=E18,"palance","unpalance") -> palance | G18: =IF(D18>E18,D18-E18,E18-D18) -> 0 | H18: =IF(D18>E18,"مدين اكبر",IF(E18>D18,"دائن اكبر","~")) -> ~
D19: =SUMIF($I$7:$AX$7,$I$7,I19:AX19) -> 0 | E19: =SUMIF($I$7:$AX$7,$J$7,I19:AX19) -> 0 | F19: =IF(D19=E19,"palance","unpalance") -> palance | G19: =IF(D19>E19,D19-E19,E19-D19) -> 0 | H19: =IF(D19>E19,"مدين اكبر",IF(E19>D19,"دائن اكبر","~")) -> ~
D20: =SUMIF($I$7:$AX$7,$I$7,I20:AX20) -> 0 | E20: =SUMIF($I$7:$AX$7,$J$7,I20:AX20) -> 0 | F20: =IF(D20=E20,"palance","unpalance") -> palance | G20: =IF(D20>E20,D20-E20,E20-D20) -> 0 | H20: =IF(D20>E20,"مدين اكبر",IF(E20>D20,"دائن اكبر","~")) -> ~
D21: =SUMIF($I$7:$AX$7,$I$7,I21:AX21) -> 0 | E21: =SUMIF($I$7:$AX$7,$J$7,I21:AX21) -> 0 | F21: =IF(D21=E21,"palance","unpalance") -> palance | G21: =IF(D21>E21,D21-E21,E21-D21) -> 0 | H21: =IF(D21>E21,"مدين اكبر",IF(E21>D21,"دائن اكبر","~")) -> ~
... D28: =SUMIF($I$7:$AX$7,$I$7,I28:AX28) -> 0 | E28: =SUMIF($I$7:$AX$7,$J$7,I28:AX28) -> 0 | F28: =IF(D28=E28,"palance","unpalance") -> palance | G28: =IF(D28>E28,D28-E28,E28-D28) -> 0 | H28: =IF(D28>E28,"مدين اكبر",IF(E28>D28,"دائن اكبر","~")) -> ~
A29: الاجمالي | F29: =IF(D29=E29,"palance","unpalance") -> palance | G29: =IF(D29>E29,D29-E29,E29-D29) -> 0 | H29: =IF(D29>E29,"مدين اكبر",IF(E29>D29,"دائن اكبر","~")) -> ~ | I29: =SUM(I8:I28) -> 0 | J29: =SUM(J8:J28) -> 0 | K29: =SUM(K8:K28) -> 0 | L29: =SUM(L8:L28) -> 0 | M29: =SUM(M8:M28) -> 0 | N29: =SUM(N8:N28) -> 0 | O29: =SUM(O8:O28) -> 0 | P29: =SUM(P8:P28) -> 0 | ... AX29: =SUM(AX8:AX28) -> 0

Sheet 4
A1: شركة المتحدة
A2: قسم الحسابات
A3: السنة المالية2021 | I3: =I29-J29+'3'!I3 -> 0 | K3: =K29-L29+'3'!K3 -> 0 | M3: =M29-N29+'3'!M3 -> 0 | O3: =O29-P29+'3'!O3 -> 0 | Q3: =Q29-R29+'3'!Q3 -> 0 | S3: =S29-T29+'3'!S3 -> 0 | U3: =U29-V29+'3'!U3 -> 0 | W3: =W29-X29+'3'!W3 -> 0 | Y3: =Y29-Z29+'3'!Y3 -> 0 | AA3: =AA29-AB29+'3'!AA3 -> 0 | AC3: =AC29-AD29+'3'!AC3 -> 0 | AE3: =AE29-AF29+'3'!AE3 -> 0 | AG3: =AG29-AH29+'3'!AG3 -> 0 | AI3: =AI29-AJ29+'3'!AI3 -> 0 | AK3: =AK29-AL29+'3'!AK3 -> 0 | AM3: =AM29-AN29+'3'!AM3 -> 0 | AO3: =AO29-AP29+'3'!AO3 -> 0 | AQ3: =AQ29-AR29+'3'!AQ3 -> 0 | AS3: =AS29-AT29+'3'!AS3 -> 0 | AU3: =AU29-AV29+'3'!AU3 -> 0 | AW3: =AW29-AX29+'3'!AW3 -> 0
A4: دليل الحسابات
A6: رقم القيد | B6: التاريخ | C6: البيان | D6: الاجمالي | F6: contorl | G6: الفرق | I6: النقدية | K6: بنك مصر | M6: مدينونTele | O6: Teachمدينون | Q6: ادوات كتابية | S6: السيارات | U6: مجمع اهلاك سيارات | W6: الاثاث | Y6: مجمع اهلاك الاثاث | AA6: مباني | AC6: معدات | AE6: الاراضي | AG6: دائنونGlobal | AI6: مصروف صيانة | AK6: رواتب واجور | AM6: مصروف اهلاك | AO6: ايرادات | AQ6: راس المال | AS6: مسحوبات | AU6: حساب1 | AW6: حساب2
D7: مدين | E7: دائن | I7: مدين | J7: دائن | K7: مدين | L7: دائن | M7: مدين | N7: دائن | O7: مدين | P7: دائن | Q7: مدين | R7: دائن | S7: مدين | T7: دائن | U7: مدين | V7: دائن | W7: مدين | X7: دائن | Y7: مدين | Z7: دائن | AA7: مدين | AB7: دائن | AC7: مدين | AD7: دائن | AE7: مدين | AF7: دائن | AG7: مدين | AH7: دائن | AI7: مدين | AJ7: دائن | AK7: مدين | AL7: دائن | AM7: مدين | AN7: دائن | AO7: مدين | AP7: دائن | AQ7: مدين | AR7: دائن | AS7: مدين | AT7: دائن | AU7: مدين | AV7: دائن | AW7: مدين | AX7: دائن
D8: 500 | E8: =SUMIF($I$7:$AX$7,$J$7,I8:AX8) -> 0 | F8: =IF(D8=E8,"palance","unpalance") -> unpalance | G8: =IF(D8>E8,D8-E8,E8-D8) -> 500 | H8: =IF(D8>E8,"مدين اكبر",IF(E8>D8,"دائن اكبر","~")) -> مدين اكبر | AP8: 0
E9: =SUMIF($I$7:$AX$7,$J$7,I9:AX9) -> 0 | F9: =IF(D9=E9,"palance","unpalance") -> palance | G9: =IF(D9>E9,D9-E9,E9-D9) -> 0 | H9: =IF(D9>E9,"مدين اكبر",IF(E9>D9,"دائن اكبر","~")) -> ~ | AP9: 0
D10: =SUMIF($I$7:$AX$7,$I$7,I10:AX10) -> 0 | E10: =SUMIF($I$7:$AX$7,$J$7,I10:AX10) -> 0 | F10: =IF(D10=E10,"palance","unpalance") -> palance | G10: =IF(D10>E10,D10-E10,E10-D10) -> 0 | H10: =IF(D10>E10,"مدين اكبر",IF(E10>D10,"دائن اكبر","~")) -> ~
D11: =SUMIF($I$7:$AX$7,$I$7,I11:AX11) -> 0 | E11: =SUMIF($I$7:$AX$7,$J$7,I11:AX11) -> 0 | F11: =IF(D11=E11,"palance","unpalance") -> palance | G11: =IF(D11>E11,D11-E11,E11-D11) -> 0 | H11: =IF(D11>E11,"مدين اكبر",IF(E11>D11,"دائن اكبر","~")) -> ~
D12: =SUMIF($I$7:$AX$7,$I$7,I12:AX12) -> 0 | E12: =SUMIF($I$7:$AX$7,$J$7,I12:AX12) -> 0 | F12: =IF(D12=E12,"palance","unpalance") -> palance | G12: =IF(D12>E12,D12-E12,E12-D12) -> 0 | H12: =IF(D12>E12,"مدين اكبر",IF(E12>D12,"دائن اكبر","~")) -> ~
D13: =SUMIF($I$7:$AX$7,$I$7,I13:AX13) -> 0 | E13: =SUMIF($I$7:$AX$7,$J$7,I13:AX13) -> 0 | F13: =IF(D13=E13,"palance","unpalance") -> palance | G13: =IF(D13>E13,D13-E13,E13-D13) -> 0 | H13: =IF(D13>E13,"مدين اكبر",IF(E13>D13,"دائن اكبر","~")) -> ~
D14: =SUMIF($I$7:$AX$7,$I$7,I14:AX14) -> 0 | E14: =SUMIF($I$7:$AX$7,$J$7,I14:AX14) -> 0 | F14: =IF(D14=E14,"palance","unpalance") -> palance | G14: =IF(D14>E14,D14-E14,E14-D14) -> 0 | H14: =IF(D14>E14,"مدين اكبر",IF(E14>D14,"دائن اكبر","~")) -> ~
D15: =SUMIF($I$7:$AX$7,$I$7,I15:AX15) -> 0 | E15: =SUMIF($I$7:$AX$7,$J$7,I15:AX15) -> 0 | F15: =IF(D15=E15,"palance","unpalance") -> palance | G15: =IF(D15>E15,D15-E15,E15-D15) -> 0 | H15: =IF(D15>E15,"مدين اكبر",IF(E15>D15,"دائن اكبر","~")) -> ~
D16: =SUMIF($I$7:$AX$7,$I$7,I16:AX16) -> 0 | E16: =SUMIF($I$7:$AX$7,$J$7,I16:AX16) -> 0 | F16: =IF(D16=E16,"palance","unpalance") -> palance | G16: =IF(D16>E16,D16-E16,E16-D16) -> 0 | H16: =IF(D16>E16,"مدين اكبر",IF(E16>D16,"دائن اكبر","~")) -> ~
D17: =SUMIF($I$7:$AX$7,$I$7,I17:AX17) -> 0 | E17: =SUMIF($I$7:$AX$7,$J$7,I17:AX17) -> 0 | F17: =IF(D17=E17,"palance","unpalance") -> palance | G17: =IF(D17>E17,D17-E17,E17-D17) -> 0 | H17: =IF(D17>E17,"مدين اكبر",IF(E17>D17,"دائن اكبر","~")) -> ~
D18: =SUMIF($I$7:$AX$7,$I$7,I18:AX18) -> 0 | E18: =SUMIF($I$7:$AX$7,$J$7,I18:AX18) -> 0 | F18: =IF(D18=E18,"palance","unpalance") -> palance | G18: =IF(D18>E18,D18-E18,E18-D18) -> 0 | H18: =IF(D18>E18,"مدين اكبر",IF(E18>D18,"دائن اكبر","~")) -> ~
D19: =SUMIF($I$7:$AX$7,$I$7,I19:AX19) -> 0 | E19: =SUMIF($I$7:$AX$7,$J$7,I19:AX19) -> 0 | F19: =IF(D19=E19,"palance","unpalance") -> palance | G19: =IF(D19>E19,D19-E19,E19-D19) -> 0 | H19: =IF(D19>E19,"مدين اكبر",IF(E19>D19,"دائن اكبر","~")) -> ~
D20: =SUMIF($I$7:$AX$7,$I$7,I20:AX20) -> 0 | E20: =SUMIF($I$7:$AX$7,$J$7,I20:AX20) -> 0 | F20: =IF(D20=E20,"palance","unpalance") -> palance | G20: =IF(D20>E20,D20-E20,E20-D20) -> 0 | H20: =IF(D20>E20,"مدين اكبر",IF(E20>D20,"دائن اكبر","~")) -> ~
D21: =SUMIF($I$7:$AX$7,$I$7,I21:AX21) -> 0 | E21: =SUMIF($I$7:$AX$7,$J$7,I21:AX21) -> 0 | F21: =IF(D21=E21,"palance","unpalance") -> palance | G21: =IF(D21>E21,D21-E21,E21-D21) -> 0 | H21: =IF(D21>E21,"مدين اكبر",IF(E21>D21,"دائن اكبر","~")) -> ~
... D28: =SUMIF($I$7:$AX$7,$I$7,I28:AX28) -> 0 | E28: =SUMIF($I$7:$AX$7,$J$7,I28:AX28) -> 0 | F28: =IF(D28=E28,"palance","unpalance") -> palance | G28: =IF(D28>E28,D28-E28,E28-D28) -> 0 | H28: =IF(D28>E28,"مدين اكبر",IF(E28>D28,"دائن اكبر","~")) -> ~
A29: الاجمالي | F29: =IF(D29=E29,"palance","unpalance") -> palance | G29: =IF(D29>E29,D29-E29,E29-D29) -> 0 | H29: =IF(D29>E29,"مدين اكبر",IF(E29>D29,"دائن اكبر","~")) -> ~ | I29: =SUM(I8:I28) -> 0 | J29: =SUM(J8:J28) -> 0 | K29: =SUM(K8:K28) -> 0 | L29: =SUM(L8:L28) -> 0 | M29: =SUM(M8:M28) -> 0 | N29: =SUM(N8:N28) -> 0 | O29: =SUM(O8:O28) -> 0 | P29: =SUM(P8:P28) -> 0 | ... AX29: =SUM(AX8:AX28) -> 0

Sheet 5
A1: شركة المتحدة
A2: قسم الحسابات
A3: السنة المالية2021 | I3: =I29-J29+'4'!I3 -> 0 | K3: =K29-L29+'4'!K3 -> 0 | M3: =M29-N29+'4'!M3 -> 0 | O3: =O29-P29+'4'!O3 -> 0 | Q3: =Q29-R29+'4'!Q3 -> 0 | S3: =S29-T29+'4'!S3 -> 0 | U3: =U29-V29+'4'!U3 -> 0 | W3: =W29-X29+'4'!W3 -> 0 | Y3: =Y29-Z29+'4'!Y3 -> 0 | AA3: =AA29-AB29+'4'!AA3 -> 0 | AC3: =AC29-AD29+'4'!AC3 -> 0 | AE3: =AE29-AF29+'4'!AE3 -> 0 | AG3: =AG29-AH29+'4'!AG3 -> 0 | AI3: =AI29-AJ29+'4'!AI3 -> 0 | AK3: =AK29-AL29+'4'!AK3 -> 0 | AM3: =AM29-AN29+'4'!AM3 -> 0 | AO3: =AO29-AP29+'4'!AO3 -> 0 | AQ3: =AQ29-AR29+'4'!AQ3 -> 0 | AS3: =AS29-AT29+'4'!AS3 -> 0 | AU3: =AU29-AV29+'4'!AU3 -> 0 | AW3: =AW29-AX29+'4'!AW3 -> 0
A4: دليل الحسابات
A6: رقم القيد | B6: التاريخ | C6: البيان | D6: الاجمالي | F6: contorl | G6: الفرق | I6: النقدية | K6: بنك مصر | M6: مدينونTele | O6: Teachمدينون | Q6: ادوات كتابية | S6: السيارات | U6: مجمع اهلاك سيارات | W6: الاثاث | Y6: مجمع اهلاك الاثاث | AA6: مباني | AC6: معدات | AE6: الاراضي | AG6: دائنونGlobal | AI6: مصروف صيانة | AK6: رواتب واجور | AM6: مصروف اهلاك | AO6: ايرادات | AQ6: راس المال | AS6: مسحوبات | AU6: حساب1 | AW6: حساب2
D7: مدين | E7: دائن | I7: مدين | J7: دائن | K7: مدين | L7: دائن | M7: مدين | N7: دائن | O7: مدين | P7: دائن | Q7: مدين | R7: دائن | S7: مدين | T7: دائن | U7: مدين | V7: دائن | W7: مدين | X7: دائن | Y7: مدين | Z7: دائن | AA7: مدين | AB7: دائن | AC7: مدين | AD7: دائن | AE7: مدين | AF7: دائن | AG7: مدين | AH7: دائن | AI7: مدين | AJ7: دائن | AK7: مدين | AL7: دائن | AM7: مدين | AN7: دائن | AO7: مدين | AP7: دائن | AQ7: مدين | AR7: دائن | AS7: مدين | AT7: دائن | AU7: مدين | AV7: دائن | AW7: مدين | AX7: دائن
D8: 500 | E8: =SUMIF($I$7:$AX$7,$J$7,I8:AX8) -> 0 | F8: =IF(D8=E8,"palance","unpalance") -> unpalance | G8: =IF(D8>E8,D8-E8,E8-D8) -> 500 | H8: =IF(D8>E8,"مدين اكبر",IF(E8>D8,"دائن اكبر","~")) -> مدين اكبر | AP8: 0
D9: =SUMIF($I$7:$AX$7,$I$7,I9:AX9) -> 0 | E9: =SUMIF($I$7:$AX$7,$J$7,I9:AX9) -> 0 | F9: =IF(D9=E9,"palance","unpalance") -> palance | G9: =IF(D9>E9,D9-E9,E9-D9) -> 0 | H9: =IF(D9>E9,"مدين اكبر",IF(E9>D9,"دائن اكبر","~")) -> ~ | AP9: 0
D10: =SUMIF($I$7:$AX$7,$I$7,I10:AX10) -> 0 | E10: =SUMIF($I$7:$AX$7,$J$7,I10:AX10) -> 0 | F10: =IF(D10=E10,"palance","unpalance") -> palance | G10: =IF(D10>E10,D10-E10,E10-D10) -> 0 | H10: =IF(D10>E10,"مدين اكبر",IF(E10>D10,"دائن اكبر","~")) -> ~
D11: =SUMIF($I$7:$AX$7,$I$7,I11:AX11) -> 0 | E11: =SUMIF($I$7:$AX$7,$J$7,I11:AX11) -> 0 | F11: =IF(D11=E11,"palance","unpalance") -> palance | G11: =IF(D11>E11,D11-E11,E11-D11) -> 0 | H11: =IF(D11>E11,"مدين اكبر",IF(E11>D11,"دائن اكبر","~")) -> ~
D12: =SUMIF($I$7:$AX$7,$I$7,I12:AX12) -> 0 | E12: =SUMIF($I$7:$AX$7,$J$7,I12:AX12) -> 0 | F12: =IF(D12=E12,"palance","unpalance") -> palance | G12: =IF(D12>E12,D12-E12,E12-D12) -> 0 | H12: =IF(D12>E12,"مدين اكبر",IF(E12>D12,"دائن اكبر","~")) -> ~
D13: =SUMIF($I$7:$AX$7,$I$7,I13:AX13) -> 0 | E13: =SUMIF($I$7:$AX$7,$J$7,I13:AX13) -> 0 | F13: =IF(D13=E13,"palance","unpalance") -> palance | G13: =IF(D13>E13,D13-E13,E13-D13) -> 0 | H13: =IF(D13>E13,"مدين اكبر",IF(E13>D13,"دائن اكبر","~")) -> ~
D14: =SUMIF($I$7:$AX$7,$I$7,I14:AX14) -> 0 | E14: =SUMIF($I$7:$AX$7,$J$7,I14:AX14) -> 0 | F14: =IF(D14=E14,"palance","unpalance") -> palance | G14: =IF(D14>E14,D14-E14,E14-D14) -> 0 | H14: =IF(D14>E14,"مدين اكبر",IF(E14>D14,"دائن اكبر","~")) -> ~ | I14: 0
D15: =SUMIF($I$7:$AX$7,$I$7,I15:AX15) -> 0 | E15: =SUMIF($I$7:$AX$7,$J$7,I15:AX15) -> 0 | F15: =IF(D15=E15,"palance","unpalance") -> palance | G15: =IF(D15>E15,D15-E15,E15-D15) -> 0 | H15: =IF(D15>E15,"مدين اكبر",IF(E15>D15,"دائن اكبر","~")) -> ~
D16: =SUMIF($I$7:$AX$7,$I$7,I16:AX16) -> 0 | E16: =SUMIF($I$7:$AX$7,$J$7,I16:AX16) -> 0 | F16: =IF(D16=E16,"palance","unpalance") -> palance | G16: =IF(D16>E16,D16-E16,E16-D16) -> 0 | H16: =IF(D16>E16,"مدين اكبر",IF(E16>D16,"دائن اكبر","~")) -> ~
D17: =SUMIF($I$7:$AX$7,$I$7,I17:AX17) -> 0 | E17: =SUMIF($I$7:$AX$7,$J$7,I17:AX17) -> 0 | F17: =IF(D17=E17,"palance","unpalance") -> palance | G17: =IF(D17>E17,D17-E17,E17-D17) -> 0 | H17: =IF(D17>E17,"مدين اكبر",IF(E17>D17,"دائن اكبر","~")) -> ~
D18: =SUMIF($I$7:$AX$7,$I$7,I18:AX18) -> 0 | E18: =SUMIF($I$7:$AX$7,$J$7,I18:AX18) -> 0 | F18: =IF(D18=E18,"palance","unpalance") -> palance | G18: =IF(D18>E18,D18-E18,E18-D18) -> 0 | H18: =IF(D18>E18,"مدين اكبر",IF(E18>D18,"دائن اكبر","~")) -> ~
D19: =SUMIF($I$7:$AX$7,$I$7,I19:AX19) -> 0 | E19: =SUMIF($I$7:$AX$7,$J$7,I19:AX19) -> 0 | F19: =IF(D19=E19,"palance","unpalance") -> palance | G19: =IF(D19>E19,D19-E19,E19-D19) -> 0 | H19: =IF(D19>E19,"مدين اكبر",IF(E19>D19,"دائن اكبر","~")) -> ~
D20: =SUMIF($I$7:$AX$7,$I$7,I20:AX20) -> 0 | E20: =SUMIF($I$7:$AX$7,$J$7,I20:AX20) -> 0 | F20: =IF(D20=E20,"palance","unpalance") -> palance | G20: =IF(D20>E20,D20-E20,E20-D20) -> 0 | H20: =IF(D20>E20,"مدين اكبر",IF(E20>D20,"دائن اكبر","~")) -> ~
D21: =SUMIF($I$7:$AX$7,$I$7,I21:AX21) -> 0 | E21: =SUMIF($I$7:$AX$7,$J$7,I21:AX21) -> 0 | F21: =IF(D21=E21,"palance","unpalance") -> palance | G21: =IF(D21>E21,D21-E21,E21-D21) -> 0 | H21: =IF(D21>E21,"مدين اكبر",IF(E21>D21,"دائن اكبر","~")) -> ~
D22: =SUMIF($I$7:$AX$7,$I$7,I22:AX22) -> 0 | E22: =SUMIF($I$7:$AX$7,$J$7,I22:AX22) -> 0 | F22: =IF(D22=E22,"palance","unpalance") -> palance | G22: =IF(D22>E22,D22-E22,E22-D22) -> 0 | H22: =IF(D22>E22,"مدين اكبر",IF(E22>D22,"دائن اكبر","~")) -> ~
D23: =SUMIF($I$7:$AX$7,$I$7,I23:AX23) -> 0 | E23: =SUMIF($I$7:$AX$7,$J$7,I23:AX23) -> 0 | F23: =IF(D23=E23,"palance","unpalance") -> palance | G23: =IF(D23>E23,D23-E23,E23-D23) -> 0 | H23: =IF(D23>E23,"مدين اكبر",IF(E23>D23,"دائن اكبر","~")) -> ~
D24: =SUMIF($I$7:$AX$7,$I$7,I24:AX24) -> 0 | E24: =SUMIF($I$7:$AX$7,$J$7,I24:AX24) -> 0 | F24: =IF(D24=E24,"palance","unpalance") -> palance | G24: =IF(D24>E24,D24-E24,E24-D24) -> 0 | H24: =IF(D24>E24,"مدين اكبر",IF(E24>D24,"دائن اكبر","~")) -> ~
D25: =SUMIF($I$7:$AX$7,$I$7,I25:AX25) -> 0 | E25: =SUMIF($I$7:$AX$7,$J$7,I25:AX25) -> 0 | F25: =IF(D25=E25,"palance","unpalance") -> palance | G25: =IF(D25>E25,D25-E25,E25-D25) -> 0 | H25: =IF(D25>E25,"مدين اكبر",IF(E25>D25,"دائن اكبر","~")) -> ~
D26: =SUMIF($I$7:$AX$7,$I$7,I26:AX26) -> 0 | E26: =SUMIF($I$7:$AX$7,$J$7,I26:AX26) -> 0 | F26: =IF(D26=E26,"palance","unpalance") -> palance | G26: =IF(D26>E26,D26-E26,E26-D26) -> 0 | H26: =IF(D26>E26,"مدين اكبر",IF(E26>D26,"دائن اكبر","~")) -> ~
... D28: =SUMIF($I$7:$AX$7,$I$7,I28:AX28) -> 0 | E28: =SUMIF($I$7:$AX$7,$J$7,I28:AX28) -> 0 | F28: =IF(D28=E28,"palance","unpalance") -> palance | G28: =IF(D28>E28,D28-E28,E28-D28) -> 0 | H28: =IF(D28>E28,"مدين اكبر",IF(E28>D28,"دائن اكبر","~")) -> ~
A29: الاجمالي | F29: =IF(D29=E29,"palance","unpalance") -> palance | G29: =IF(D29>E29,D29-E29,E29-D29) -> 0 | H29: =IF(D29>E29,"مدين اكبر",IF(E29>D29,"دائن اكبر","~")) -> ~ | I29: =SUM(I8:I28) -> 0 | J29: =SUM(J8:J28) -> 0 | K29: =SUM(K8:K28) -> 0 | L29: =SUM(L8:L28) -> 0 | M29: =SUM(M8:M28) -> 0 | N29: =SUM(N8:N28) -> 0 | O29: =SUM(O8:O28) -> 0 | P29: =SUM(P8:P28) -> 0 | ... AX29: =SUM(AX8:AX28) -> 0

Sheet 6
A1: شركة المتحدة
A2: قسم الحسابات
A3: السنة المالية2021 | I3: =I29-J29+'5'!I3 -> 0 | K3: =K29-L29+'5'!K3 -> 0 | M3: =M29-N29+'5'!M3 -> 0 | O3: =O29-P29+'5'!O3 -> 0 | Q3: =Q29-R29+'5'!Q3 -> 0 | S3: =S29-T29+'5'!S3 -> 0 | U3: =U29-V29+'5'!U3 -> 0 | W3: =W29-X29+'5'!W3 -> 0 | Y3: =Y29-Z29+'5'!Y3 -> 0 | AA3: =AA29-AB29+'5'!AA3 -> 0 | AC3: =AC29-AD29+'5'!AC3 -> 0 | AE3: =AE29-AF29+'5'!AE3 -> 0 | AG3: =AG29-AH29+'5'!AG3 -> 0 | AI3: =AI29-AJ29+'5'!AI3 -> 0 | AK3: =AK29-AL29+'5'!AK3 -> 0 | AM3: =AM29-AN29+'5'!AM3 -> 0 | AO3: =AO29-AP29+'5'!AO3 -> 0 | AQ3: =AQ29-AR29+'5'!AQ3 -> 0 | AS3: =AS29-AT29+'5'!AS3 -> 0 | AU3: =AU29-AV29+'5'!AU3 -> 0 | AW3: =AW29-AX29+'5'!AW3 -> 0
A4: دليل الحسابات
A6: رقم القيد | B6: التاريخ | C6: البيان | D6: الاجمالي | F6: contorl | G6: الفرق | I6: النقدية | K6: بنك مصر | M6: مدينونTele | O6: Teachمدينون | Q6: ادوات كتابية | S6: السيارات | U6: مجمع اهلاك سيارات | W6: الاثاث | Y6: مجمع اهلاك الاثاث | AA6: مباني | AC6: معدات | AE6: الاراضي | AG6: دائنونGlobal | AI6: مصروف صيانة | AK6: رواتب واجور | AM6: مصروف اهلاك | AO6: ايرادات | AQ6: راس المال | AS6: مسحوبات | AU6: حساب1 | AW6: حساب2
D7: مدين | E7: دائن | I7: مدين | J7: دائن | K7: مدين | L7: دائن | M7: مدين | N7: دائن | O7: مدين | P7: دائن | Q7: مدين | R7: دائن | S7: مدين | T7: دائن | U7: مدين | V7: دائن | W7: مدين | X7: دائن | Y7: مدين | Z7: دائن | AA7: مدين | AB7: دائن | AC7: مدين | AD7: دائن | AE7: مدين | AF7: دائن | AG7: مدين | AH7: دائن | AI7: مدين | AJ7: دائن | AK7: مدين | AL7: دائن | AM7: مدين | AN7: دائن | AO7: مدين | AP7: دائن | AQ7: مدين | AR7: دائن | AS7: مدين | AT7: دائن | AU7: مدين | AV7: دائن | AW7: مدين | AX7: دائن
D8: 500 | E8: =SUMIF($I$7:$AX$7,$J$7,I8:AX8) -> 0 | F8: =IF(D8=E8,"palance","unpalance") -> unpalance | G8: =IF(D8>E8,D8-E8,E8-D8) -> 500 | H8: =IF(D8>E8,"مدين اكبر",IF(E8>D8,"دائن اكبر","~")) -> مدين اكبر | AP8: 0
D9: =SUMIF($I$7:$AX$7,$I$7,I9:AX9) -> 0 | E9: =SUMIF($I$7:$AX$7,$J$7,I9:AX9) -> 0 | F9: =IF(D9=E9,"palance","unpalance") -> palance | G9: =IF(D9>E9,D9-E9,E9-D9) -> 0 | H9: =IF(D9>E9,"مدين اكبر",IF(E9>D9,"دائن اكبر","~")) -> ~ | AP9: 0
D10: =SUMIF($I$7:$AX$7,$I$7,I10:AX10) -> 0 | E10: =SUMIF($I$7:$AX$7,$J$7,I10:AX10) -> 0 | F10: =IF(D10=E10,"palance","unpalance") -> palance | G10: =IF(D10>E10,D10-E10,E10-D10) -> 0 | H10: =IF(D10>E10,"مدين اكبر",IF(E10>D10,"دائن اكبر","~")) -> ~
D11: =SUMIF($I$7:$AX$7,$I$7,I11:AX11) -> 0 | E11: =SUMIF($I$7:$AX$7,$J$7,I11:AX11) -> 0 | F11: =IF(D11=E11,"palance","unpalance") -> palance | G11: =IF(D11>E11,D11-E11,E11-D11) -> 0 | H11: =IF(D11>E11,"مدين اكبر",IF(E11>D11,"دائن اكبر","~")) -> ~
D12: =SUMIF($I$7:$AX$7,$I$7,I12:AX12) -> 0 | E12: =SUMIF($I$7:$AX$7,$J$7,I12:AX12) -> 0 | F12: =IF(D12=E12,"palance","unpalance") -> palance | G12: =IF(D12>E12,D12-E12,E12-D12) -> 0 | H12: =IF(D12>E12,"مدين اكبر",IF(E12>D12,"دائن اكبر","~")) -> ~
D13: =SUMIF($I$7:$AX$7,$I$7,I13:AX13) -> 0 | E13: =SUMIF($I$7:$AX$7,$J$7,I13:AX13) -> 0 | F13: =IF(D13=E13,"palance","unpalance") -> palance | G13: =IF(D13>E13,D13-E13,E13-D13) -> 0 | H13: =IF(D13>E13,"مدين اكبر",IF(E13>D13,"دائن اكبر","~")) -> ~
D14: =SUMIF($I$7:$AX$7,$I$7,I14:AX14) -> 0 | E14: =SUMIF($I$7:$AX$7,$J$7,I14:AX14) -> 0 | F14: =IF(D14=E14,"palance","unpalance") -> palance | G14: =IF(D14>E14,D14-E14,E14-D14) -> 0 | H14: =IF(D14>E14,"مدين اكبر",IF(E14>D14,"دائن اكبر","~")) -> ~
D15: =SUMIF($I$7:$AX$7,$I$7,I15:AX15) -> 0 | E15: =SUMIF($I$7:$AX$7,$J$7,I15:AX15) -> 0 | F15: =IF(D15=E15,"palance","unpalance") -> palance | G15: =IF(D15>E15,D15-E15,E15-D15) -> 0 | H15: =IF(D15>E15,"مدين اكبر",IF(E15>D15,"دائن اكبر","~")) -> ~
D16: =SUMIF($I$7:$AX$7,$I$7,I16:AX16) -> 0 | E16: =SUMIF($I$7:$AX$7,$J$7,I16:AX16) -> 0 | F16: =IF(D16=E16,"palance","unpalance") -> palance | G16: =IF(D16>E16,D16-E16,E16-D16) -> 0 | H16: =IF(D16>E16,"مدين اكبر",IF(E16>D16,"دائن اكبر","~")) -> ~
D17: =SUMIF($I$7:$AX$7,$I$7,I17:AX17) -> 0 | E17: =SUMIF($I$7:$AX$7,$J$7,I17:AX17) -> 0 | F17: =IF(D17=E17,"palance","unpalance") -> palance | G17: =IF(D17>E17,D17-E17,E17-D17) -> 0 | H17: =IF(D17>E17,"مدين اكبر",IF(E17>D17,"دائن اكبر","~")) -> ~
D18: =SUMIF($I$7:$AX$7,$I$7,I18:AX18) -> 0 | E18: =SUMIF($I$7:$AX$7,$J$7,I18:AX18) -> 0 | F18: =IF(D18=E18,"palance","unpalance") -> palance | G18: =IF(D18>E18,D18-E18,E18-D18) -> 0 | H18: =IF(D18>E18,"مدين اكبر",IF(E18>D18,"دائن اكبر","~")) -> ~
D19: =SUMIF($I$7:$AX$7,$I$7,I19:AX19) -> 0 | E19: =SUMIF($I$7:$AX$7,$J$7,I19:AX19) -> 0 | F19: =IF(D19=E19,"palance","unpalance") -> palance | G19: =IF(D19>E19,D19-E19,E19-D19) -> 0 | H19: =IF(D19>E19,"مدين اكبر",IF(E19>D19,"دائن اكبر","~")) -> ~
D20: =SUMIF($I$7:$AX$7,$I$7,I20:AX20) -> 0 | E20: =SUMIF($I$7:$AX$7,$J$7,I20:AX20) -> 0 | F20: =IF(D20=E20,"palance","unpalance") -> palance | G20: =IF(D20>E20,D20-E20,E20-D20) -> 0 | H20: =IF(D20>E20,"مدين اكبر",IF(E20>D20,"دائن اكبر","~")) -> ~
D21: =SUMIF($I$7:$AX$7,$I$7,I21:AX21) -> 0 | E21: =SUMIF($I$7:$AX$7,$J$7,I21:AX21) -> 0 | F21: =IF(D21=E21,"palance","unpalance") -> palance | G21: =IF(D21>E21,D21-E21,E21-D21) -> 0 | H21: =IF(D21>E21,"مدين اكبر",IF(E21>D21,"دائن اكبر","~")) -> ~
... D28: =SUMIF($I$7:$AX$7,$I$7,I28:AX28) -> 0 | E28: =SUMIF($I$7:$AX$7,$J$7,I28:AX28) -> 0 | F28: =IF(D28=E28,"palance","unpalance") -> palance | G28: =IF(D28>E28,D28-E28,E28-D28) -> 0 | H28: =IF(D28>E28,"مدين اكبر",IF(E28>D28,"دائن اكبر","~")) -> ~
A29: الاجمالي | F29: =IF(D29=E29,"palance","unpalance") -> palance | G29: =IF(D29>E29,D29-E29,E29-D29) -> 0 | H29: =IF(D29>E29,"مدين اكبر",IF(E29>D29,"دائن اكبر","~")) -> ~ | I29: =SUM(I8:I28) -> 0 | J29: =SUM(J8:J28) -> 0 | K29: =SUM(K8:K28) -> 0 | L29: =SUM(L8:L28) -> 0 | M29: =SUM(M8:M28) -> 0 | N29: =SUM(N8:N28) -> 0 | O29: =SUM(O8:O28) -> 0 | P29: =SUM(P8:P28) -> 0 | ... AX29: =SUM(AX8:AX28) -> 0

Sheet 7
A1: شركة المتحدة
A2: قسم الحسابات
A3: السنة المالية2021 | I3: =I29-J29+'6'!I3 -> 0 | K3: =K29-L29+'6'!K3 -> 0 | M3: =M29-N29+'6'!M3 -> 0 | O3: =O29-P29+'6'!O3 -> 0 | Q3: =Q29-R29+'6'!Q3 -> 0 | S3: =S29-T29+'6'!S3 -> 0 | U3: =U29-V29+'6'!U3 -> 0 | W3: =W29-X29+'6'!W3 -> 0 | Y3: =Y29-Z29+'6'!Y3 -> 0 | AA3: =AA29-AB29+'6'!AA3 -> 0 | AC3: =AC29-AD29+'6'!AC3 -> 0 | AE3: =AE29-AF29+'6'!AE3 -> 0 | AG3: =AG29-AH29+'6'!AG3 -> 0 | AI3: =AI29-AJ29+'6'!AI3 -> 0 | AK3: =AK29-AL29+'6'!AK3 -> 0 | AM3: =AM29-AN29+'6'!AM3 -> 0 | AO3: =AO29-AP29+'6'!AO3 -> 0 | AQ3: =AQ29-AR29+'6'!AQ3 -> 0 | AS3: =AS29-AT29+'6'!AS3 -> 0 | AU3: =AU29-AV29+'6'!AU3 -> 0 | AW3: =AW29-AX29+'6'!AW3 -> 0
A4: دليل الحسابات
A6: رقم القيد | B6: التاريخ | C6: البيان | D6: الاجمالي | F6: contorl | G6: الفرق | I6: النقدية | K6: بنك مصر | M6: مدينونTele | O6: Teachمدينون | Q6: ادوات كتابية | S6: السيارات | U6: مجمع اهلاك سيارات | W6: الاثاث | Y6: مجمع اهلاك الاثاث | AA6: مباني | AC6: معدات | AE6: الاراضي | AG6: دائنونGlobal | AI6: مصروف صيانة | AK6: رواتب واجور | AM6: مصروف اهلاك | AO6: ايرادات | AQ6: راس المال | AS6: مسحوبات | AU6: حساب1 | AW6: حساب2
D7: مدين | E7: دائن | I7: مدين | J7: دائن | K7: مدين | L7: دائن | M7: مدين | N7: دائن | O7: مدين | P7: دائن | Q7: مدين | R7: دائن | S7: مدين | T7: دائن | U7: مدين | V7: دائن | W7: مدين | X7: دائن | Y7: مدين | Z7: دائن | AA7: مدين | AB7: دائن | AC7: مدين | AD7: دائن | AE7: مدين | AF7: دائن | AG7: مدين | AH7: دائن | AI7: مدين | AJ7: دائن | AK7: مدين | AL7: دائن | AM7: مدين | AN7: دائن | AO7: مدين | AP7: دائن | AQ7: مدين | AR7: دائن | AS7: مدين | AT7: دائن | AU7: مدين | AV7: دائن | AW7: مدين | AX7: دائن
D8: 500 | E8: =SUMIF($I$7:$AX$7,$J$7,I8:AX8) -> 0 | F8: =IF(D8=E8,"palance","unpalance") -> unpalance | G8: =IF(D8>E8,D8-E8,E8-D8) -> 500 | H8: =IF(D8>E8,"مدين اكبر",IF(E8>D8,"دائن اكبر","~")) -> مدين اكبر | AP8: 0
D9: =SUMIF($I$7:$AX$7,$I$7,I9:AX9) -> 0 | E9: =SUMIF($I$7:$AX$7,$J$7,I9:AX9) -> 0 | F9: =IF(D9=E9,"palance","unpalance") -> palance | G9: =IF(D9>E9,D9-E9,E9-D9) -> 0 | H9: =IF(D9>E9,"مدين اكبر",IF(E9>D9,"دائن اكبر","~")) -> ~ | AP9: 0
D10: =SUMIF($I$7:$AX$7,$I$7,I10:AX10) -> 0 | E10: =SUMIF($I$7:$AX$7,$J$7,I10:AX10) -> 0 | F10: =IF(D10=E10,"palance","unpalance") -> palance | G10: =IF(D10>E10,D10-E10,E10-D10) -> 0 | H10: =IF(D10>E10,"مدين اكبر",IF(E10>D10,"دائن اكبر","~")) -> ~
D11: =SUMIF($I$7:$AX$7,$I$7,I11:AX11) -> 0 | E11: =SUMIF($I$7:$AX$7,$J$7,I11:AX11) -> 0 | F11: =IF(D11=E11,"palance","unpalance") -> palance | G11: =IF(D11>E11,D11-E11,E11-D11) -> 0 | H11: =IF(D11>E11,"مدين اكبر",IF(E11>D11,"دائن اكبر","~")) -> ~
D12: =SUMIF($I$7:$AX$7,$I$7,I12:AX12) -> 0 | E12: =SUMIF($I$7:$AX$7,$J$7,I12:AX12) -> 0 | F12: =IF(D12=E12,"palance","unpalance") -> palance | G12: =IF(D12>E12,D12-E12,E12-D12) -> 0 | H12: =IF(D12>E12,"مدين اكبر",IF(E12>D12,"دائن اكبر","~")) -> ~
D13: =SUMIF($I$7:$AX$7,$I$7,I13:AX13) -> 0 | E13: =SUMIF($I$7:$AX$7,$J$7,I13:AX13) -> 0 | F13: =IF(D13=E13,"palance","unpalance") -> palance | G13: =IF(D13>E13,D13-E13,E13-D13) -> 0 | H13: =IF(D13>E13,"مدين اكبر",IF(E13>D13,"دائن اكبر","~")) -> ~
D14: =SUMIF($I$7:$AX$7,$I$7,I14:AX14) -> 0 | E14: =SUMIF($I$7:$AX$7,$J$7,I14:AX14) -> 0 | F14: =IF(D14=E14,"palance","unpalance") -> palance | G14: =IF(D14>E14,D14-E14,E14-D14) -> 0 | H14: =IF(D14>E14,"مدين اكبر",IF(E14>D14,"دائن اكبر","~")) -> ~
D15: =SUMIF($I$7:$AX$7,$I$7,I15:AX15) -> 0 | E15: =SUMIF($I$7:$AX$7,$J$7,I15:AX15) -> 0 | F15: =IF(D15=E15,"palance","unpalance") -> palance | G15: =IF(D15>E15,D15-E15,E15-D15) -> 0 | H15: =IF(D15>E15,"مدين اكبر",IF(E15>D15,"دائن اكبر","~")) -> ~
D16: =SUMIF($I$7:$AX$7,$I$7,I16:AX16) -> 0 | E16: =SUMIF($I$7:$AX$7,$J$7,I16:AX16) -> 0 | F16: =IF(D16=E16,"palance","unpalance") -> palance | G16: =IF(D16>E16,D16-E16,E16-D16) -> 0 | H16: =IF(D16>E16,"مدين اكبر",IF(E16>D16,"دائن اكبر","~")) -> ~
D17: =SUMIF($I$7:$AX$7,$I$7,I17:AX17) -> 0 | E17: =SUMIF($I$7:$AX$7,$J$7,I17:AX17) -> 0 | F17: =IF(D17=E17,"palance","unpalance") -> palance | G17: =IF(D17>E17,D17-E17,E17-D17) -> 0 | H17: =IF(D17>E17,"مدين اكبر",IF(E17>D17,"دائن اكبر","~")) -> ~
D18: =SUMIF($I$7:$AX$7,$I$7,I18:AX18) -> 0 | E18: =SUMIF($I$7:$AX$7,$J$7,I18:AX18) -> 0 | F18: =IF(D18=E18,"palance","unpalance") -> palance | G18: =IF(D18>E18,D18-E18,E18-D18) -> 0 | H18: =IF(D18>E18,"مدين اكبر",IF(E18>D18,"دائن اكبر","~")) -> ~
D19: =SUMIF($I$7:$AX$7,$I$7,I19:AX19) -> 0 | E19: =SUMIF($I$7:$AX$7,$J$7,I19:AX19) -> 0 | F19: =IF(D19=E19,"palance","unpalance") -> palance | G19: =IF(D19>E19,D19-E19,E19-D19) -> 0 | H19: =IF(D19>E19,"مدين اكبر",IF(E19>D19,"دائن اكبر","~")) -> ~
D20: =SUMIF($I$7:$AX$7,$I$7,I20:AX20) -> 0 | E20: =SUMIF($I$7:$AX$7,$J$7,I20:AX20) -> 0 | F20: =IF(D20=E20,"palance","unpalance") -> palance | G20: =IF(D20>E20,D20-E20,E20-D20) -> 0 | H20: =IF(D20>E20,"مدين اكبر",IF(E20>D20,"دائن اكبر","~")) -> ~
D21: =SUMIF($I$7:$AX$7,$I$7,I21:AX21) -> 0 | E21: =SUMIF($I$7:$AX$7,$J$7,I21:AX21) -> 0 | F21: =IF(D21=E21,"palance","unpalance") -> palance | G21: =IF(D21>E21,D21-E21,E21-D21) -> 0 | H21: =IF(D21>E21,"مدين اكبر",IF(E21>D21,"دائن اكبر","~")) -> ~
... D28: =SUMIF($I$7:$AX$7,$I$7,I28:AX28) -> 0 | E28: =SUMIF($I$7:$AX$7,$J$7,I28:AX28) -> 0 | F28: =IF(D28=E28,"palance","unpalance") -> palance | G28: =IF(D28>E28,D28-E28,E28-D28) -> 0 | H28: =IF(D28>E28,"مدين اكبر",IF(E28>D28,"دائن اكبر","~")) -> ~
A29: الاجمالي | F29: =IF(D29=E29,"palance","unpalance") -> palance | G29: =IF(D29>E29,D29-E29,E29-D29) -> 0 | H29: =IF(D29>E29,"مدين اكبر",IF(E29>D29,"دائن اكبر","~")) -> ~ | I29: =SUM(I8:I28) -> 0 | J29: =SUM(J8:J28) -> 0 | K29: =SUM(K8:K28) -> 0 | L29: =SUM(L8:L28) -> 0 | M29: =SUM(M8:M28) -> 0 | N29: =SUM(N8:N28) -> 0 | O29: =SUM(O8:O28) -> 0 | P29: =SUM(P8:P28) -> 0 | ... AX29: =SUM(AX8:AX28) -> 0

Sheet 8
A1: شركة المتحدة
A2: قسم الحسابات
A3: السنة المالية2021 | I3: =I29-J29+'7'!I3 -> 0 | K3: =K29-L29+'7'!K3 -> 0 | M3: =M29-N29+'7'!M3 -> 0 | O3: =O29-P29+'7'!O3 -> 0 | Q3: =Q29-R29+'7'!Q3 -> 0 | S3: =S29-T29+'7'!S3 -> 0 | U3: =U29-V29+'7'!U3 -> 0 | W3: =W29-X29+'7'!W3 -> 0 | Y3: =Y29-Z29+'7'!Y3 -> 0 | AA3: =AA29-AB29+'7'!AA3 -> 0 | AC3: =AC29-AD29+'7'!AC3 -> 0 | AE3: =AE29-AF29+'7'!AE3 -> 0 | AG3: =AG29-AH29+'7'!AG3 -> 0 | AI3: =AI29-AJ29+'7'!AI3 -> 0 | AK3: =AK29-AL29+'7'!AK3 -> 0 | AM3: =AM29-AN29+'7'!AM3 -> 0 | AO3: =AO29-AP29+'7'!AO3 -> 0 | AQ3: =AQ29-AR29+'7'!AQ3 -> 0 | AS3: =AS29-AT29+'7'!AS3 -> 0 | AU3: =AU29-AV29+'7'!AU3 -> 0 | AW3: =AW29-AX29+'7'!AW3 -> 0
A4: دليل الحسابات
A6: رقم القيد | B6: التاريخ | C6: البيان | D6: الاجمالي | F6: contorl | G6: الفرق | I6: النقدية | K6: بنك مصر | M6: مدينونTele | O6: Teachمدينون | Q6: ادوات كتابية | S6: السيارات | U6: مجمع اهلاك سيارات | W6: الاثاث | Y6: مجمع اهلاك الاثاث | AA6: مباني | AC6: معدات | AE6: الاراضي | AG6: دائنونGlobal | AI6: مصروف صيانة | AK6: رواتب واجور | AM6: مصروف اهلاك | AO6: ايرادات | AQ6: راس المال | AS6: مسحوبات | AU6: حساب1 | AW6: حساب2
D7: مدين | E7: دائن | I7: مدين | J7: دائن | K7: مدين | L7: دائن | M7: مدين | N7: دائن | O7: مدين | P7: دائن | Q7: مدين | R7: دائن | S7: مدين | T7: دائن | U7: مدين | V7: دائن | W7: مدين | X7: دائن | Y7: مدين | Z7: دائن | AA7: مدين | AB7: دائن | AC7: مدين | AD7: دائن | AE7: مدين | AF7: دائن | AG7: مدين | AH7: دائن | AI7: مدين | AJ7: دائن | AK7: مدين | AL7: دائن | AM7: مدين | AN7: دائن | AO7: مدين | AP7: دائن | AQ7: مدين | AR7: دائن | AS7: مدين | AT7: دائن | AU7: مدين | AV7: دائن | AW7: مدين | AX7: دائن
D8: 500 | E8: =SUMIF($I$7:$AX$7,$J$7,I8:AX8) -> 0 | F8: =IF(D8=E8,"palance","unpalance") -> unpalance | G8: =IF(D8>E8,D8-E8,E8-D8) -> 500 | H8: =IF(D8>E8,"مدين اكبر",IF(E8>D8,"دائن اكبر","~")) -> مدين اكبر | AP8: 0
D9: =SUMIF($I$7:$AX$7,$I$7,I9:AX9) -> 0 | E9: =SUMIF($I$7:$AX$7,$J$7,I9:AX9) -> 0 | F9: =IF(D9=E9,"palance","unpalance") -> palance | G9: =IF(D9>E9,D9-E9,E9-D9) -> 0 | H9: =IF(D9>E9,"مدين اكبر",IF(E9>D9,"دائن اكبر","~")) -> ~ | AP9: 0
D10: =SUMIF($I$7:$AX$7,$I$7,I10:AX10) -> 0 | E10: =SUMIF($I$7:$AX$7,$J$7,I10:AX10) -> 0 | F10: =IF(D10=E10,"palance","unpalance") -> palance | G10: =IF(D10>E10,D10-E10,E10-D10) -> 0 | H10: =IF(D10>E10,"مدين اكبر",IF(E10>D10,"دائن اكبر","~")) -> ~
D11: =SUMIF($I$7:$AX$7,$I$7,I11:AX11) -> 0 | E11: =SUMIF($I$7:$AX$7,$J$7,I11:AX11) -> 0 | F11: =IF(D11=E11,"palance","unpalance") -> palance | G11: =IF(D11>E11,D11-E11,E11-D11) -> 0 | H11: =IF(D11>E11,"مدين اكبر",IF(E11>D11,"دائن اكبر","~")) -> ~
D12: =SUMIF($I$7:$AX$7,$I$7,I12:AX12) -> 0 | E12: =SUMIF($I$7:$AX$7,$J$7,I12:AX12) -> 0 | F12: =IF(D12=E12,"palance","unpalance") -> palance | G12: =IF(D12>E12,D12-E12,E12-D12) -> 0 | H12: =IF(D12>E12,"مدين اكبر",IF(E12>D12,"دائن اكبر","~")) -> ~
D13: =SUMIF($I$7:$AX$7,$I$7,I13:AX13) -> 0 | E13: =SUMIF($I$7:$AX$7,$J$7,I13:AX13) -> 0 | F13: =IF(D13=E13,"palance","unpalance") -> palance | G13: =IF(D13>E13,D13-E13,E13-D13) -> 0 | H13: =IF(D13>E13,"مدين اكبر",IF(E13>D13,"دائن اكبر","~")) -> ~
D14: =SUMIF($I$7:$AX$7,$I$7,I14:AX14) -> 0 | E14: =SUMIF($I$7:$AX$7,$J$7,I14:AX14) -> 0 | F14: =IF(D14=E14,"palance","unpalance") -> palance | G14: =IF(D14>E14,D14-E14,E14-D14) -> 0 | H14: =IF(D14>E14,"مدين اكبر",IF(E14>D14,"دائن اكبر","~")) -> ~
D15: =SUMIF($I$7:$AX$7,$I$7,I15:AX15) -> 0 | E15: =SUMIF($I$7:$AX$7,$J$7,I15:AX15) -> 0 | F15: =IF(D15=E15,"palance","unpalance") -> palance | G15: =IF(D15>E15,D15-E15,E15-D15) -> 0 | H15: =IF(D15>E15,"مدين اكبر",IF(E15>D15,"دائن اكبر","~")) -> ~
D16: =SUMIF($I$7:$AX$7,$I$7,I16:AX16) -> 0 | E16: =SUMIF($I$7:$AX$7,$J$7,I16:AX16) -> 0 | F16: =IF(D16=E16,"palance","unpalance") -> palance | G16: =IF(D16>E16,D16-E16,E16-D16) -> 0 | H16: =IF(D16>E16,"مدين اكبر",IF(E16>D16,"دائن اكبر","~")) -> ~
D17: =SUMIF($I$7:$AX$7,$I$7,I17:AX17) -> 0 | E17: =SUMIF($I$7:$AX$7,$J$7,I17:AX17) -> 0 | F17: =IF(D17=E17,"palance","unpalance") -> palance | G17: =IF(D17>E17,D17-E17,E17-D17) -> 0 | H17: =IF(D17>E17,"مدين اكبر",IF(E17>D17,"دائن اكبر","~")) -> ~
D18: =SUMIF($I$7:$AX$7,$I$7,I18:AX18) -> 0 | E18: =SUMIF($I$7:$AX$7,$J$7,I18:AX18) -> 0 | F18: =IF(D18=E18,"palance","unpalance") -> palance | G18: =IF(D18>E18,D18-E18,E18-D18) -> 0 | H18: =IF(D18>E18,"مدين اكبر",IF(E18>D18,"دائن اكبر","~")) -> ~
D19: =SUMIF($I$7:$AX$7,$I$7,I19:AX19) -> 0 | E19: =SUMIF($I$7:$AX$7,$J$7,I19:AX19) -> 0 | F19: =IF(D19=E19,"palance","unpalance") -> palance | G19: =IF(D19>E19,D19-E19,E19-D19) -> 0 | H19: =IF(D19>E19,"مدين اكبر",IF(E19>D19,"دائن اكبر","~")) -> ~
D20: =SUMIF($I$7:$AX$7,$I$7,I20:AX20) -> 0 | E20: =SUMIF($I$7:$AX$7,$J$7,I20:AX20) -> 0 | F20: =IF(D20=E20,"palance","unpalance") -> palance | G20: =IF(D20>E20,D20-E20,E20-D20) -> 0 | H20: =IF(D20>E20,"مدين اكبر",IF(E20>D20,"دائن اكبر","~")) -> ~
D21: =SUMIF($I$7:$AX$7,$I$7,I21:AX21) -> 0 | E21: =SUMIF($I$7:$AX$7,$J$7,I21:AX21) -> 0 | F21: =IF(D21=E21,"palance","unpalance") -> palance | G21: =IF(D21>E21,D21-E21,E21-D21) -> 0 | H21: =IF(D21>E21,"مدين اكبر",IF(E21>D21,"دائن اكبر","~")) -> ~
... D28: =SUMIF($I$7:$AX$7,$I$7,I28:AX28) -> 0 | E28: =SUMIF($I$7:$AX$7,$J$7,I28:AX28) -> 0 | F28: =IF(D28=E28,"palance","unpalance") -> palance | G28: =IF(D28>E28,D28-E28,E28-D28) -> 0 | H28: =IF(D28>E28,"مدين اكبر",IF(E28>D28,"دائن اكبر","~")) -> ~
A29: الاجمالي | F29: =IF(D29=E29,"palance","unpalance") -> palance | G29: =IF(D29>E29,D29-E29,E29-D29) -> 0 | H29: =IF(D29>E29,"مدين اكبر",IF(E29>D29,"دائن اكبر","~")) -> ~ | I29: =SUM(I8:I28) -> 0 | J29: =SUM(J8:J28) -> 0 | K29: =SUM(K8:K28) -> 0 | L29: =SUM(L8:L28) -> 0 | M29: =SUM(M8:M28) -> 0 | N29: =SUM(N8:N28) -> 0 | O29: =SUM(O8:O28) -> 0 | P29: =SUM(P8:P28) -> 0 | ... AX29: =SUM(AX8:AX28) -> 0

Sheet 9
A1: شركة المتحدة
A2: قسم الحسابات
A3: السنة المالية2021 | I3: =I29-J29+'8'!I3 -> 0 | K3: =K29-L29+'8'!K3 -> 0 | M3: =M29-N29+'8'!M3 -> 0 | O3: =O29-P29+'8'!O3 -> 0 | Q3: =Q29-R29+'8'!Q3 -> 0 | S3: =S29-T29+'8'!S3 -> 0 | U3: =U29-V29+'8'!U3 -> 0 | W3: =W29-X29+'8'!W3 -> 0 | Y3: =Y29-Z29+'8'!Y3 -> 0 | AA3: =AA29-AB29+'8'!AA3 -> 0 | AC3: =AC29-AD29+'8'!AC3 -> 0 | AE3: =AE29-AF29+'8'!AE3 -> 0 | AG3: =AG29-AH29+'8'!AG3 -> 0 | AI3: =AI29-AJ29+'8'!AI3 -> 0 | AK3: =AK29-AL29+'8'!AK3 -> 0 | AM3: =AM29-AN29+'8'!AM3 -> 0 | AO3: =AO29-AP29+'8'!AO3 -> 0 | AQ3: =AQ29-AR29+'8'!AQ3 -> 0 | AS3: =AS29-AT29+'8'!AS3 -> 0 | AU3: =AU29-AV29+'8'!AU3 -> 0 | AW3: =AW29-AX29+'8'!AW3 -> 0
A4: دليل الحسابات
A6: رقم القيد | B6: التاريخ | C6: البيان | D6: الاجمالي | F6: contorl | G6: الفرق | I6: النقدية | K6: بنك مصر | M6: مدينونTele | O6: Teachمدينون | Q6: ادوات كتابية | S6: السيارات | U6: مجمع اهلاك سيارات | W6: الاثاث | Y6: مجمع اهلاك الاثاث | AA6: مباني | AC6: معدات | AE6: الاراضي | AG6: دائنونGlobal | AI6: مصروف صيانة | AK6: رواتب واجور | AM6: مصروف اهلاك | AO6: ايرادات | AQ6: راس المال | AS6: مسحوبات | AU6: حساب1 | AW6: حساب2
D7: مدين | E7: دائن | I7: مدين | J7: دائن | K7: مدين | L7: دائن | M7: مدين | N7: دائن | O7: مدين | P7: دائن | Q7: مدين | R7: دائن | S7: مدين | T7: دائن | U7: مدين | V7: دائن | W7: مدين | X7: دائن | Y7: مدين | Z7: دائن | AA7: مدين | AB7: دائن | AC7: مدين | AD7: دائن | AE7: مدين | AF7: دائن | AG7: مدين | AH7: دائن | AI7: مدين | AJ7: دائن | AK7: مدين | AL7: دائن | AM7: مدين | AN7: دائن | AO7: مدين | AP7: دائن | AQ7: مدين | AR7: دائن | AS7: مدين | AT7: دائن | AU7: مدين | AV7: دائن | AW7: مدين | AX7: دائن
D8: =SUMIF($I$7:$AX$7,$I$7,I8:AX8) -> 0 | E8: 0 | F8: =IF(D8=E8,"palance","unpalance") -> palance | G8: =IF(D8>E8,D8-E8,E8-D8) -> 0 | H8: =IF(D8>E8,"مدين اكبر",IF(E8>D8,"دائن اكبر","~")) -> ~ | I8: 0 | AP8: 0
D9: =SUMIF($I$7:$AX$7,$I$7,I9:AX9) -> 0 | E9: 0 | F9: =IF(D9=E9,"palance","unpalance") -> palance | G9: =IF(D9>E9,D9-E9,E9-D9) -> 0 | H9: =IF(D9>E9,"مدين اكبر",IF(E9>D9,"دائن اكبر","~")) -> ~ | AP9: 0
D10: =SUMIF($I$7:$AX$7,$I$7,I10:AX10) -> 0 | E10: =SUMIF($I$7:$AX$7,$J$7,I10:AX10) -> 0 | F10: =IF(D10=E10,"palance","unpalance") -> palance | G10: =IF(D10>E10,D10-E10,E10-D10) -> 0 | H10: =IF(D10>E10,"مدين اكبر",IF(E10>D10,"دائن اكبر","~")) -> ~
D11: =SUMIF($I$7:$AX$7,$I$7,I11:AX11) -> 0 | E11: =SUMIF($I$7:$AX$7,$J$7,I11:AX11) -> 0 | F11: =IF(D11=E11,"palance","unpalance") -> palance | G11: =IF(D11>E11,D11-E11,E11-D11) -> 0 | H11: =IF(D11>E11,"مدين اكبر",IF(E11>D11,"دائن اكبر","~")) -> ~
D12: =SUMIF($I$7:$AX$7,$I$7,I12:AX12) -> 0 | E12: =SUMIF($I$7:$AX$7,$J$7,I12:AX12) -> 0 | F12: =IF(D12=E12,"palance","unpalance") -> palance | G12: =IF(D12>E12,D12-E12,E12-D12) -> 0 | H12: =IF(D12>E12,"مدين اكبر",IF(E12>D12,"دائن اكبر","~")) -> ~
D13: =SUMIF($I$7:$AX$7,$I$7,I13:AX13) -> 0 | E13: =SUMIF($I$7:$AX$7,$J$7,I13:AX13) -> 0 | F13: =IF(D13=E13,"palance","unpalance") -> palance | G13: =IF(D13>E13,D13-E13,E13-D13) -> 0 | H13: =IF(D13>E13,"مدين اكبر",IF(E13>D13,"دائن اكبر","~")) -> ~
D14: =SUMIF($I$7:$AX$7,$I$7,I14:AX14) -> 0 | E14: =SUMIF($I$7:$AX$7,$J$7,I14:AX14) -> 0 | F14: =IF(D14=E14,"palance","unpalance") -> palance | G14: =IF(D14>E14,D14-E14,E14-D14) -> 0 | H14: =IF(D14>E14,"مدين اكبر",IF(E14>D14,"دائن اكبر","~")) -> ~
