Workbook

Sheet Budget
B2: Budgeted Income & Expenses 2026
B4: Figures in USD | C4: January | D4: February | E4: March | F4: April | G4: May | H4: June | I4: July | J4: August | K4: September | L4: October | M4: November | N4: December
B5: Income:
B6: Base Salary | C6: 2200 | D6: 2200 | E6: 2200 | F6: 3000 | G6: 3000 | H6: 3000 | I6: 3000 | J6: 3000 | K6: 3000 | L6: 3000 | M6: 3000 | N6: 3000
B7: Bonus | C7: 500 | D7: =C7*1.1 -> 550 | E7: 500 | F7: 500 | G7: 500 | H7: 500 | I7: 500 | J7: 500 | K7: 500 | L7: 500 | M7: 500 | N7: 500
B8: Side Hustle | C8: 100 | D8: =C8*1.3 -> 130 | E8: =D8*1.3 -> 169 | F8: =E8*1.3 -> 219.7 | G8: =F8*1.3 -> 285.61 | H8: =G8*1.3 -> 371.293 | I8: =H8*1.3 -> 482.6809 | J8: =I8*1.3 -> 627.48517 | K8: =J8*1.3 -> 815.73072 | ... N8: =M8*1.3 -> 1792.1604
B9: Total Income | C9: =SUM(C6:C8) -> 2800 | D9: =SUM(D6:D8) -> 2880 | E9: =SUM(E6:E8) -> 2869 | F9: =SUM(F6:F8) -> 3719.7 | G9: =SUM(G6:G8) -> 3785.61 | H9: =SUM(H6:H8) -> 3871.293 | I9: =SUM(I6:I8) -> 3982.6809 | J9: =SUM(J6:J8) -> 4127.4852 | ... N9: =SUM(N6:N8) -> 5292.1604
B11: Expenses:
B12: Rent | C12: 1120 | D12: 1120 | E12: 1120 | F12: 1120 | G12: 1120 | H12: 1120 | I12: 1120 | J12: 1120 | K12: 1120 | L12: 1120 | M12: 1120 | N12: 1120
B13: Utilities | C13: =C12*0.1 -> 112 | D13: =D12*0.1 -> 112 | E13: =E12*0.1 -> 112 | F13: =F12*0.1 -> 112 | G13: =G12*0.1 -> 112 | H13: =H12*0.1 -> 112 | I13: =I12*0.1 -> 112 | J13: =J12*0.1 -> 112 | ... N13: =N12*0.1 -> 112
B14: Transport | C14: 55 | D14: 55 | E14: 55 | F14: 55 | G14: 55 | H14: 55 | I14: 55 | J14: 55 | K14: 55 | L14: 55 | M14: 55 | N14: 55
B15: Groceries | C15: 550 | D15: 550 | E15: 550 | F15: 550 | G15: 550 | H15: 550 | I15: 550 | J15: 550 | K15: 550 | L15: 550 | M15: 550 | N15: 550
B16: Leisure | C16: 400 | D16: 400 | E16: 400 | F16: 400 | G16: 400 | H16: 400 | I16: 400 | J16: 400 | K16: 400 | L16: 400 | M16: 400 | N16: 400
B17: Other | C17: 100 | D17: 100 | E17: 100 | F17: 100 | G17: 100 | H17: 100 | I17: 100 | J17: 100 | K17: 100 | L17: 100 | M17: 100 | N17: 100
B18: Total Expenses | C18: =SUM(C12:C17) -> 2337 | D18: =SUM(D12:D17) -> 2337 | E18: =SUM(E12:E17) -> 2337 | F18: =SUM(F12:F17) -> 2337 | G18: =SUM(G12:G17) -> 2337 | H18: =SUM(H12:H17) -> 2337 | I18: =SUM(I12:I17) -> 2337 | J18: =SUM(J12:J17) -> 2337 | ... N18: =SUM(N12:N17) -> 2337
B20: Savings | C20: =C9-C18 -> 463 | D20: =D9-D18 -> 543 | E20: =E9-E18 -> 532 | F20: =F9-F18 -> 1382.7 | G20: =G9-G18 -> 1448.61 | H20: =H9-H18 -> 1534.293 | I20: =I9-I18 -> 1645.6809 | J20: =J9-J18 -> 1790.4852 | ... N20: =N9-N18 -> 2955.1604
B21: Cumulative Savings | C21: =C20 -> 463 | D21: =D20+C21 -> 1006 | E21: =E20+D21 -> 1538 | F21: =F20+E21 -> 2920.7 | G21: =G20+F21 -> 4369.31 | H21: =H20+G21 -> 5903.603 | I21: =I20+H21 -> 7549.2839 | J21: =J20+I21 -> 9339.7691 | K21: =K20+J21 -> 11318.5 | ... N21: =N20+M21 -> 19038.695

Sheet Actual
B2: Actual Income & Expenses 2026
B4: Date | C4: Month | D4: Category | E4: Description | F4: Amount | G4: MonthNum | H4: Categories
B5: 44562 | C5: =TEXT(B5,"MMMM") -> January | D5: Rent | E5: Apartment split with friend | F5: 1120 | G5: =MONTH(B5) -> 1 | H5: Base Salary
B6: 44562 | C6: =TEXT(B6,"MMMM") -> January | D6: Utilities | E6: Higher month than usual | F6: 140 | G6: =MONTH(B6) -> 1 | H6: Bonus
B7: 44562 | C7: =TEXT(B7,"MMMM") -> January | D7: Transport | E7: Metro card | F7: 55 | G7: =MONTH(B7) -> 1 | H7: Side Hustle
B8: 44569 | C8: =TEXT(B8,"MMMM") -> January | D8: Groceries | E8: Walmart shopping | F8: 449 | G8: =MONTH(B8) -> 1 | H8: Rent
B9: 44572 | C9: =TEXT(B9,"MMMM") -> January | D9: Leisure | E9: Hotel in NYC | F9: 245 | G9: =MONTH(B9) -> 1 | H9: Utilities
B10: 44573 | C10: =TEXT(B10,"MMMM") -> January | D10: Leisure | E10: Dinner with friends (invited my partner) | F10: 168 | G10: =MONTH(B10) -> 1 | H10: Transport
B11: 44573 | C11: =TEXT(B11,"MMMM") -> January | D11: Leisure | E11: Drake concert | F11: 149 | G11: =MONTH(B11) -> 1 | H11: Groceries
B12: 44575 | C12: =TEXT(B12,"MMMM") -> January | D12: Other | E12: Bought new clothes | F12: 249 | G12: =MONTH(B12) -> 1 | H12: Leisure
B13: 44592 | C13: =TEXT(B13,"MMMM") -> January | D13: Bonus | E13: Commissions from each sale | F13: 458 | G13: =MONTH(B13) -> 1 | H13: Other
B14: 44592 | C14: =TEXT(B14,"MMMM") -> January | D14: Base Salary | E14: 9-5 job | F14: 3000 | G14: =MONTH(B14) -> 1
B15: 44592 | C15: =TEXT(B15,"MMMM") -> January | D15: Side Hustle | E15: Startup idea $ | F15: 184 | G15: =MONTH(B15) -> 1
B16: 44593 | C16: =TEXT(B16,"MMMM") -> February | D16: Rent | E16: Apartment split with friend | F16: 1120 | G16: =MONTH(B16) -> 2
B17: 44593 | C17: =TEXT(B17,"MMMM") -> February | D17: Utilities | E17: Average month | F17: 105 | G17: =MONTH(B17) -> 2
B18: 44593 | C18: =TEXT(B18,"MMMM") -> February | D18: Transport | E18: Metro card | F18: 55 | G18: =MONTH(B18) -> 2
B19: 44600 | C19: =TEXT(B19,"MMMM") -> February | D19: Groceries | E19: Walmart shopping | F19: 305 | G19: =MONTH(B19) -> 2
B20: 44603 | C20: =TEXT(B20,"MMMM") -> February | D20: Leisure | E20: Drinks out | F20: 28 | G20: =MONTH(B20) -> 2
B21: 44604 | C21: =TEXT(B21,"MMMM") -> February | D21: Leisure | E21: Date night | F21: 99 | G21: =MONTH(B21) -> 2
B22: 44604 | C22: =TEXT(B22,"MMMM") -> February | D22: Leisure | E22: Tennis x2 | F22: 67 | G22: =MONTH(B22) -> 2
B23: 44606 | C23: =TEXT(B23,"MMMM") -> February | D23: Other | E23: Snacks | F23: 18 | G23: =MONTH(B23) -> 2
B24: 44620 | C24: =TEXT(B24,"MMMM") -> February | D24: Bonus | E24: Commissions from each sale | F24: 305 | G24: =MONTH(B24) -> 2
B25: 44620 | C25: =TEXT(B25,"MMMM") -> February | D25: Base Salary | E25: 9-5 job | F25: 3000 | G25: =MONTH(B25) -> 2
... B41: 44659 | C41: =TEXT(B41,"MMMM") -> April | D41: Groceries | E41: Walmart shopping | F41: 449 | G41: =MONTH(B41) -> 4
B42: =DATE(2026,4,5) -> 46117 | C42: April | D42: Groceries | E42: Hosted dinner party (extra groceries) | F42: 171 | G42: =MONTH(B42) -> 4
B43: 44662 | C43: =TEXT(B43,"MMMM") -> April | D43: Leisure | E43: Travel back home | F43: 245 | G43: =MONTH(B43) -> 4
B44: 44663 | C44: =TEXT(B44,"MMMM") -> April | D44: Leisure | E44: Dinner with friends (invited my partner) | F44: 168 | G44: =MONTH(B44) -> 4
B45: 44663 | C45: =TEXT(B45,"MMMM") -> April | D45: Leisure | E45: Disco & drinks | F45: 49 | G45: =MONTH(B45) -> 4
B46: =DATE(2026,4,18) -> 46130 | C46: April | D46: Leisure | E46: Concert tickets w/ partner | F46: 156 | G46: =MONTH(B46) -> 4
B47: =DATE(2026,4,25) -> 46137 | C47: April | D47: Leisure | E47: Weekend getaway | F47: 130 | G47: =MONTH(B47) -> 4
B48: 44665 | C48: =TEXT(B48,"MMMM") -> April | D48: Other | E48: Bought new clothes | F48: 249 | G48: =MONTH(B48) -> 4
B49: =DATE(2026,4,22) -> 46134 | C49: April | D49: Other | E49: Unexpected birthday gift for sister | F49: 171 | G49: =MONTH(B49) -> 4
B50: 44679 | C50: =TEXT(B50,"MMMM") -> April | D50: Bonus | E50: Bad sales month - low commissions | F50: 380 | G50: =MONTH(B50) -> 4
B51: 44679 | C51: =TEXT(B51,"MMMM") -> April | D51: Base Salary | E51: 9-5 job | F51: 3000 | G51: =MONTH(B51) -> 4
B52: 44679 | C52: =TEXT(B52,"MMMM") -> April | D52: Side Hustle | E52: Startup idea $ | F52: 258 | G52: =MONTH(B52) -> 4
B53: 44682 | C53: =TEXT(B53,"MMMM") -> May | D53: Rent | E53: Apartment split with friend | F53: 1120 | G53: =MONTH(B53) -> 5
B54: 44682 | C54: =TEXT(B54,"MMMM") -> May | D54: Utilities | E54: Higher month than usual | F54: 155 | G54: =MONTH(B54) -> 5
B55: =DATE(2026,5,8) -> 46150 | C55: May | D55: Utilities | E55: Window AC unit purchase | F55: 55 | G55: =MONTH(B55) -> 5
B56: =DATE(2026,5,22) -> 46164 | C56: May | D56: Utilities | E56: Higher electricity bill - AC usage | F56: 35 | G56: =MONTH(B56) -> 5
B57: 44682 | C57: =TEXT(B57,"MMMM") -> May | D57: Transport | E57: Metro card | F57: 55 | G57: =MONTH(B57) -> 5
...

Sheet Dashboard Finished
B2: Budget vs. Actual Dashboard
B4: Current Month -> | C4: October
B6: Figures in USD | C6: Budget | D6: Actual | F6: Var. Abs. | G6: Var. % | I6: Budget vs. Actual Income
B7: Income:
B8: Base Salary | C8: {=INDEX(Budget!$B$4:$N$21,MATCH('Dashboard Finished'!B8,Budget!$B$4:$B$21,0),MATCH('Dashboard Finished'!$C$4,Budget!$B$4:$N$4,0))} -> 3000 | D8: =SUMIFS(Actual!F:F,Actual!C:C,'Dashboard Finished'!$C$4,Actual!D:D,'Dashboard Finished'!B8) -> 3000 | F8: =D8-C8 -> 0 | G8: =D8/C8-1 -> 0
B9: Bonus | C9: {=INDEX(Budget!$B$4:$N$21,MATCH('Dashboard Finished'!B9,Budget!$B$4:$B$21,0),MATCH('Dashboard Finished'!$C$4,Budget!$B$4:$N$4,0))} -> 500 | D9: =SUMIFS(Actual!F:F,Actual!C:C,'Dashboard Finished'!$C$4,Actual!D:D,'Dashboard Finished'!B9) -> 555 | F9: =D9-C9 -> 55 | G9: =D9/C9-1 -> 0.11
B10: Side Hustle | C10: {=INDEX(Budget!$B$4:$N$21,MATCH('Dashboard Finished'!B10,Budget!$B$4:$B$21,0),MATCH('Dashboard Finished'!$C$4,Budget!$B$4:$N$4,0))} -> 1060.4499 | D10: =SUMIFS(Actual!F:F,Actual!C:C,'Dashboard Finished'!$C$4,Actual!D:D,'Dashboard Finished'!B10) -> 1357 | F10: =D10-C10 -> 296.55006 | G10: =D10/C10-1 -> 0.27964551
B11: Total Income | C11: =SUM(C8:C10) -> 4560.4499 | D11: =SUM(D8:D10) -> 4912 | F11: =D11-C11 -> 351.55006 | G11: =D11/C11-1 -> 0.077086706
B13: Expenses:
B14: Rent | C14: =INDEX(Budget!$B$4:$N$21,MATCH('Dashboard Finished'!B14,Budget!$B$4:$B$21,0),MATCH('Dashboard Finished'!$C$4,Budget!$B$4:$N$4,0)) -> 1120 | D14: =SUMIFS(Actual!F:F,Actual!C:C,'Dashboard Finished'!$C$4,Actual!D:D,'Dashboard Finished'!B14) -> 1120 | F14: =C14-D14 -> 0 | G14: =C14/D14-1 -> 0
B15: Utilities | C15: {=INDEX(Budget!$B$4:$N$21,MATCH('Dashboard Finished'!B15,Budget!$B$4:$B$21,0),MATCH('Dashboard Finished'!$C$4,Budget!$B$4:$N$4,0))} -> 112 | D15: =SUMIFS(Actual!F:F,Actual!C:C,'Dashboard Finished'!$C$4,Actual!D:D,'Dashboard Finished'!B15) -> 145 | F15: =C15-D15 -> -33 | G15: =C15/D15-1 -> -0.22758621
B16: Transport | C16: {=INDEX(Budget!$B$4:$N$21,MATCH('Dashboard Finished'!B16,Budget!$B$4:$B$21,0),MATCH('Dashboard Finished'!$C$4,Budget!$B$4:$N$4,0))} -> 55 | D16: =SUMIFS(Actual!F:F,Actual!C:C,'Dashboard Finished'!$C$4,Actual!D:D,'Dashboard Finished'!B16) -> 55 | F16: =C16-D16 -> 0 | G16: =C16/D16-1 -> 0 | I16: Actual Expenses Breakdown
B17: Groceries | C17: {=INDEX(Budget!$B$4:$N$21,MATCH('Dashboard Finished'!B17,Budget!$B$4:$B$21,0),MATCH('Dashboard Finished'!$C$4,Budget!$B$4:$N$4,0))} -> 550 | D17: =SUMIFS(Actual!F:F,Actual!C:C,'Dashboard Finished'!$C$4,Actual!D:D,'Dashboard Finished'!B17) -> 312 | F17: =C17-D17 -> 238 | G17: =C17/D17-1 -> 0.76282051
B18: Leisure | C18: {=INDEX(Budget!$B$4:$N$21,MATCH('Dashboard Finished'!B18,Budget!$B$4:$B$21,0),MATCH('Dashboard Finished'!$C$4,Budget!$B$4:$N$4,0))} -> 400 | D18: =SUMIFS(Actual!F:F,Actual!C:C,'Dashboard Finished'!$C$4,Actual!D:D,'Dashboard Finished'!B18) -> 400 | F18: =C18-D18 -> 0 | G18: =C18/D18-1 -> 0
B19: Other | C19: {=INDEX(Budget!$B$4:$N$21,MATCH('Dashboard Finished'!B19,Budget!$B$4:$B$21,0),MATCH('Dashboard Finished'!$C$4,Budget!$B$4:$N$4,0))} -> 100 | D19: =SUMIFS(Actual!F:F,Actual!C:C,'Dashboard Finished'!$C$4,Actual!D:D,'Dashboard Finished'!B19) -> 100 | F19: =C19-D19 -> 0 | G19: =C19/D19-1 -> 0
B20: Total Expenses | C20: =SUM(C14:C19) -> 2337 | D20: =SUM(D14:D19) -> 2132 | F20: =C20-D20 -> 205 | G20: =C20/D20-1 -> 0.096153846
B22: Savings | C22: =C11-C20 -> 2223.4499 | D22: =D11-D20 -> 2780 | F22: =D22-C22 -> 556.55006 | G22: =D22/C22-1 -> 0.25030924

Sheet Monthly Report
B1: Monthly Financial Report
B2: October
B5: Total Income | D5: Total Expenses | F5: Net Savings | H5: YTD Cumulative Savings
B6: Budget | C6: =C14 -> 4560.4499 | D6: Budget | E6: =C24 -> 2337 | F6: Budget | G6: =C27 -> 2223.4499 | H6: Budget | I6: =INDEX(Budget!$C$21:$N$21,MATCH($B$2,Budget!$C$4:$N$4,0)) -> 13541.95
B7: Actual | C7: =D14 -> 4912 | D7: Actual | E7: =D24 -> 2132 | F7: Actual | G7: =D27 -> 2780 | H7: Actual | I7: =SUMPRODUCT((IFERROR(MATCH(Actual!$C$5:$C$507,Budget!$C$4:$N$4,0),0)<=MATCH($B$2,Budget!$C$4:$N$4,0))*((Actual!$D$5:$D$507="Base Salary")+(Actual!$D$5:$D$507="Bonus")+(Actual!$D$5:$D$507="Side Hustle"))*Actual!$F$5:$F$507)-SUMPRODUCT((IFERROR(MATCH(Actual!$C$5:$C$507,Budget!$C$4:$N$4,0),0)<=MATCH($B$2,Budget!$C$4:$N$4,0))*((Actual!$D$5:$D$507="Rent")+(Actual!$D$5:$D$507="Utilities")+(Actual!$D$5:$D$507="Transport")+(Actual!$D$5:$D$507="Groceries")+(Actual!$D$5:$D$507="Leisure")+(Actual!$D$5:$D$507="Other"))*Actual!$F$5:$F$507) -> 23816
B8: Variance | C8: =C7-C6 -> 351.55006 | D8: Variance | E8: =E7-E6 -> -205 | F8: Variance | G8: =G7-G6 -> 556.55006 | H8: Variance | I8: =I7-I6 -> 10274.05
B10: Category | C10: Budget | D10: Actual | E10: Variance ($) | F10: Variance (%)
B11: Base Salary | C11: =INDEX(Budget!$C$6:$N$18,MATCH($B11,Budget!$B$6:$B$18,0),MATCH($B$2,Budget!$C$4:$N$4,0)) -> 3000 | D11: =SUMIFS(Actual!$F:$F,Actual!$C:$C,$B$2,Actual!$D:$D,$B11) -> 3000 | E11: =D11-C11 -> 0 | F11: =IFERROR((D11-C11)/C11,0) -> 0
B12: Bonus | C12: =INDEX(Budget!$C$6:$N$18,MATCH($B12,Budget!$B$6:$B$18,0),MATCH($B$2,Budget!$C$4:$N$4,0)) -> 500 | D12: =SUMIFS(Actual!$F:$F,Actual!$C:$C,$B$2,Actual!$D:$D,$B12) -> 555 | E12: =D12-C12 -> 55 | F12: =IFERROR((D12-C12)/C12,0) -> 0.11
B13: Side Hustle | C13: =INDEX(Budget!$C$6:$N$18,MATCH($B13,Budget!$B$6:$B$18,0),MATCH($B$2,Budget!$C$4:$N$4,0)) -> 1060.4499 | D13: =SUMIFS(Actual!$F:$F,Actual!$C:$C,$B$2,Actual!$D:$D,$B13) -> 1357 | E13: =D13-C13 -> 296.55006 | F13: =IFERROR((D13-C13)/C13,0) -> 0.27964551
B14: Total Income | C14: =SUM(C11:C13) -> 4560.4499 | D14: =SUM(D11:D13) -> 4912 | E14: =D14-C14 -> 351.55006 | F14: =IFERROR((D14-C14)/C14,0) -> 0.077086706
B17: Category | C17: Budget | D17: Actual | E17: Variance ($) | F17: Variance (%)
B18: Rent | C18: =INDEX(Budget!$C$6:$N$18,MATCH($B18,Budget!$B$6:$B$18,0),MATCH($B$2,Budget!$C$4:$N$4,0)) -> 1120 | D18: =SUMIFS(Actual!$F:$F,Actual!$C:$C,$B$2,Actual!$D:$D,$B18) -> 1120 | E18: =D18-C18 -> 0 | F18: =IFERROR((D18-C18)/C18,0) -> 0
B19: Utilities | C19: =INDEX(Budget!$C$6:$N$18,MATCH($B19,Budget!$B$6:$B$18,0),MATCH($B$2,Budget!$C$4:$N$4,0)) -> 112 | D19: =SUMIFS(Actual!$F:$F,Actual!$C:$C,$B$2,Actual!$D:$D,$B19) -> 145 | E19: =D19-C19 -> 33 | F19: =IFERROR((D19-C19)/C19,0) -> 0.29464286
B20: Transport | C20: =INDEX(Budget!$C$6:$N$18,MATCH($B20,Budget!$B$6:$B$18,0),MATCH($B$2,Budget!$C$4:$N$4,0)) -> 55 | D20: =SUMIFS(Actual!$F:$F,Actual!$C:$C,$B$2,Actual!$D:$D,$B20) -> 55 | E20: =D20-C20 -> 0 | F20: =IFERROR((D20-C20)/C20,0) -> 0
B21: Groceries | C21: =INDEX(Budget!$C$6:$N$18,MATCH($B21,Budget!$B$6:$B$18,0),MATCH($B$2,Budget!$C$4:$N$4,0)) -> 550 | D21: =SUMIFS(Actual!$F:$F,Actual!$C:$C,$B$2,Actual!$D:$D,$B21) -> 312 | E21: =D21-C21 -> -238 | F21: =IFERROR((D21-C21)/C21,0) -> -0.43272727
B22: Leisure | C22: =INDEX(Budget!$C$6:$N$18,MATCH($B22,Budget!$B$6:$B$18,0),MATCH($B$2,Budget!$C$4:$N$4,0)) -> 400 | D22: =SUMIFS(Actual!$F:$F,Actual!$C:$C,$B$2,Actual!$D:$D,$B22) -> 400 | E22: =D22-C22 -> 0 | F22: =IFERROR((D22-C22)/C22,0) -> 0
B23: Other | C23: =INDEX(Budget!$C$6:$N$18,MATCH($B23,Budget!$B$6:$B$18,0),MATCH($B$2,Budget!$C$4:$N$4,0)) -> 100 | D23: =SUMIFS(Actual!$F:$F,Actual!$C:$C,$B$2,Actual!$D:$D,$B23) -> 100 | E23: =D23-C23 -> 0 | F23: =IFERROR((D23-C23)/C23,0) -> 0
B24: Total Expenses | C24: =SUM(C18:C23) -> 2337 | D24: =SUM(D18:D23) -> 2132 | E24: =D24-C24 -> -205 | F24: =IFERROR((D24-C24)/C24,0) -> -0.087719298
B27: Savings | C27: =C14-C24 -> 2223.4499 | D27: =D14-D24 -> 2780 | E27: =D27-C27 -> 556.55006 | F27: =IFERROR((D27-C27)/C27,0) -> 0.25030924

Sheet __tracelight_scratchpad__

Sheet YTD Analysis
A1: YTD Cumulative Savings Analysis
A2: Category | B2: (Multiple Items) | E2: Category | F2: (Multiple Items) | I2: Best Month: | J2: =INDEX($I$5:$I$16,MATCH(MAX($J$5:$J$16),$J$5:$J$16,0)) -> December | K2: Worst Month: | L2: =INDEX($I$5:$I$16,MATCH(MIN($J$5:$J$16),$J$5:$J$16,0)) -> April
A3: INCOME | E3: EXPENSES | I3: YTD Total: | J3: {=INDEX($K$5:$K$16,MAX(MONTH(Actual!$B$5:$B$143)))} -> 23634 | K3: On Track?: | L3: {=IF(J3>=INDEX(Budget!$C$21:$N$21,MAX(MONTH(Actual!$B$5:$B$143))),"✅ ","⚠️")} -> ✅
A4: MonthNum | B4: Sum of Amount | E4: MonthNum | F4: Sum of Amount | I4: Month | J4: Monthly Savings | K4: Cumulative YTD | L4: % of Annual Target
A5: 1 | B5: 3642 | E5: 1 | F5: 2575 | I5: January | J5: =IFERROR(GETPIVOTDATA("Amount",$A$4,"MonthNum",ROW()-4),0)-IFERROR(GETPIVOTDATA("Amount",$E$4,"MonthNum",ROW()-4),0) -> 1067 | K5: =J5 -> 1067 | L5: =IFERROR(K5/Budget!$N$21,0) -> 0.056043757
A6: 2 | B6: 3533 | E6: 2 | F6: 1797 | I6: February | J6: =IFERROR(GETPIVOTDATA("Amount",$A$4,"MonthNum",ROW()-4),0)-IFERROR(GETPIVOTDATA("Amount",$E$4,"MonthNum",ROW()-4),0) -> 1736 | K6: =K5+J6 -> 2803 | L6: =IFERROR(K6/Budget!$N$21,0) -> 0.14722648
A7: 3 | B7: 3657 | E7: 3 | F7: 2097 | I7: March | J7: =IFERROR(GETPIVOTDATA("Amount",$A$4,"MonthNum",ROW()-4),0)-IFERROR(GETPIVOTDATA("Amount",$E$4,"MonthNum",ROW()-4),0) -> 1560 | K7: =K6+J7 -> 4363 | L7: =IFERROR(K7/Budget!$N$21,0) -> 0.22916487
A8: 4 | B8: 3638 | E8: 4 | F8: 3103 | I8: April | J8: =IFERROR(GETPIVOTDATA("Amount",$A$4,"MonthNum",ROW()-4),0)-IFERROR(GETPIVOTDATA("Amount",$E$4,"MonthNum",ROW()-4),0) -> 535 | K8: =K7+J8 -> 4898 | L8: =IFERROR(K8/Budget!$N$21,0) -> 0.25726553
A9: 5 | B9: 3888 | E9: 5 | F9: 2839 | I9: May | J9: =IFERROR(GETPIVOTDATA("Amount",$A$4,"MonthNum",ROW()-4),0)-IFERROR(GETPIVOTDATA("Amount",$E$4,"MonthNum",ROW()-4),0) -> 1049 | K9: =K8+J9 -> 5947 | L9: =IFERROR(K9/Budget!$N$21,0) -> 0.31236385
A10: 6 | B10: 3888 | E10: 6 | F10: 2148 | I10: June | J10: =IFERROR(GETPIVOTDATA("Amount",$A$4,"MonthNum",ROW()-4),0)-IFERROR(GETPIVOTDATA("Amount",$E$4,"MonthNum",ROW()-4),0) -> 1740 | K10: =K9+J10 -> 7687 | L10: =IFERROR(K10/Budget!$N$21,0) -> 0.40375666
A11: 7 | B11: 4143 | E11: 7 | F11: 2181 | I11: July | J11: =IFERROR(GETPIVOTDATA("Amount",$A$4,"MonthNum",ROW()-4),0)-IFERROR(GETPIVOTDATA("Amount",$E$4,"MonthNum",ROW()-4),0) -> 1962 | K11: =K10+J11 -> 9649 | L11: =IFERROR(K11/Budget!$N$21,0) -> 0.50680995
A12: 8 | B12: 4415 | E12: 8 | F12: 2200 | I12: August | J12: =IFERROR(GETPIVOTDATA("Amount",$A$4,"MonthNum",ROW()-4),0)-IFERROR(GETPIVOTDATA("Amount",$E$4,"MonthNum",ROW()-4),0) -> 2215 | K12: =K11+J12 -> 11864 | L12: =IFERROR(K12/Budget!$N$21,0) -> 0.62315195
A13: 9 | B13: 4522 | E13: 9 | F13: 2006 | I13: September | J13: =IFERROR(GETPIVOTDATA("Amount",$A$4,"MonthNum",ROW()-4),0)-IFERROR(GETPIVOTDATA("Amount",$E$4,"MonthNum",ROW()-4),0) -> 2516 | K13: =K12+J13 -> 14380 | L13: =IFERROR(K13/Budget!$N$21,0) -> 0.75530387
A14: 10 | B14: 4912 | E14: 10 | F14: 2314 | I14: October | J14: =IFERROR(GETPIVOTDATA("Amount",$A$4,"MonthNum",ROW()-4),0)-IFERROR(GETPIVOTDATA("Amount",$E$4,"MonthNum",ROW()-4),0) -> 2598 | K14: =K13+J14 -> 16978 | L14: =IFERROR(K14/Budget!$N$21,0) -> 0.8917628
A15: 11 | B15: 5395 | E15: 11 | F15: 2083 | I15: November | J15: =IFERROR(GETPIVOTDATA("Amount",$A$4,"MonthNum",ROW()-4),0)-IFERROR(GETPIVOTDATA("Amount",$E$4,"MonthNum",ROW()-4),0) -> 3312 | K15: =K14+J15 -> 20290 | L15: =IFERROR(K15/Budget!$N$21,0) -> 1.0657243
A16: 12 | B16: 6037 | E16: 12 | F16: 2693 | I16: December | J16: =IFERROR(GETPIVOTDATA("Amount",$A$4,"MonthNum",ROW()-4),0)-IFERROR(GETPIVOTDATA("Amount",$E$4,"MonthNum",ROW()-4),0) -> 3344 | K16: =K15+J16 -> 23634 | L16: =IFERROR(K16/Budget!$N$21,0) -> 1.2413666
A17: Grand Total | B17: 51670 | E17: Grand Total | F17: 28036

Sheet Monthly Review Log
A1: Month | B1: Biggest Deviation | C1: Top Achievement | D1: Next Month Action
A2: January | B2: Other came in at $249 vs $100 budget (+149%) on impulse clothing purchases. | C2: Groceries finished at $449 — $101 under budget thanks to consistent Walmart shopping. | D2: Set a hard $100 monthly cap on "Other" and pre-approve clothing buys.
A3: February | B3: No category exceeded budget — all discretionary lines came in materially under target. | C3: Cleanest month of the year: Leisure $194 vs $400 and Other $18 vs $100 — saved ~$470 vs plan. | D3: Bank the surplus into savings before March discretionary creep returns.
A4: March | B4: Other hit $199 vs $100 (+99%) driven by another clothing purchase. | C4: Groceries only $208 (-62%) and Side Hustle income strong relative to spend discipline. | D4: Move clothing into a quarterly envelope budget instead of monthly impulse.
A5: April | B5: Other surged to $420 vs $100 (+320%) — clothing plus an unexpected birthday gift compounded the overrun. | C5: Base Salary stable at $3,000; Transport held flat at $55 metro card with zero variance. | D5: Freeze all non-essential "Other" and Leisure spend in May; require 24h cooling-off on any purchase >$50.
A6: May | B6: Other reached $380 vs $100 (+280%) as stress-driven online shopping compounded April's overspend. | C6: Side Hustle still delivered $180 despite reduced focus — baseline income held. | D6: Schedule weekly Side Hustle blocks in June and switch "Other" to cash-only to break the spiral.
A7: June | B7: Utilities and Other essentially on budget; Leisure $383 vs $400 — mild overall pressure only. | C7: Side Hustle jumped to $476 — best month YTD; Leisure pulled back below target. | D7: Reinvest part of the Side Hustle uplift into emergency fund before July travel temptations.
A8: July | B8: Utilities $158 vs $112 (+41%) on summer AC; Other $145 vs $100 (+45%) on running shoes. | C8: Side Hustle climbed to $618 — second consecutive record month. | D8: Pre-pay or smooth the electricity bill and defer non-essential gear purchases to August.
A9: August | B9: Utilities $152 vs $112 (+36%) sustained AC load; Leisure $490 vs $400 (+23%) on weekend trip. | C9: Side Hustle hit $803 — new record; Other came in 12% under budget. | D9: Cap weekend trips at one per month and shift AC usage to off-peak hours in September.
A10: September | B10: No category exceeded budget — a fully disciplined month across all discretionary lines. | C10: Side Hustle exploded to $1,044 — first four-figure month; Leisure under by $110. | D10: Lock in the discipline: keep Leisure at September pace heading into Q4 holiday season.
A11: October | B11: Utilities $145 vs $112 (+29%) on a higher heating ramp-up — only material expense overrun this month. | C11: Side Hustle at $1,357 — another new YTD record; Groceries $312 (-43%) and Leisure landed exactly on plan at $400. | D11: Lock in Q4 discipline — pre-approve any Black Friday clothing or travel before booking.
A12: November | B12: Other $220 vs $100 (+120%) on Black Friday clothing — the only material overrun this month. | C12: Side Hustle reached $1,763 — new high; Groceries $268 (-51%) and Leisure $298 (-26%) both well under budget. | D12: Use a pre-built December gift list and shop only against that list to avoid repeat overruns.
A13: December | B13: Other $285 vs $100 (+185%) on Christmas gifts; Leisure $640 vs $400 (+60%) on ski trip and NYE. | C13: Side Hustle closed the year at $2,292 — strongest month ever; full-year savings target exceeded. | D13: Roll December's holiday cost into a 2027 sinking fund (~$50/month) so it stops blowing the budget.
